Workbook
Name SegmentaciónDeDatos_CIUDAD: #N/A
Name SegmentaciónDeDatos_NOMBRE_COMERCIAL: #N/A

Sheet INFORME
A1: INFORME AUDITORIA MAYO
D3: EJECUCION DEL PLAN
D4: CIUDAD | E4: #PDV Obj. | F4: #PDV Eje. | G4: .% Ejecucion | H4: Obj Mystery | I4: Mystery Eje. | J4: % Efectividad.
D5: BARRANQUILLA | E5: 1 | F5: 1 | G5: 1 | H5: 1 | I5: 1 | J5: 1
D6: CALI | E6: 1 | F6: 1 | G6: 1 | H6: 1 | I6: 1 | J6: 1
D7: BOGOTA | E7: 2 | F7: 2 | G7: 1 | H7: 2 | I7: 1 | J7: 0.5
D8: PEREIRA | E8: 1 | F8: 0 | G8: 0 | H8: 1 | I8: 0 | J8: 0
D9: Total general | E9: 5 | F9: 4 | G9: 0.8 | H9: 5 | I9: 3 | J9: 0.6
D15: MYSTERY POR CLUSTER
D16: Suma de % MYSTERY | E16: Etiquetas de columna
D17: CLUSTER | E17: TRADICIONAL | F17: ESPECIALIZADO | G17: % MYSTERY
D18: ACTIVIDADES DEL MES | E18: 1 | F18: 1 | G18: 1
D19: EJECUCIÓN DEL PDV | E19: 1 | F19: 1 | G19: 1
D20: HORARIO | E20: 1 | F20: 1 | G20: 1
D21: PRESENTACIÓN PERSONAL | E21: 1 | F21: 1 | G21: 1
D22: % MYSTERY | E22: 1 | F22: 1 | G22: 1
D25: MYSTERY POR CLUSTER - CIUDAD
D26: Suma de % MYSTERY | E26: Etiquetas de columna
D27: CLUSTER | E27: BOGOTA | F27: CALI | G27: BARRANQUILLA | H27: % MYSTERY
D28: ACTIVIDADES DEL MES | E28: 1 | F28: 1 | G28: 1 | H28: 1
D29: EJECUCIÓN DEL PDV | E29: 1 | F29: 1 | G29: 1 | H29: 1
D30: HORARIO | E30: 1 | F30: 1 | G30: 1 | H30: 1
D31: PRESENTACIÓN PERSONAL | E31: 1 | F31: 1 | G31: 1 | H31: 1
D32: % MYSTERY | E32: 1 | F32: 1 | G32: 1 | H32: 1
D39: MYSTERY EFECTIVO | E39: (Todas)
D40: MYSTERY POR PDV
D41: Suma de % MYSTERY | G41: CLUSTER
D42: CIUDAD | E42: CANAL | F42: NOMBRE COMERCIAL | G42: ACTIVIDADES DEL MES | H42: EJECUCIÓN DEL PDV | I42: HORARIO | J42: PRESENTACIÓN PERSONAL | K42: % MYSTERY
D43: BOGOTA | E43: ESPECIALIZADO | F43: LAIKA USAQUEN | G43: 1 | H43: 1 | I43: 1 | J43: 1 | K43: 1
D44: CALI | E44: TRADICIONAL | F44: AHORRAMAS PASOANCHO | G44: 1 | H44: 1 | I44: 1 | J44: 1 | K44: 1
D45: BARRANQUILLA | E45: ESPECIALIZADO | F45: 425892 - UNIMED | G45: 1 | H45: 1 | I45: 1 | J45: 1 | K45: 1
D46: % MYSTERY | G46: 1 | H46: 1 | I46: 1 | J46: 1 | K46: 1

Sheet Videos
A1: CANAL | B1: CIUDAD | C1: NOMBRE COMERCIAL | D1: VIDEO 1 | E1: VIDEO 2 | F1: VIDEO 3 | G1: VIDEO 4 | H1: VIDEO 5
A2: ESPECIALIZADO | B2: BOGOTA | C2: LAIKA USAQUEN | D2: https://drive.google.com/file/d/1q4znj-sZYga0AGFWHBAxPFPfPNRB6Drl/view?usp=sharing | E2: - | F2: - | G2: - | H2: -
A3: TRADICIONAL | B3: BOGOTA | C3: AUTOSERVICIO AHORRAMAS | D3: https://drive.google.com/file/d/1c79rCJlQAVGf_z2Yf1UjzhYW3Wi0XXt7/view?usp=sharing | E3: https://drive.google.com/file/d/1ionukm8SW-5XhkhNes0tc-1J0JZppf_T/view?usp=sharing | F3: - | G3: - | H3: -
A4: TRADICIONAL | B4: CALI | C4: AHORRAMAS PASOANCHO | D4: https://drive.google.com/file/d/1-k_iYHs27SP3Pyan0JRgHUezBlo6CFTi/view?usp=sharing | E4: - | F4: - | G4: - | H4: -
A5: ESPECIALIZADO | B5: BARRANQUILLA | C5: 425892 - UNIMED | D5: https://drive.google.com/file/d/1D_d3zZVP0HjIg_r9FuHzk3CQiUTP1leV/view?usp=sharing | E5: - | F5: - | G5: - | H5: -

Sheet PUNTAJES
A1: ACTIVIDAD | B1: CIUDAD | C1: CANAL | D1: CADENA | E1: CODIGO PDV | F1: NOMBRE COMERCIAL | G1: PREGUNTA | H1: RTA | I1: FECHA VISITA | J1: CODIGO RUTA | K1: USUARIO | L1: MYSTERY EFECTIVO | M1: CLUSTER | N1: TOTAL PUNTAJE | O1: RTA CORRECTA | P1: PUNTAJE OBTENIDO | Q1: Columna1 | R1: Columna2 | T1: SI(O(G17="Dog Chow";G17="Cat Chow";G17="Alpo";G17="Gatsy";G17="Feliz");N17;0) | U1: SI(O(G29="Dog Chow húmedo";G29="Cat Chow húmedo";G29="Fancy Feast";G29="Felix";G29="Proplan húmedo";G29="One húmedo";G29="Snack Abrazzos";G29="Snak Dentalife";G29="Arenilla Tidy Cat");N29;0)
A2: NESTLE PURINA | B2: CALI | C2: TRADICIONAL | D2: TRADICIONAL | E2: 127058 | F2: AHORRAMAS PASOANCHO | G2: SE LOGRA REALIZAR LA AUDITORIA? | H2: SI | J2: 31364497 | K2: PREMISEUNP 51 | L2: =_xlfn.XLOOKUP(Tabla2__2[[#This Row],[CODIGO RUTA]],'DATA INFORME'!I:I,'DATA INFORME'!K:K) -> SI | M2: =IF(Tabla2__2[[#This Row],[MYSTERY EFECTIVO]]="SI",_xlfn.XLOOKUP(Tabla2__2[[#This Row],[PREGUNTA]],ENCUESTA!G:G,ENCUESTA!D:D),"N/A") -> N/A | N2: =IF(Tabla2__2[[#This Row],[MYSTERY EFECTIVO]]="SI",(IF(Tabla2__2[[#This Row],[CANAL]]="TRADICIONAL",_xlfn.XLOOKUP(Tabla2__2[[#This Row],[PREGUNTA]],ENCUESTA!G:G,ENCUESTA!A:A),IF(Tabla2__2[[#This Row],[CANAL]]="ESPECIALIZADO",_xlfn.XLOOKUP(Tabla2__2[[#This Row],[PREGUNTA]],ENCUESTA!G:G,ENCUESTA!B:B),IF(Tabla2__2[[#This Row],[CANAL]]="MODERNO",_xlfn.XLOOKUP(Tabla2__2[[#This Row],[PREGUNTA]],ENCUESTA!G:G,ENCUESTA!C:C))))),0) -> 0 | O2: =_xlfn.XLOOKUP(Tabla2__2[[#This Row],[PREGUNTA]],ENCUESTA!G:G,ENCUESTA!H:H) -> 0 | P2: =IF(Tabla2__2[[#This Row],[RTA]]=Tabla2__2[[#This Row],[RTA CORRECTA]],Tabla2__2[[#This Row],[TOTAL PUNTAJE]],0) -> 0 | Q2: =IF(OR(H2="Dog Chow húmedo",H2="Cat Chow húmedo",H2="Fancy Feast",H2="Felix",H2="Proplan húmedo",H2="One húmedo",H2="Snack Abrazzos",H2="Snak Dentalife",H2="Arenilla Tidy Cat"),N2,0) -> 0
A3: NESTLE PURINA | B3: BARRANQUILLA | C3: ESPECIALIZADO | D3: ESPECIALIZADO | E3: 425892 | F3: 425892 - UNIMED | G3: SU CABELLO LUCE LIMPIO, ORGANIZADO O RECOGIDO | H3: SI | J3: 31389386 | K3: NestleP.5 | L3: =_xlfn.XLOOKUP(Tabla2__2[[#This Row],[CODIGO RUTA]],'DATA INFORME'!I:I,'DATA INFORME'!K:K) -> SI | M3: =IF(Tabla2__2[[#This Row],[MYSTERY EFECTIVO]]="SI",_xlfn.XLOOKUP(Tabla2__2[[#This Row],[PREGUNTA]],ENCUESTA!G:G,ENCUESTA!D:D),"N/A") -> PRESENTACIÓN PERSONAL | N3: =IF(Tabla2__2[[#This Row],[MYSTERY EFECTIVO]]="SI",(IF(Tabla2__2[[#This Row],[CANAL]]="TRADICIONAL",_xlfn.XLOOKUP(Tabla2__2[[#This Row],[PREGUNTA]],ENCUESTA!G:G,ENCUESTA!A:A),IF(Tabla2__2[[#This Row],[CANAL]]="ESPECIALIZADO",_xlfn.XLOOKUP(Tabla2__2[[#This Row],[PREGUNTA]],ENCUESTA!G:G,ENCUESTA!B:B),IF(Tabla2__2[[#This Row],[CANAL]]="MODERNO",_xlfn.XLOOKUP(Tabla2__2[[#This Row],[PREGUNTA]],ENCUESTA!G:G,ENCUESTA!C:C))))),0) -> 1 | O3: =_xlfn.XLOOKUP(Tabla2__2[[#This Row],[PREGUNTA]],ENCUESTA!G:G,ENCUESTA!H:H) -> SI | P3: =IF(Tabla2__2[[#This Row],[RTA]]=Tabla2__2[[#This Row],[RTA CORRECTA]],Tabla2__2[[#This Row],[TOTAL PUNTAJE]],0) -> 1 | Q3: =IF(OR(H3="Dog Chow húmedo",H3="Cat Chow húmedo",H3="Fancy Feast",H3="Felix",H3="Proplan húmedo",H3="One húmedo",H3="Snack Abrazzos",H3="Snak Dentalife",H3="Arenilla Tidy Cat"),N3,0) -> 0
A4: NESTLE PURINA | B4: BARRANQUILLA | C4: ESPECIALIZADO | D4: ESPECIALIZADO | E4: 425892 | F4: 425892 - UNIMED | G4: EL UNIFORME Y ZAPATOS SE ENCUENTRAN LIMPIOS Y EN BUEN ESTADO | H4: SI | J4: 31389386 | K4: NestleP.5 | L4: =_xlfn.XLOOKUP(Tabla2__2[[#This Row],[CODIGO RUTA]],'DATA INFORME'!I:I,'DATA INFORME'!K:K) -> SI | M4: =IF(Tabla2__2[[#This Row],[MYSTERY EFECTIVO]]="SI",_xlfn.XLOOKUP(Tabla2__2[[#This Row],[PREGUNTA]],ENCUESTA!G:G,ENCUESTA!D:D),"N/A") -> PRESENTACIÓN PERSONAL | N4: =IF(Tabla2__2[[#This Row],[MYSTERY EFECTIVO]]="SI",(IF(Tabla2__2[[#This Row],[CANAL]]="TRADICIONAL",_xlfn.XLOOKUP(Tabla2__2[[#This Row],[PREGUNTA]],ENCUESTA!G:G,ENCUESTA!A:A),IF(Tabla2__2[[#This Row],[CANAL]]="ESPECIALIZADO",_xlfn.XLOOKUP(Tabla2__2[[#This Row],[PREGUNTA]],ENCUESTA!G:G,ENCUESTA!B:B),IF(Tabla2__2[[#This Row],[CANAL]]="MODERNO",_xlfn.XLOOKUP(Tabla2__2[[#This Row],[PREGUNTA]],ENCUESTA!G:G,ENCUESTA!C:C))))),0) -> 1 | O4: =_xlfn.XLOOKUP(Tabla2__2[[#This Row],[PREGUNTA]],ENCUESTA!G:G,ENCUESTA!H:H) -> SI | P4: =IF(Tabla2__2[[#This Row],[RTA]]=Tabla2__2[[#This Row],[RTA CORRECTA]],Tabla2__2[[#This Row],[TOTAL PUNTAJE]],0) -> 1 | Q4: =IF(OR(H4="Dog Chow húmedo",H4="Cat Chow húmedo",H4="Fancy Feast",H4="Felix",H4="Proplan húmedo",H4="One húmedo",H4="Snack Abrazzos",H4="Snak Dentalife",H4="Arenilla Tidy Cat"),N4,0) -> 0
A5: NESTLE PURINA | B5: BARRANQUILLA | C5: ESPECIALIZADO | D5: ESPECIALIZADO | E5: 425892 | F5: 425892 - UNIMED | G5: POSEE ALGUNA PRENDA ENCIMA DEL UNIFORME NO AUTORIZADA POR LA MARCA (UNICAMENTE ESTA PERMITIDO CHALECO DE SODIMAC Y EASY) | H5: NO | J5: 31389386 | K5: NestleP.5 | L5: =_xlfn.XLOOKUP(Tabla2__2[[#This Row],[CODIGO RUTA]],'DATA INFORME'!I:I,'DATA INFORME'!K:K) -> SI | M5: =IF(Tabla2__2[[#This Row],[MYSTERY EFECTIVO]]="SI",_xlfn.XLOOKUP(Tabla2__2[[#This Row],[PREGUNTA]],ENCUESTA!G:G,ENCUESTA!D:D),"N/A") -> PRESENTACIÓN PERSONAL | N5: =IF(Tabla2__2[[#This Row],[MYSTERY EFECTIVO]]="SI",(IF(Tabla2__2[[#This Row],[CANAL]]="TRADICIONAL",_xlfn.XLOOKUP(Tabla2__2[[#This Row],[PREGUNTA]],ENCUESTA!G:G,ENCUESTA!A:A),IF(Tabla2__2[[#This Row],[CANAL]]="ESPECIALIZADO",_xlfn.XLOOKUP(Tabla2__2[[#This Row],[PREGUNTA]],ENCUESTA!G:G,ENCUESTA!B:B),IF(Tabla2__2[[#This Row],[CANAL]]="MODERNO",_xlfn.XLOOKUP(Tabla2__2[[#This Row],[PREGUNTA]],ENCUESTA!G:G,ENCUESTA!C:C))))),0) -> 1 | O5: =_xlfn.XLOOKUP(Tabla2__2[[#This Row],[PREGUNTA]],ENCUESTA!G:G,ENCUESTA!H:H) -> NO | P5: =IF(Tabla2__2[[#This Row],[RTA]]=Tabla2__2[[#This Row],[RTA CORRECTA]],Tabla2__2[[#This Row],[TOTAL PUNTAJE]],0) -> 1 | Q5: =IF(OR(H5="Dog Chow húmedo",H5="Cat Chow húmedo",H5="Fancy Feast",H5="Felix",H5="Proplan húmedo",H5="One húmedo",H5="Snack Abrazzos",H5="Snak Dentalife",H5="Arenilla Tidy Cat"),N5,0) -> 0
A6: NESTLE PURINA | B6: BARRANQUILLA | C6: ESPECIALIZADO | D6: ESPECIALIZADO | E6: 425892 | F6: 425892 - UNIMED | G6: CUENTA CON CALZADO DE ACUERDO AL UNIFORME | H6: SI | J6: 31389386 | K6: NestleP.5 | L6: =_xlfn.XLOOKUP(Tabla2__2[[#This Row],[CODIGO RUTA]],'DATA INFORME'!I:I,'DATA INFORME'!K:K) -> SI | M6: =IF(Tabla2__2[[#This Row],[MYSTERY EFECTIVO]]="SI",_xlfn.XLOOKUP(Tabla2__2[[#This Row],[PREGUNTA]],ENCUESTA!G:G,ENCUESTA!D:D),"N/A") -> PRESENTACIÓN PERSONAL | N6: =IF(Tabla2__2[[#This Row],[MYSTERY EFECTIVO]]="SI",(IF(Tabla2__2[[#This Row],[CANAL]]="TRADICIONAL",_xlfn.XLOOKUP(Tabla2__2[[#This Row],[PREGUNTA]],ENCUESTA!G:G,ENCUESTA!A:A),IF(Tabla2__2[[#This Row],[CANAL]]="ESPECIALIZADO",_xlfn.XLOOKUP(Tabla2__2[[#This Row],[PREGUNTA]],ENCUESTA!G:G,ENCUESTA!B:B),IF(Tabla2__2[[#This Row],[CANAL]]="MODERNO",_xlfn.XLOOKUP(Tabla2__2[[#This Row],[PREGUNTA]],ENCUESTA!G:G,ENCUESTA!C:C))))),0) -> 1 | O6: =_xlfn.XLOOKUP(Tabla2__2[[#This Row],[PREGUNTA]],ENCUESTA!G:G,ENCUESTA!H:H) -> SI | P6: =IF(Tabla2__2[[#This Row],[RTA]]=Tabla2__2[[#This Row],[RTA CORRECTA]],Tabla2__2[[#This Row],[TOTAL PUNTAJE]],0) -> 1 | Q6: =IF(OR(H6="Dog Chow húmedo",H6="Cat Chow húmedo",H6="Fancy Feast",H6="Felix",H6="Proplan húmedo",H6="One húmedo",H6="Snack Abrazzos",H6="Snak Dentalife",H6="Arenilla Tidy Cat"),N6,0) -> 0
A7: NESTLE PURINA | B7: BARRANQUILLA | C7: ESPECIALIZADO | D7: ESPECIALIZADO | E7: 425892 | F7: 425892 - UNIMED | G7: CUENTA CON CAMISA DEL UNIFORME Y LOGOS SEGÚN EL CARGO (NEGRA / GRIS / ROJA / TURQUESA) (ES PERMITIDO USAR DEBAJO DE LA CAMISA BUSO MANGA LARGA NEGRO) | H7: SI | J7: 31389386 | K7: NestleP.5 | L7: =_xlfn.XLOOKUP(Tabla2__2[[#This Row],[CODIGO RUTA]],'DATA INFORME'!I:I,'DATA INFORME'!K:K) -> SI | M7: =IF(Tabla2__2[[#This Row],[MYSTERY EFECTIVO]]="SI",_xlfn.XLOOKUP(Tabla2__2[[#This Row],[PREGUNTA]],ENCUESTA!G:G,ENCUESTA!D:D),"N/A") -> PRESENTACIÓN PERSONAL | N7: =IF(Tabla2__2[[#This Row],[MYSTERY EFECTIVO]]="SI",(IF(Tabla2__2[[#This Row],[CANAL]]="TRADICIONAL",_xlfn.XLOOKUP(Tabla2__2[[#This Row],[PREGUNTA]],ENCUESTA!G:G,ENCUESTA!A:A),IF(Tabla2__2[[#This Row],[CANAL]]="ESPECIALIZADO",_xlfn.XLOOKUP(Tabla2__2[[#This Row],[PREGUNTA]],ENCUESTA!G:G,ENCUESTA!B:B),IF(Tabla2__2[[#This Row],[CANAL]]="MODERNO",_xlfn.XLOOKUP(Tabla2__2[[#This Row],[PREGUNTA]],ENCUESTA!G:G,ENCUESTA!C:C))))),0) -> 1 | O7: =_xlfn.XLOOKUP(Tabla2__2[[#This Row],[PREGUNTA]],ENCUESTA!G:G,ENCUESTA!H:H) -> SI | P7: =IF(Tabla2__2[[#This Row],[RTA]]=Tabla2__2[[#This Row],[RTA CORRECTA]],Tabla2__2[[#This Row],[TOTAL PUNTAJE]],0) -> 1 | Q7: =IF(OR(H7="Dog Chow húmedo",H7="Cat Chow húmedo",H7="Fancy Feast",H7="Felix",H7="Proplan húmedo",H7="One húmedo",H7="Snack Abrazzos",H7="Snak Dentalife",H7="Arenilla Tidy Cat"),N7,0) -> 0
A8: NESTLE PURINA | B8: BARRANQUILLA | C8: ESPECIALIZADO | D8: ESPECIALIZADO | E8: 425892 | F8: 425892 - UNIMED | G8: CUENTA CON PANTALON DEL UNIFORME SEGÚN EL CARGO (NEGRO / ROJO / TURQUESA / JEAN) | H8: SI | J8: 31389386 | K8: NestleP.5 | L8: =_xlfn.XLOOKUP(Tabla2__2[[#This Row],[CODIGO RUTA]],'DATA INFORME'!I:I,'DATA INFORME'!K:K) -> SI | M8: =IF(Tabla2__2[[#This Row],[MYSTERY EFECTIVO]]="SI",_xlfn.XLOOKUP(Tabla2__2[[#This Row],[PREGUNTA]],ENCUESTA!G:G,ENCUESTA!D:D),"N/A") -> PRESENTACIÓN PERSONAL | N8: =IF(Tabla2__2[[#This Row],[MYSTERY EFECTIVO]]="SI",(IF(Tabla2__2[[#This Row],[CANAL]]="TRADICIONAL",_xlfn.XLOOKUP(Tabla2__2[[#This Row],[PREGUNTA]],ENCUESTA!G:G,ENCUESTA!A:A),IF(Tabla2__2[[#This Row],[CANAL]]="ESPECIALIZADO",_xlfn.XLOOKUP(Tabla2__2[[#This Row],[PREGUNTA]],ENCUESTA!G:G,ENCUESTA!B:B),IF(Tabla2__2[[#This Row],[CANAL]]="MODERNO",_xlfn.XLOOKUP(Tabla2__2[[#This Row],[PREGUNTA]],ENCUESTA!G:G,ENCUESTA!C:C))))),0) -> 1 | O8: =_xlfn.XLOOKUP(Tabla2__2[[#This Row],[PREGUNTA]],ENCUESTA!G:G,ENCUESTA!H:H) -> SI | P8: =IF(Tabla2__2[[#This Row],[RTA]]=Tabla2__2[[#This Row],[RTA CORRECTA]],Tabla2__2[[#This Row],[TOTAL PUNTAJE]],0) -> 1 | Q8: =IF(OR(H8="Dog Chow húmedo",H8="Cat Chow húmedo",H8="Fancy Feast",H8="Felix",H8="Proplan húmedo",H8="One húmedo",H8="Snack Abrazzos",H8="Snak Dentalife",H8="Arenilla Tidy Cat"),N8,0) -> 0
A9: NESTLE PURINA | B9: BARRANQUILLA | C9: ESPECIALIZADO | D9: ESPECIALIZADO | E9: 425892 | F9: 425892 - UNIMED | G9: ¿CUMPLE HORARIO DE ENTRADA O SALIDA DE LA TIENDA? | H9: SI | J9: 31389386 | K9: NestleP.5 | L9: =_xlfn.XLOOKUP(Tabla2__2[[#This Row],[CODIGO RUTA]],'DATA INFORME'!I:I,'DATA INFORME'!K:K) -> SI | M9: =IF(Tabla2__2[[#This Row],[MYSTERY EFECTIVO]]="SI",_xlfn.XLOOKUP(Tabla2__2[[#This Row],[PREGUNTA]],ENCUESTA!G:G,ENCUESTA!D:D),"N/A") -> HORARIO | N9: =IF(Tabla2__2[[#This Row],[MYSTERY EFECTIVO]]="SI",(IF(Tabla2__2[[#This Row],[CANAL]]="TRADICIONAL",_xlfn.XLOOKUP(Tabla2__2[[#This Row],[PREGUNTA]],ENCUESTA!G:G,ENCUESTA!A:A),IF(Tabla2__2[[#This Row],[CANAL]]="ESPECIALIZADO",_xlfn.XLOOKUP(Tabla2__2[[#This Row],[PREGUNTA]],ENCUESTA!G:G,ENCUESTA!B:B),IF(Tabla2__2[[#This Row],[CANAL]]="MODERNO",_xlfn.XLOOKUP(Tabla2__2[[#This Row],[PREGUNTA]],ENCUESTA!G:G,ENCUESTA!C:C))))),0) -> 20 | O9: =_xlfn.XLOOKUP(Tabla2__2[[#This Row],[PREGUNTA]],ENCUESTA!G:G,ENCUESTA!H:H) -> SI | P9: =IF(Tabla2__2[[#This Row],[RTA]]=Tabla2__2[[#This Row],[RTA CORRECTA]],Tabla2__2[[#This Row],[TOTAL PUNTAJE]],0) -> 20 | Q9: =IF(OR(H9="Dog Chow húmedo",H9="Cat Chow húmedo",H9="Fancy Feast",H9="Felix",H9="Proplan húmedo",H9="One húmedo",H9="Snack Abrazzos",H9="Snak Dentalife",H9="Arenilla Tidy Cat"),N9,0) -> 0
A10: NESTLE PURINA | B10: BARRANQUILLA | C10: ESPECIALIZADO | D10: ESPECIALIZADO | E10: 425892 | F10: 425892 - UNIMED | G10: SE LOGRA REALIZAR LA AUDITORIA? | H10: SI | J10: 31389386 | K10: NestleP.5 | L10: =_xlfn.XLOOKUP(Tabla2__2[[#This Row],[CODIGO RUTA]],'DATA INFORME'!I:I,'DATA INFORME'!K:K) -> SI | M10: =IF(Tabla2__2[[#This Row],[MYSTERY EFECTIVO]]="SI",_xlfn.XLOOKUP(Tabla2__2[[#This Row],[PREGUNTA]],ENCUESTA!G:G,ENCUESTA!D:D),"N/A") -> N/A | N10: =IF(Tabla2__2[[#This Row],[MYSTERY EFECTIVO]]="SI",(IF(Tabla2__2[[#This Row],[CANAL]]="TRADICIONAL",_xlfn.XLOOKUP(Tabla2__2[[#This Row],[PREGUNTA]],ENCUESTA!G:G,ENCUESTA!A:A),IF(Tabla2__2[[#This Row],[CANAL]]="ESPECIALIZADO",_xlfn.XLOOKUP(Tabla2__2[[#This Row],[PREGUNTA]],ENCUESTA!G:G,ENCUESTA!B:B),IF(Tabla2__2[[#This Row],[CANAL]]="MODERNO",_xlfn.XLOOKUP(Tabla2__2[[#This Row],[PREGUNTA]],ENCUESTA!G:G,ENCUESTA!C:C))))),0) -> 0 | O10: =_xlfn.XLOOKUP(Tabla2__2[[#This Row],[PREGUNTA]],ENCUESTA!G:G,ENCUESTA!H:H) -> 0 | P10: =IF(Tabla2__2[[#This Row],[RTA]]=Tabla2__2[[#This Row],[RTA CORRECTA]],Tabla2__2[[#This Row],[TOTAL PUNTAJE]],0) -> 0 | Q10: =IF(OR(H10="Dog Chow húmedo",H10="Cat Chow húmedo",H10="Fancy Feast",H10="Felix",H10="Proplan húmedo",H10="One húmedo",H10="Snack Abrazzos",H10="Snak Dentalife",H10="Arenilla Tidy Cat"),N10,0) -> 0
A11: NESTLE PURINA | B11: BOGOTA | C11: ESPECIALIZADO | D11: ESPECIALIZADO | E11: 555967 | F11: LAIKA USAQUEN | G11: INDIQUE OBSERVACIÓN/NOVEDAD | H11: El PDV no maneja snacks por el momento | J11: 31379123 | K11: NestleP.1 | L11: =_xlfn.XLOOKUP(Tabla2__2[[#This Row],[CODIGO RUTA]],'DATA INFORME'!I:I,'DATA INFORME'!K:K) -> SI | M11: =IF(Tabla2__2[[#This Row],[MYSTERY EFECTIVO]]="SI",_xlfn.XLOOKUP(Tabla2__2[[#This Row],[PREGUNTA]],ENCUESTA!G:G,ENCUESTA!D:D),"N/A") -> N/A | N11: =IF(Tabla2__2[[#This Row],[MYSTERY EFECTIVO]]="SI",(IF(Tabla2__2[[#This Row],[CANAL]]="TRADICIONAL",_xlfn.XLOOKUP(Tabla2__2[[#This Row],[PREGUNTA]],ENCUESTA!G:G,ENCUESTA!A:A),IF(Tabla2__2[[#This Row],[CANAL]]="ESPECIALIZADO",_xlfn.XLOOKUP(Tabla2__2[[#This Row],[PREGUNTA]],ENCUESTA!G:G,ENCUESTA!B:B),IF(Tabla2__2[[#This Row],[CANAL]]="MODERNO",_xlfn.XLOOKUP(Tabla2__2[[#This Row],[PREGUNTA]],ENCUESTA!G:G,ENCUESTA!C:C))))),0) -> 0 | O11: =_xlfn.XLOOKUP(Tabla2__2[[#This Row],[PREGUNTA]],ENCUESTA!G:G,ENCUESTA!H:H) -> 0 | P11: =IF(Tabla2__2[[#This Row],[RTA]]=Tabla2__2[[#This Row],[RTA CORRECTA]],Tabla2__2[[#This Row],[TOTAL PUNTAJE]],0) -> 0 | Q11: =IF(OR(H11="Dog Chow húmedo",H11="Cat Chow húmedo",H11="Fancy Feast",H11="Felix",H11="Proplan húmedo",H11="One húmedo",H11="Snack Abrazzos",H11="Snak Dentalife",H11="Arenilla Tidy Cat"),N11,0) -> 0
A12: NESTLE PURINA | B12: BARRANQUILLA | C12: ESPECIALIZADO | D12: ESPECIALIZADO | E12: 425892 | F12: 425892 - UNIMED | G12: PRESENTA EXCESO DE MAQUILLAJE QUE NO CUMPLE CON EL CODIGO DE VESTIMENTA | H12: NO | J12: 31389386 | K12: NestleP.5 | L12: =_xlfn.XLOOKUP(Tabla2__2[[#This Row],[CODIGO RUTA]],'DATA INFORME'!I:I,'DATA INFORME'!K:K) -> SI | M12: =IF(Tabla2__2[[#This Row],[MYSTERY EFECTIVO]]="SI",_xlfn.XLOOKUP(Tabla2__2[[#This Row],[PREGUNTA]],ENCUESTA!G:G,ENCUESTA!D:D),"N/A") -> PRESENTACIÓN PERSONAL | N12: =IF(Tabla2__2[[#This Row],[MYSTERY EFECTIVO]]="SI",(IF(Tabla2__2[[#This Row],[CANAL]]="TRADICIONAL",_xlfn.XLOOKUP(Tabla2__2[[#This Row],[PREGUNTA]],ENCUESTA!G:G,ENCUESTA!A:A),IF(Tabla2__2[[#This Row],[CANAL]]="ESPECIALIZADO",_xlfn.XLOOKUP(Tabla2__2[[#This Row],[PREGUNTA]],ENCUESTA!G:G,ENCUESTA!B:B),IF(Tabla2__2[[#This Row],[CANAL]]="MODERNO",_xlfn.XLOOKUP(Tabla2__2[[#This Row],[PREGUNTA]],ENCUESTA!G:G,ENCUESTA!C:C))))),0) -> 1 | O12: =_xlfn.XLOOKUP(Tabla2__2[[#This Row],[PREGUNTA]],ENCUESTA!G:G,ENCUESTA!H:H) -> NO | P12: =IF(Tabla2__2[[#This Row],[RTA]]=Tabla2__2[[#This Row],[RTA CORRECTA]],Tabla2__2[[#This Row],[TOTAL PUNTAJE]],0) -> 1 | Q12: =IF(OR(H12="Dog Chow húmedo",H12="Cat Chow húmedo",H12="Fancy Feast",H12="Felix",H12="Proplan húmedo",H12="One húmedo",H12="Snack Abrazzos",H12="Snak Dentalife",H12="Arenilla Tidy Cat"),N12,0) -> 0
A13: NESTLE PURINA | B13: BOGOTA | C13: ESPECIALIZADO | D13: ESPECIALIZADO | E13: 555967 | F13: LAIKA USAQUEN | G13: DESEA AÑADIR ALGUNA OBSERVACION / NOVEDAD CON LA AUDITORIA REALIZADA? | H13: NO | J13: 31379123 | K13: NestleP.1 | L13: =_xlfn.XLOOKUP(Tabla2__2[[#This Row],[CODIGO RUTA]],'DATA INFORME'!I:I,'DATA INFORME'!K:K) -> SI | M13: =IF(Tabla2__2[[#This Row],[MYSTERY EFECTIVO]]="SI",_xlfn.XLOOKUP(Tabla2__2[[#This Row],[PREGUNTA]],ENCUESTA!G:G,ENCUESTA!D:D),"N/A") -> N/A | N13: =IF(Tabla2__2[[#This Row],[MYSTERY EFECTIVO]]="SI",(IF(Tabla2__2[[#This Row],[CANAL]]="TRADICIONAL",_xlfn.XLOOKUP(Tabla2__2[[#This Row],[PREGUNTA]],ENCUESTA!G:G,ENCUESTA!A:A),IF(Tabla2__2[[#This Row],[CANAL]]="ESPECIALIZADO",_xlfn.XLOOKUP(Tabla2__2[[#This Row],[PREGUNTA]],ENCUESTA!G:G,ENCUESTA!B:B),IF(Tabla2__2[[#This Row],[CANAL]]="MODERNO",_xlfn.XLOOKUP(Tabla2__2[[#This Row],[PREGUNTA]],ENCUESTA!G:G,ENCUESTA!C:C))))),0) -> 0 | O13: =_xlfn.XLOOKUP(Tabla2__2[[#This Row],[PREGUNTA]],ENCUESTA!G:G,ENCUESTA!H:H) -> 0 | P13: =IF(Tabla2__2[[#This Row],[RTA]]=Tabla2__2[[#This Row],[RTA CORRECTA]],Tabla2__2[[#This Row],[TOTAL PUNTAJE]],0) -> 0 | Q13: =IF(OR(H13="Dog Chow húmedo",H13="Cat Chow húmedo",H13="Fancy Feast",H13="Felix",H13="Proplan húmedo",H13="One húmedo",H13="Snack Abrazzos",H13="Snak Dentalife",H13="Arenilla Tidy Cat"),N13,0) -> 0
... A99: NESTLE PURINA | B99: BOGOTA | C99: TRADICIONAL | D99: TRADICIONAL | E99: 103263 | F99: AUTOSERVICIO AHORRAMAS | G99: INDIQUE OBSERVACIÓN/NOVEDAD | H99: El asesor o asesora no se encuentra en el punto de venta; se espero hasta pasadas las 8 am pero no se presentó, indican que se encuentra en incapacidad. | J99: 31465725 | K99: NestleP.1 | L99: =_xlfn.XLOOKUP(Tabla2__2[[#This Row],[CODIGO RUTA]],'DATA INFORME'!I:I,'DATA INFORME'!K:K) -> NO | M99: =IF(Tabla2__2[[#This Row],[MYSTERY EFECTIVO]]="SI",_xlfn.XLOOKUP(Tabla2__2[[#This Row],[PREGUNTA]],ENCUESTA!G:G,ENCUESTA!D:D),"N/A") -> N/A | N99: =IF(Tabla2__2[[#This Row],[MYSTERY EFECTIVO]]="SI",(IF(Tabla2__2[[#This Row],[CANAL]]="TRADICIONAL",_xlfn.XLOOKUP(Tabla2__2[[#This Row],[PREGUNTA]],ENCUESTA!G:G,ENCUESTA!A:A),IF(Tabla2__2[[#This Row],[CANAL]]="ESPECIALIZADO",_xlfn.XLOOKUP(Tabla2__2[[#This Row],[PREGUNTA]],ENCUESTA!G:G,ENCUESTA!B:B),IF(Tabla2__2[[#This Row],[CANAL]]="MODERNO",_xlfn.XLOOKUP(Tabla2__2[[#This Row],[PREGUNTA]],ENCUESTA!G:G,ENCUESTA!C:C))))),0) -> 0 | O99: =_xlfn.XLOOKUP(Tabla2__2[[#This Row],[PREGUNTA]],ENCUESTA!G:G,ENCUESTA!H:H) -> 0 | P99: =IF(Tabla2__2[[#This Row],[RTA]]=Tabla2__2[[#This Row],[RTA CORRECTA]],Tabla2__2[[#This Row],[TOTAL PUNTAJE]],0) -> 0 | Q99: =IF(OR(H99="Dog Chow húmedo",H99="Cat Chow húmedo",H99="Fancy Feast",H99="Felix",H99="Proplan húmedo",H99="One húmedo",H99="Snack Abrazzos",H99="Snak Dentalife",H99="Arenilla Tidy Cat"),N99,0) -> 0

Sheet Panel
A1: CANAL | B1: CIUDAD | C1: CODIGO PDV | D1: NOMBRE COMERCIAL | E1: Objetivo Mystery | F1: #PDV Objetivos | G1: #PDV Ejecutados | H1: # Visitas | I1: Mystery Ejecutado
A2: =_xlfn.XLOOKUP(Tabla1[[#This Row],[CODIGO PDV]],Export!H:H,Export!D:D,0) -> TRADICIONAL | B2: BOGOTA | C2: 103263 | D2: AUTOSERVICIO AHORRAMAS | E2: 1 | F2: 1 | G2: =IF(COUNTIFS(Export!I:I,Tabla1[[#This Row],[CODIGO PDV]])>0,1,0) -> 1 | H2: =COUNTIFS('DATA INFORME'!D:D,Tabla1[[#This Row],[CODIGO PDV]]) -> 1 | I2: =COUNTIFS('DATA INFORME'!D:D,Tabla1[[#This Row],[CODIGO PDV]],'DATA INFORME'!K:K,"SI") -> 0
A3: =_xlfn.XLOOKUP(Tabla1[[#This Row],[CODIGO PDV]],Export!H:H,Export!D:D,0) -> ESPECIALIZADO | B3: BOGOTA | C3: 555967 | D3: LAIKA USAQUEN | E3: 1 | F3: 1 | G3: =IF(COUNTIFS(Export!I:I,Tabla1[[#This Row],[CODIGO PDV]])>0,1,0) -> 1 | H3: =COUNTIFS('DATA INFORME'!D:D,Tabla1[[#This Row],[CODIGO PDV]]) -> 1 | I3: =COUNTIFS('DATA INFORME'!D:D,Tabla1[[#This Row],[CODIGO PDV]],'DATA INFORME'!K:K,"SI") -> 1
A4: =_xlfn.XLOOKUP(Tabla1[[#This Row],[CODIGO PDV]],Export!H:H,Export!D:D,0) -> TRADICIONAL | B4: CALI | C4: 127058 | D4: AHORRAMAS PASOANCHO | E4: 1 | F4: 1 | G4: =IF(COUNTIFS(Export!I:I,Tabla1[[#This Row],[CODIGO PDV]])>0,1,0) -> 1 | H4: =COUNTIFS('DATA INFORME'!D:D,Tabla1[[#This Row],[CODIGO PDV]]) -> 1 | I4: =COUNTIFS('DATA INFORME'!D:D,Tabla1[[#This Row],[CODIGO PDV]],'DATA INFORME'!K:K,"SI") -> 1
A5: =_xlfn.XLOOKUP(Tabla1[[#This Row],[CODIGO PDV]],Export!H:H,Export!D:D,0) -> ESPECIALIZADO | B5: BARRANQUILLA | C5: 425892 | D5: 425892 - UNIMED | E5: 1 | F5: 1 | G5: =IF(COUNTIFS(Export!I:I,Tabla1[[#This Row],[CODIGO PDV]])>0,1,0) -> 1 | H5: =COUNTIFS('DATA INFORME'!D:D,Tabla1[[#This Row],[CODIGO PDV]]) -> 1 | I5: =COUNTIFS('DATA INFORME'!D:D,Tabla1[[#This Row],[CODIGO PDV]],'DATA INFORME'!K:K,"SI") -> 1
A6: TRADICIONAL | B6: PEREIRA | C6: 152026 | D6: SUPERMERCADO LA 13 | E6: 1 | F6: 1 | G6: =IF(COUNTIFS(Export!I:I,Tabla1[[#This Row],[CODIGO PDV]])>0,1,0) -> 0 | H6: =COUNTIFS('DATA INFORME'!D:D,Tabla1[[#This Row],[CODIGO PDV]]) -> 0 | I6: =COUNTIFS('DATA INFORME'!D:D,Tabla1[[#This Row],[CODIGO PDV]],'DATA INFORME'!K:K,"SI") -> 0
A9: CANAL | B9: CIUDAD | C9: VUM | D9: NOMBRE PDV | E9: NOVEDAD
A10: TRADICIONAL | B10: BOGOTA | C10: 103263 | D10: AUTOSERVICIO AHORRAMAS | E10: El asesor o asesora no se encuentra en el punto de venta; se espero hasta pasadas las 8 am pero no se presentó, indican que se encuentra en incapacidad. | G10: No se tiene canal Moderno porque era en Cartagena HOMECENTER CARTAGENA pero no se pudo y el backup era en Barranquilla UNIMED canal Especializado
A11: TRADICIONAL | B11: PEREIRA | C11: 152026 | D11: SUPERMERCADO LA 13 | E11: Novedad con la persona encargada de hacer el mystery
E13: =UPPER(E12)

Sheet DATA INFORME
A1: ACTIVIDAD | B1: CIUDAD | C1: CADENA | D1: CODIGO PDV | E1: NOMBRE COMERCIAL | F1: CONSECUTIVO ENCUESTA | G1: NOMBRE ENCUESTA | H1: FECHA VISITA | I1: CODIGO RUTA | J1: USUARIO | K1: SE LOGRA REALIZAR LA AUDITORIA? | L1: ¿CUMPLE HORARIO DE ENTRADA O SALIDA DE LA TIENDA? | M1: CUENTA CON PANTALON DEL UNIFORME SEGÚN EL CARGO (NEGRO / ROJO / TURQUESA / JEAN) | N1: CUENTA CON CAMISA DEL UNIFORME Y LOGOS SEGÚN EL CARGO (NEGRA / GRIS / ROJA / TURQUESA) (ES PERMITIDO USAR DEBAJO DE LA CAMISA BUSO MANGA LARGA NEGRO) | O1: CUENTA CON CALZADO DE ACUERDO AL UNIFORME | P1: POSEE ALGUNA PRENDA ENCIMA DEL UNIFORME NO AUTORIZADA POR LA MARCA (UNICAMENTE ESTA PERMITIDO CHALECO DE SODIMAC Y EASY) | Q1: EL UNIFORME Y ZAPATOS SE ENCUENTRAN LIMPIOS Y EN BUEN ESTADO | R1: SU CABELLO LUCE LIMPIO, ORGANIZADO O RECOGIDO | S1: PRESENTA EXCESO DE MAQUILLAJE QUE NO CUMPLE CON EL CODIGO DE VESTIMENTA | T1: TIENE TATUAJES O PIERCINGS VISIBLES QUE NO CUMPLE CON EL CODIGO DE VESTIMENTA | U1: TIENE UÑAS LLAMATIVAS Y/O LARGAS QUE NO CUMPLE CON EL CODIGO DE VESTIMENTA | V1: USA ACCESORIOS QUE NO CUMPLE CON EL CODIGO DE VESTIMENTA | W1: EL LINEAL SE ENCUENTRA LIMPIO Y ORGANIZADO (EVIDENCIA POLVO O TIERRA EN EL PRODUCTO Y/O LINEAL) | X1: LOS PRODUCTOS TIENEN EL PRECIO Y ESTAN ACORDE O CORRESPONDIENTE A CADA REFERENCIA (REVISAR LA FECHA DE IMPRESIÓN DEL PRECIO) | Y1: LOS PRODUCTOS ESTAN SURTIDOS DE ACUERDO A PEPS O FIFO (REVISAR TANTO PRODUCTO SECO COMO HUMEDO) | Z1: CONOCE LOS INFALTABLES DEL PUNTO DE VENTA Y CUENTA CON EL MATERIAL DE APOYO (AYUDAVENTAS INFALTABLES) | AA1: CONOCE Y TIENE SURTIDO DE ACUERDO A LA ESTRATEGIA DE EXHIBICIÓN (ETAPAS DE VIDA - SEGMENTACIÓN DE MARCAS) | AB1: CONOCE EL % DE PARTICIPACIÓN QUE TIENE EN EL PUNTO DE VENTA E INFORMA CUAL ES ESE % (REALIZAR EL EJERCICIO DE CONTAR LAS CARAS PARA VALIDAR SI ES CORRECTO) | AC1: CONOCE LOS INFALTABLES DE PRO PLAN (GATOS Y PERROS) ALIMENTO SECO | AD1: EL PDV CUENTA CON EXHIBICIONES ADICIONALES? (REVISAR Y QUE SE VEA EN EL VIDEO) | AE1: LOS PRECIOS ESTAN EN LINEA CON LOS SUGERIDOS DEL CANAL? (REVISAR Y QUE SE VEA EN EL VIDEO) | AF1: MANEJA MARCA DE PERROS, GATOS O AMBOS, Y HAY PRESENCIA DE LA COMPETENCIA? (EN EL VIDEO DEBE QUEDAR LA VISUAL DE LAS MARCAS DE LA COMPETENCIA PRESENTES EN EL PDV) | AG1: CONOCE EL % DE PARTICIPACIÓN QUE TIENEN LAS MARCAS PURINA DENTRO DEL UNIVERSO? | AH1: SELECCIONE EL CANAL DEL PDV AUDITADO? | AI1: CT - CONOCE EL PRECIO DE LA PAQUETERIA (DOG CHOW 350G / 475G; CAT CHOW 200G? (Si el mercaderista informa que el PDV no lo permite implementar quedaria como N/A) | AJ1: CT - CONOCE LAS INNOVACIONES ALTA PROTEINA? ESTÁ DISPONIBLE EN PDV? | AK1: CT - CONOCE LAS INNOVACIONES - RISTRAS WET? ESTA DISPONIBLE EN PDV? | AL1: CT - CONOCE LAS INNOVACIONES - NUTRICION REFORZADA DE WET? ESTA DISPONIBLE EN PDV? | AM1: CT - LOS PRECIOS DE LAS REFERENCIAS DOG CHOW ESTAN ALINEADOS A LA NUEVA ESTRATEGIA? | AN1: DESEA AÑADIR ALGUNA OBSERVACION / NOVEDAD CON LA AUDITORIA REALIZADA? | AO1: INDIQUE OBSERVACIÓN/NOVEDAD | AP1: CE - SE ENCUENTRAN LAS INNOVACIONES (RENOVACIÓN DE POCUHES PRO PLAN, "FANCY 15 MARZO" FELIX TRIPLE DELICIUS Y MEGAMIX, DOG CHOW POUCHES DE ALTA PROTEINA Y MULTIPROTEINA) | AQ1: CE - SE ENCUENTRA EN EL LINEAL LAS REFERENCIAS 1,5 EN PU Y ADU DE LA MARCA EXCELLENT? | AR1: CE - SE ENCUENTRA LA NUEVA REFERENCIA DE EXCELLENT ESTIRILIZADO DE 1K? | AS1: CE - CUENTA CON LA PLANOMETRIA EN PDV (HORIZONTAL/VERTICAL) NO LADEADO? | AT1: CE - SE ENCUENTRA LA REFERENCIA PRO PLAN WET DE SALMON Y/URINARIO | AU1: CE - EL PDV MANEJA SNACKS, ESTAMOS PRESENTES? (REVISAR Y QUE SE VEA EN EL VIDEO)
A2: NESTLE PURINA | B2: BARRANQUILLA | C2: ESPECIALIZADO | D2: 425892 | E2: 425892 - UNIMED | F2: 1 | G2: AUDITORIA MAYO 2026 | H2: 46169.398 | I2: 31389386 | J2: NestleP.5 | K2: SI | L2: SI | M2: SI | N2: SI | O2: SI | P2: NO | Q2: SI | R2: SI | S2: NO | T2: NO | U2: NO | V2: NO | W2: SI | X2: SI | Y2: SI | Z2: SI | AA2: SI | AB2: SI | AC2: SI | AD2: SI | AE2: SI | AF2: SI | AG2: SI | AH2: ESPECIALIZADO | AN2: NO | AO2: no se encuentran Snacks pero eso no puede afectar la calificación de la chica | AP2: SI | AQ2: SI | AR2: SI | AS2: SI | AT2: SI | AU2: SI
A3: NESTLE PURINA | B3: BOGOTA | C3: ESPECIALIZADO | D3: 555967 | E3: LAIKA USAQUEN | F3: 1 | G3: AUDITORIA MAYO 2026 | H3: 46165 | I3: 31379123 | J3: NestleP.1 | K3: SI | L3: SI | M3: SI | N3: SI | O3: SI | P3: NO | Q3: SI | R3: SI | S3: NO | T3: NO | U3: NO | V3: NO | W3: SI | X3: SI | Y3: SI | Z3: SI | AA3: SI | AB3: SI | AC3: SI | AD3: SI | AE3: SI | AF3: SI | AG3: SI | AH3: ESPECIALIZADO | AN3: NO | AO3: El PDV no maneja snacks por el momento | AP3: SI | AQ3: SI | AR3: SI | AS3: SI | AT3: SI | AU3: SI
A4: NESTLE PURINA | B4: BOGOTA | C4: TRADICIONAL | D4: 103263 | E4: AUTOSERVICIO AHORRAMAS | F4: 1 | G4: AUDITORIA MAYO 2026 | H4: 46172 | I4: 31465725 | J4: NestleP.1 | K4: NO | AN4: SI | AO4: El asesor o asesora no se encuentra en el punto de venta; se espero hasta pasadas las 8 am pero no se presentó, indican que se encuentra en incapacidad.
A5: NESTLE PURINA | B5: CALI | C5: TRADICIONAL | D5: 127058 | E5: AHORRAMAS PASOANCHO | F5: 1 | G5: AUDITORIA MAYO 2026 | H5: 46163.572 | I5: 31364497 | J5: PREMISEUNP 51 | K5: SI | L5: SI | M5: SI | N5: SI | O5: SI | P5: NO | Q5: SI | R5: SI | S5: NO | T5: NO | U5: NO | V5: NO | W5: SI | X5: SI | Y5: SI | Z5: SI | AA5: SI | AB5: SI | AC5: SI | AD5: SI | AE5: SI | AF5: SI | AG5: SI | AH5: TRADICIONAL | AI5: SI | AJ5: SI | AK5: SI | AL5: SI | AM5: SI | AN5: NO | AO5: ninguna

Sheet Export
A1: ACTIVIDAD | B1: REGIONAL | C1: CIUDAD | D1: CANAL | E1: CADENA | F1: SUBCADENA | G1: ZONA | H1: RV | I1: CODIGO PDV | J1: NOMBRE COMERCIAL | K1: CODIGO EAN | L1: TIPO PUNTO VENTA | M1: CONSECUTIVO ENCUESTA | N1: NOMBRE ENCUESTA | O1: PREGUNTA | P1: RESPUESTA | Q1: CODIGO FOTO | R1: OBSERVACION | S1: FECHA VISITA | T1: FECHA INICIO VISITA | U1: FECHA CREACIÓN RESPUESTA | V1: CODIGO RUTA | W1: CLIENTE | X1: CODIGO EXHIBICION | Y1: NOMBRE EXHIBICION | Z1: NOMBRE USUARIO | AA1: USUARIO | AB1: NOMBRE SUPERVISOR | AC1: USUARIO SUPERVISOR
A2: NESTLE PURINA | B2: PACIFICO | C2: CALI | D2: TRADICIONAL | E2: TRADICIONAL | F2: TRADICIONAL | G2: CALI | H2: 127058 | I2: 127058 | J2: AHORRAMAS PASOANCHO | K2: 0 | L2: SUPERMERCADOS INDEPENDIENTES | M2: 1 | N2: AUDITORIA MAYO 2026 | O2: SE LOGRA REALIZAR LA AUDITORIA? | P2: SI | S2: 21/05/2026 13:43:07 | T2: 21/05/2026 13:43:22 | U2: 21/05/2026 13:43:44 | V2: 31364497 | W2: PRODUCTIVIDAD | Z2: ADRIANA PAREDES | AA2: PREMISEUNP 51 | AB2: JUAN CAMILO FIGUEROA | AC2: JUAN.FIGUEROA
A3: NESTLE PURINA | B3: PACIFICO | C3: CALI | D3: TRADICIONAL | E3: TRADICIONAL | F3: TRADICIONAL | G3: CALI | H3: 127058 | I3: 127058 | J3: AHORRAMAS PASOANCHO | K3: 0 | L3: SUPERMERCADOS INDEPENDIENTES | M3: 1 | N3: AUDITORIA MAYO 2026 | O3: ¿CUMPLE HORARIO DE ENTRADA O SALIDA DE LA TIENDA? | P3: SI | S3: 21/05/2026 13:43:07 | T3: 21/05/2026 13:43:22 | U3: 21/05/2026 13:43:49 | V3: 31364497 | W3: PRODUCTIVIDAD | Z3: ADRIANA PAREDES | AA3: PREMISEUNP 51 | AB3: JUAN CAMILO FIGUEROA | AC3: JUAN.FIGUEROA
A4: NESTLE PURINA | B4: PACIFICO | C4: CALI | D4: TRADICIONAL | E4: TRADICIONAL | F4: TRADICIONAL | G4: CALI | H4: 127058 | I4: 127058 | J4: AHORRAMAS PASOANCHO | K4: 0 | L4: SUPERMERCADOS INDEPENDIENTES | M4: 1 | N4: AUDITORIA MAYO 2026 | O4: CUENTA CON PANTALON DEL UNIFORME SEGÚN EL CARGO (NEGRO / ROJO / TURQUESA / JEAN) | P4: SI | S4: 21/05/2026 13:43:07 | T4: 21/05/2026 13:43:22 | U4: 21/05/2026 13:43:54 | V4: 31364497 | W4: PRODUCTIVIDAD | Z4: ADRIANA PAREDES | AA4: PREMISEUNP 51 | AB4: JUAN CAMILO FIGUEROA | AC4: JUAN.FIGUEROA
A5: NESTLE PURINA | B5: PACIFICO | C5: CALI | D5: TRADICIONAL | E5: TRADICIONAL | F5: TRADICIONAL | G5: CALI | H5: 127058 | I5: 127058 | J5: AHORRAMAS PASOANCHO | K5: 0 | L5: SUPERMERCADOS INDEPENDIENTES | M5: 1 | N5: AUDITORIA MAYO 2026 | O5: CUENTA CON CAMISA DEL UNIFORME Y LOGOS SEGÚN EL CARGO (NEGRA / GRIS / ROJA / TURQUESA) (ES PERMITIDO USAR DEBAJO DE LA CAMISA BUSO MANGA LARGA NEGRO) | P5: SI | S5: 21/05/2026 13:43:07 | T5: 21/05/2026 13:43:22 | U5: 21/05/2026 13:43:57 | V5: 31364497 | W5: PRODUCTIVIDAD | Z5: ADRIANA PAREDES | AA5: PREMISEUNP 51 | AB5: JUAN CAMILO FIGUEROA | AC5: JUAN.FIGUEROA
A6: NESTLE PURINA | B6: PACIFICO | C6: CALI | D6: TRADICIONAL | E6: TRADICIONAL | F6: TRADICIONAL | G6: CALI | H6: 127058 | I6: 127058 | J6: AHORRAMAS PASOANCHO | K6: 0 | L6: SUPERMERCADOS INDEPENDIENTES | M6: 1 | N6: AUDITORIA MAYO 2026 | O6: CUENTA CON CALZADO DE ACUERDO AL UNIFORME | P6: SI | S6: 21/05/2026 13:43:07 | T6: 21/05/2026 13:43:22 | U6: 21/05/2026 13:44:00 | V6: 31364497 | W6: PRODUCTIVIDAD | Z6: ADRIANA PAREDES | AA6: PREMISEUNP 51 | AB6: JUAN CAMILO FIGUEROA | AC6: JUAN.FIGUEROA
A7: NESTLE PURINA | B7: PACIFICO | C7: CALI | D7: TRADICIONAL | E7: TRADICIONAL | F7: TRADICIONAL | G7: CALI | H7: 127058 | I7: 127058 | J7: AHORRAMAS PASOANCHO | K7: 0 | L7: SUPERMERCADOS INDEPENDIENTES | M7: 1 | N7: AUDITORIA MAYO 2026 | O7: POSEE ALGUNA PRENDA ENCIMA DEL UNIFORME NO AUTORIZADA POR LA MARCA (UNICAMENTE ESTA PERMITIDO CHALECO DE SODIMAC Y EASY) | P7: NO | S7: 21/05/2026 13:43:07 | T7: 21/05/2026 13:43:22 | U7: 21/05/2026 13:44:04 | V7: 31364497 | W7: PRODUCTIVIDAD | Z7: ADRIANA PAREDES | AA7: PREMISEUNP 51 | AB7: JUAN CAMILO FIGUEROA | AC7: JUAN.FIGUEROA
A8: NESTLE PURINA | B8: PACIFICO | C8: CALI | D8: TRADICIONAL | E8: TRADICIONAL | F8: TRADICIONAL | G8: CALI | H8: 127058 | I8: 127058 | J8: AHORRAMAS PASOANCHO | K8: 0 | L8: SUPERMERCADOS INDEPENDIENTES | M8: 1 | N8: AUDITORIA MAYO 2026 | O8: EL UNIFORME Y ZAPATOS SE ENCUENTRAN LIMPIOS Y EN BUEN ESTADO | P8: SI | S8: 21/05/2026 13:43:07 | T8: 21/05/2026 13:43:22 | U8: 21/05/2026 13:44:08 | V8: 31364497 | W8: PRODUCTIVIDAD | Z8: ADRIANA PAREDES | AA8: PREMISEUNP 51 | AB8: JUAN CAMILO FIGUEROA | AC8: JUAN.FIGUEROA
A9: NESTLE PURINA | B9: PACIFICO | C9: CALI | D9: TRADICIONAL | E9: TRADICIONAL | F9: TRADICIONAL | G9: CALI | H9: 127058 | I9: 127058 | J9: AHORRAMAS PASOANCHO | K9: 0 | L9: SUPERMERCADOS INDEPENDIENTES | M9: 1 | N9: AUDITORIA MAYO 2026 | O9: SU CABELLO LUCE LIMPIO, ORGANIZADO O RECOGIDO | P9: SI | S9: 21/05/2026 13:43:07 | T9: 21/05/2026 13:43:22 | U9: 21/05/2026 13:44:12 | V9: 31364497 | W9: PRODUCTIVIDAD | Z9: ADRIANA PAREDES | AA9: PREMISEUNP 51 | AB9: JUAN CAMILO FIGUEROA | AC9: JUAN.FIGUEROA
A10: NESTLE PURINA | B10: PACIFICO | C10: CALI | D10: TRADICIONAL | E10: TRADICIONAL | F10: TRADICIONAL | G10: CALI | H10: 127058 | I10: 127058 | J10: AHORRAMAS PASOANCHO | K10: 0 | L10: SUPERMERCADOS INDEPENDIENTES | M10: 1 | N10: AUDITORIA MAYO 2026 | O10: PRESENTA EXCESO DE MAQUILLAJE QUE NO CUMPLE CON EL CODIGO DE VESTIMENTA | P10: NO | S10: 21/05/2026 13:43:07 | T10: 21/05/2026 13:43:22 | U10: 21/05/2026 13:44:17 | V10: 31364497 | W10: PRODUCTIVIDAD | Z10: ADRIANA PAREDES | AA10: PREMISEUNP 51 | AB10: JUAN CAMILO FIGUEROA | AC10: JUAN.FIGUEROA
A11: NESTLE PURINA | B11: PACIFICO | C11: CALI | D11: TRADICIONAL | E11: TRADICIONAL | F11: TRADICIONAL | G11: CALI | H11: 127058 | I11: 127058 | J11: AHORRAMAS PASOANCHO | K11: 0 | L11: SUPERMERCADOS INDEPENDIENTES | M11: 1 | N11: AUDITORIA MAYO 2026 | O11: TIENE TATUAJES O PIERCINGS VISIBLES QUE NO CUMPLE CON EL CODIGO DE VESTIMENTA | P11: NO | S11: 21/05/2026 13:43:07 | T11: 21/05/2026 13:43:22 | U11: 21/05/2026 13:44:34 | V11: 31364497 | W11: PRODUCTIVIDAD | Z11: ADRIANA PAREDES | AA11: PREMISEUNP 51 | AB11: JUAN CAMILO FIGUEROA | AC11: JUAN.FIGUEROA
A12: NESTLE PURINA | B12: PACIFICO | C12: CALI | D12: TRADICIONAL | E12: TRADICIONAL | F12: TRADICIONAL | G12: CALI | H12: 127058 | I12: 127058 | J12: AHORRAMAS PASOANCHO | K12: 0 | L12: SUPERMERCADOS INDEPENDIENTES | M12: 1 | N12: AUDITORIA MAYO 2026 | O12: TIENE UÑAS LLAMATIVAS Y/O LARGAS QUE NO CUMPLE CON EL CODIGO DE VESTIMENTA | P12: NO | S12: 21/05/2026 13:43:07 | T12: 21/05/2026 13:43:22 | U12: 21/05/2026 13:44:40 | V12: 31364497 | W12: PRODUCTIVIDAD | Z12: ADRIANA PAREDES | AA12: PREMISEUNP 51 | AB12: JUAN CAMILO FIGUEROA | AC12: JUAN.FIGUEROA
A13: NESTLE PURINA | B13: PACIFICO | C13: CALI | D13: TRADICIONAL | E13: TRADICIONAL | F13: TRADICIONAL | G13: CALI | H13: 127058 | I13: 127058 | J13: AHORRAMAS PASOANCHO | K13: 0 | L13: SUPERMERCADOS INDEPENDIENTES | M13: 1 | N13: AUDITORIA MAYO 2026 | O13: USA ACCESORIOS QUE NO CUMPLE CON EL CODIGO DE VESTIMENTA | P13: NO | S13: 21/05/2026 13:43:07 | T13: 21/05/2026 13:43:22 | U13: 21/05/2026 13:44:45 | V13: 31364497 | W13: PRODUCTIVIDAD | Z13: ADRIANA PAREDES | AA13: PREMISEUNP 51 | AB13: JUAN CAMILO FIGUEROA | AC13: JUAN.FIGUEROA
... A32: NESTLE PURINA | B32: PACIFICO | C32: CALI | D32: TRADICIONAL | E32: TRADICIONAL | F32: TRADICIONAL | G32: CALI | H32: 127058 | I32: 127058 | J32: AHORRAMAS PASOANCHO | K32: 0 | L32: SUPERMERCADOS INDEPENDIENTES | M32: 1 | N32: AUDITORIA MAYO 2026 | O32: INDIQUE OBSERVACIÓN/NOVEDAD | P32: ninguna | S32: 21/05/2026 13:43:07 | T32: 21/05/2026 13:43:22 | U32: 21/05/2026 13:47:39 | V32: 31364497 | W32: PRODUCTIVIDAD | Z32: ADRIANA PAREDES | AA32: PREMISEUNP 51 | AB32: JUAN CAMILO FIGUEROA | AC32: JUAN.FIGUEROA
A33: NESTLE PURINA | B33: CENTRO | C33: BOGOTA | D33: ESPECIALIZADO | E33: ESPECIALIZADO | F33: ESPECIALIZADO | G33: BOGOTA | H33: 555967 | I33: 555967 | J33: LAIKA USAQUEN | L33: SUPER IND | M33: 1 | N33: AUDITORIA MAYO 2026 | O33: SE LOGRA REALIZAR LA AUDITORIA? | P33: SI | S33: 23/05/2026 00:00:00 | T33: 25/05/2026 11:45:21 | U33: 25/05/2026 11:49:50 | V33: 31379123 | W33: PRODUCTIVIDAD | Z33: User 1 | AA33: NestleP.1 | AB33: CAMILO MONTAÑO RESTREPO | AC33: camilo.montano
A34: NESTLE PURINA | B34: CENTRO | C34: BOGOTA | D34: ESPECIALIZADO | E34: ESPECIALIZADO | F34: ESPECIALIZADO | G34: BOGOTA | H34: 555967 | I34: 555967 | J34: LAIKA USAQUEN | L34: SUPER IND | M34: 1 | N34: AUDITORIA MAYO 2026 | O34: ¿CUMPLE HORARIO DE ENTRADA O SALIDA DE LA TIENDA? | P34: SI | S34: 23/05/2026 00:00:00 | T34: 25/05/2026 11:45:21 | U34: 25/05/2026 11:49:50 | V34: 31379123 | W34: PRODUCTIVIDAD | Z34: User 1 | AA34: NestleP.1 | AB34: CAMILO MONTAÑO RESTREPO | AC34: camilo.montano
A35: NESTLE PURINA | B35: CENTRO | C35: BOGOTA | D35: ESPECIALIZADO | E35: ESPECIALIZADO | F35: ESPECIALIZADO | G35: BOGOTA | H35: 555967 | I35: 555967 | J35: LAIKA USAQUEN | L35: SUPER IND | M35: 1 | N35: AUDITORIA MAYO 2026 | O35: CUENTA CON PANTALON DEL UNIFORME SEGÚN EL CARGO (NEGRO / ROJO / TURQUESA / JEAN) | P35: SI | S35: 23/05/2026 00:00:00 | T35: 25/05/2026 11:45:21 | U35: 25/05/2026 11:49:50 | V35: 31379123 | W35: PRODUCTIVIDAD | Z35: User 1 | AA35: NestleP.1 | AB35: CAMILO MONTAÑO RESTREPO | AC35: camilo.montano
A36: NESTLE PURINA | B36: CENTRO | C36: BOGOTA | D36: ESPECIALIZADO | E36: ESPECIALIZADO | F36: ESPECIALIZADO | G36: BOGOTA | H36: 555967 | I36: 555967 | J36: LAIKA USAQUEN | L36: SUPER IND | M36: 1 | N36: AUDITORIA MAYO 2026 | O36: CUENTA CON CAMISA DEL UNIFORME Y LOGOS SEGÚN EL CARGO (NEGRA / GRIS / ROJA / TURQUESA) (ES PERMITIDO USAR DEBAJO DE LA CAMISA BUSO MANGA LARGA NEGRO) | P36: SI | S36: 23/05/2026 00:00:00 | T36: 25/05/2026 11:45:21 | U36: 25/05/2026 11:49:50 | V36: 31379123 | W36: PRODUCTIVIDAD | Z36: User 1 | AA36: NestleP.1 | AB36: CAMILO MONTAÑO RESTREPO | AC36: camilo.montano
A37: NESTLE PURINA | B37: CENTRO | C37: BOGOTA | D37: ESPECIALIZADO | E37: ESPECIALIZADO | F37: ESPECIALIZADO | G37: BOGOTA | H37: 555967 | I37: 555967 | J37: LAIKA USAQUEN | L37: SUPER IND | M37: 1 | N37: AUDITORIA MAYO 2026 | O37: CUENTA CON CALZADO DE ACUERDO AL UNIFORME | P37: SI | S37: 23/05/2026 00:00:00 | T37: 25/05/2026 11:45:21 | U37: 25/05/2026 11:49:50 | V37: 31379123 | W37: PRODUCTIVIDAD | Z37: User 1 | AA37: NestleP.1 | AB37: CAMILO MONTAÑO RESTREPO | AC37: camilo.montano
A38: NESTLE PURINA | B38: CENTRO | C38: BOGOTA | D38: ESPECIALIZADO | E38: ESPECIALIZADO | F38: ESPECIALIZADO | G38: BOGOTA | H38: 555967 | I38: 555967 | J38: LAIKA USAQUEN | L38: SUPER IND | M38: 1 | N38: AUDITORIA MAYO 2026 | O38: POSEE ALGUNA PRENDA ENCIMA DEL UNIFORME NO AUTORIZADA POR LA MARCA (UNICAMENTE ESTA PERMITIDO CHALECO DE SODIMAC Y EASY) | P38: NO | S38: 23/05/2026 00:00:00 | T38: 25/05/2026 11:45:21 | U38: 25/05/2026 11:49:50 | V38: 31379123 | W38: PRODUCTIVIDAD | Z38: User 1 | AA38: NestleP.1 | AB38: CAMILO MONTAÑO RESTREPO | AC38: camilo.montano
A39: NESTLE PURINA | B39: CENTRO | C39: BOGOTA | D39: ESPECIALIZADO | E39: ESPECIALIZADO | F39: ESPECIALIZADO | G39: BOGOTA | H39: 555967 | I39: 555967 | J39: LAIKA USAQUEN | L39: SUPER IND | M39: 1 | N39: AUDITORIA MAYO 2026 | O39: EL UNIFORME Y ZAPATOS SE ENCUENTRAN LIMPIOS Y EN BUEN ESTADO | P39: SI | S39: 23/05/2026 00:00:00 | T39: 25/05/2026 11:45:21 | U39: 25/05/2026 11:49:50 | V39: 31379123 | W39: PRODUCTIVIDAD | Z39: User 1 | AA39: NestleP.1 | AB39: CAMILO MONTAÑO RESTREPO | AC39: camilo.montano
A40: NESTLE PURINA | B40: CENTRO | C40: BOGOTA | D40: ESPECIALIZADO | E40: ESPECIALIZADO | F40: ESPECIALIZADO | G40: BOGOTA | H40: 555967 | I40: 555967 | J40: LAIKA USAQUEN | L40: SUPER IND | M40: 1 | N40: AUDITORIA MAYO 2026 | O40: SU CABELLO LUCE LIMPIO, ORGANIZADO O RECOGIDO | P40: SI | S40: 23/05/2026 00:00:00 | T40: 25/05/2026 11:45:21 | U40: 25/05/2026 11:49:50 | V40: 31379123 | W40: PRODUCTIVIDAD | Z40: User 1 | AA40: NestleP.1 | AB40: CAMILO MONTAÑO RESTREPO | AC40: camilo.montano
A41: NESTLE PURINA | B41: CENTRO | C41: BOGOTA | D41: ESPECIALIZADO | E41: ESPECIALIZADO | F41: ESPECIALIZADO | G41: BOGOTA | H41: 555967 | I41: 555967 | J41: LAIKA USAQUEN | L41: SUPER IND | M41: 1 | N41: AUDITORIA MAYO 2026 | O41: PRESENTA EXCESO DE MAQUILLAJE QUE NO CUMPLE CON EL CODIGO DE VESTIMENTA | P41: NO | S41: 23/05/2026 00:00:00 | T41: 25/05/2026 11:45:21 | U41: 25/05/2026 11:49:50 | V41: 31379123 | W41: PRODUCTIVIDAD | Z41: User 1 | AA41: NestleP.1 | AB41: CAMILO MONTAÑO RESTREPO | AC41: camilo.montano
A42: NESTLE PURINA | B42: CENTRO | C42: BOGOTA | D42: ESPECIALIZADO | E42: ESPECIALIZADO | F42: ESPECIALIZADO | G42: BOGOTA | H42: 555967 | I42: 555967 | J42: LAIKA USAQUEN | L42: SUPER IND | M42: 1 | N42: AUDITORIA MAYO 2026 | O42: TIENE TATUAJES O PIERCINGS VISIBLES QUE NO CUMPLE CON EL CODIGO DE VESTIMENTA | P42: NO | S42: 23/05/2026 00:00:00 | T42: 25/05/2026 11:45:21 | U42: 25/05/2026 11:49:50 | V42: 31379123 | W42: PRODUCTIVIDAD | Z42: User 1 | AA42: NestleP.1 | AB42: CAMILO MONTAÑO RESTREPO | AC42: camilo.montano
A43: NESTLE PURINA | B43: CENTRO | C43: BOGOTA | D43: ESPECIALIZADO | E43: ESPECIALIZADO | F43: ESPECIALIZADO | G43: BOGOTA | H43: 555967 | I43: 555967 | J43: LAIKA USAQUEN | L43: SUPER IND | M43: 1 | N43: AUDITORIA MAYO 2026 | O43: TIENE UÑAS LLAMATIVAS Y/O LARGAS QUE NO CUMPLE CON EL CODIGO DE VESTIMENTA | P43: NO | S43: 23/05/2026 00:00:00 | T43: 25/05/2026 11:45:21 | U43: 25/05/2026 11:49:50 | V43: 31379123 | W43: PRODUCTIVIDAD | Z43: User 1 | AA43: NestleP.1 | AB43: CAMILO MONTAÑO RESTREPO | AC43: camilo.montano
A44: NESTLE PURINA | B44: CENTRO | C44: BOGOTA | D44: ESPECIALIZADO | E44: ESPECIALIZADO | F44: ESPECIALIZADO | G44: BOGOTA | H44: 555967 | I44: 555967 | J44: LAIKA USAQUEN | L44: SUPER IND | M44: 1 | N44: AUDITORIA MAYO 2026 | O44: USA ACCESORIOS QUE NO CUMPLE CON EL CODIGO DE VESTIMENTA | P44: NO | S44: 23/05/2026 00:00:00 | T44: 25/05/2026 11:45:21 | U44: 25/05/2026 11:49:50 | V44: 31379123 | W44: PRODUCTIVIDAD | Z44: User 1 | AA44: NestleP.1 | AB44: CAMILO MONTAÑO RESTREPO | AC44: camilo.montano
... A64: NESTLE PURINA | B64: CENTRO | C64: BOGOTA | D64: ESPECIALIZADO | E64: ESPECIALIZADO | F64: ESPECIALIZADO | G64: BOGOTA | H64: 555967 | I64: 555967 | J64: LAIKA USAQUEN | L64: SUPER IND | M64: 1 | N64: AUDITORIA MAYO 2026 | O64: INDIQUE OBSERVACIÓN/NOVEDAD | P64: El PDV no maneja snacks por el momento | S64: 23/05/2026 00:00:00 | T64: 25/05/2026 11:45:21 | U64: 25/05/2026 11:49:50 | V64: 31379123 | W64: PRODUCTIVIDAD | Z64: User 1 | AA64: NestleP.1 | AB64: CAMILO MONTAÑO RESTREPO | AC64: camilo.montano
A65: NESTLE PURINA | B65: COSTA | C65: BARRANQUILLA | D65: ESPECIALIZADO | E65: ESPECIALIZADO | F65: ESPECIALIZADO | G65: COSTA | H65: 425892 | I65: 425892 | J65: 425892 - UNIMED | K65: 0 | L65: STO 039 CHIQUINQUIRA | M65: 1 | N65: AUDITORIA MAYO 2026 | O65: SE LOGRA REALIZAR LA AUDITORIA? | P65: SI | S65: 27/05/2026 09:33:10 | T65: 27/05/2026 09:33:15 | U65: 27/05/2026 09:33:20 | V65: 31389386 | W65: PRODUCTIVIDAD | Z65: User 5 | AA65: NestleP.5 | AB65: CAMILO MONTAÑO RESTREPO | AC65: camilo.montano
A66: NESTLE PURINA | B66: COSTA | C66: BARRANQUILLA | D66: ESPECIALIZADO | E66: ESPECIALIZADO | F66: ESPECIALIZADO | G66: COSTA | H66: 425892 | I66: 425892 | J66: 425892 - UNIMED | K66: 0 | L66: STO 039 CHIQUINQUIRA | M66: 1 | N66: AUDITORIA MAYO 2026 | O66: ¿CUMPLE HORARIO DE ENTRADA O SALIDA DE LA TIENDA? | P66: SI | S66: 27/05/2026 09:33:10 | T66: 27/05/2026 09:33:15 | U66: 27/05/2026 09:33:28 | V66: 31389386 | W66: PRODUCTIVIDAD | Z66: User 5 | AA66: NestleP.5 | AB66: CAMILO MONTAÑO RESTREPO | AC66: camilo.montano
A67: NESTLE PURINA | B67: COSTA | C67: BARRANQUILLA | D67: ESPECIALIZADO | E67: ESPECIALIZADO | F67: ESPECIALIZADO | G67: COSTA | H67: 425892 | I67: 425892 | J67: 425892 - UNIMED | K67: 0 | L67: STO 039 CHIQUINQUIRA | M67: 1 | N67: AUDITORIA MAYO 2026 | O67: CUENTA CON PANTALON DEL UNIFORME SEGÚN EL CARGO (NEGRO / ROJO / TURQUESA / JEAN) | P67: SI | S67: 27/05/2026 09:33:10 | T67: 27/05/2026 09:33:15 | U67: 27/05/2026 09:33:34 | V67: 31389386 | W67: PRODUCTIVIDAD | Z67: User 5 | AA67: NestleP.5 | AB67: CAMILO MONTAÑO RESTREPO | AC67: camilo.montano
A68: NESTLE PURINA | B68: COSTA | C68: BARRANQUILLA | D68: ESPECIALIZADO | E68: ESPECIALIZADO | F68: ESPECIALIZADO | G68: COSTA | H68: 425892 | I68: 425892 | J68: 425892 - UNIMED | K68: 0 | L68: STO 039 CHIQUINQUIRA | M68: 1 | N68: AUDITORIA MAYO 2026 | O68: CUENTA CON CAMISA DEL UNIFORME Y LOGOS SEGÚN EL CARGO (NEGRA / GRIS / ROJA / TURQUESA) (ES PERMITIDO USAR DEBAJO DE LA CAMISA BUSO MANGA LARGA NEGRO) | P68: SI | S68: 27/05/2026 09:33:10 | T68: 27/05/2026 09:33:15 | U68: 27/05/2026 09:33:39 | V68: 31389386 | W68: PRODUCTIVIDAD | Z68: User 5 | AA68: NestleP.5 | AB68: CAMILO MONTAÑO RESTREPO | AC68: camilo.montano
A69: NESTLE PURINA | B69: COSTA | C69: BARRANQUILLA | D69: ESPECIALIZADO | E69: ESPECIALIZADO | F69: ESPECIALIZADO | G69: COSTA | H69: 425892 | I69: 425892 | J69: 425892 - UNIMED | K69: 0 | L69: STO 039 CHIQUINQUIRA | M69: 1 | N69: AUDITORIA MAYO 2026 | O69: CUENTA CON CALZADO DE ACUERDO AL UNIFORME | P69: SI | S69: 27/05/2026 09:33:10 | T69: 27/05/2026 09:33:15 | U69: 27/05/2026 09:33:41 | V69: 31389386 | W69: PRODUCTIVIDAD | Z69: User 5 | AA69: NestleP.5 | AB69: CAMILO MONTAÑO RESTREPO | AC69: camilo.montano
A70: NESTLE PURINA | B70: COSTA | C70: BARRANQUILLA | D70: ESPECIALIZADO | E70: ESPECIALIZADO | F70: ESPECIALIZADO | G70: COSTA | H70: 425892 | I70: 425892 | J70: 425892 - UNIMED | K70: 0 | L70: STO 039 CHIQUINQUIRA | M70: 1 | N70: AUDITORIA MAYO 2026 | O70: POSEE ALGUNA PRENDA ENCIMA DEL UNIFORME NO AUTORIZADA POR LA MARCA (UNICAMENTE ESTA PERMITIDO CHALECO DE SODIMAC Y EASY) | P70: NO | S70: 27/05/2026 09:33:10 | T70: 27/05/2026 09:33:15 | U70: 27/05/2026 09:33:48 | V70: 31389386 | W70: PRODUCTIVIDAD | Z70: User 5 | AA70: NestleP.5 | AB70: CAMILO MONTAÑO RESTREPO | AC70: camilo.montano
A71: NESTLE PURINA | B71: COSTA | C71: BARRANQUILLA | D71: ESPECIALIZADO | E71: ESPECIALIZADO | F71: ESPECIALIZADO | G71: COSTA | H71: 425892 | I71: 425892 | J71: 425892 - UNIMED | K71: 0 | L71: STO 039 CHIQUINQUIRA | M71: 1 | N71: AUDITORIA MAYO 2026 | O71: EL UNIFORME Y ZAPATOS SE ENCUENTRAN LIMPIOS Y EN BUEN ESTADO | P71: SI | S71: 27/05/2026 09:33:10 | T71: 27/05/2026 09:33:15 | U71: 27/05/2026 09:34:02 | V71: 31389386 | W71: PRODUCTIVIDAD | Z71: User 5 | AA71: NestleP.5 | AB71: CAMILO MONTAÑO RESTREPO | AC71: camilo.montano
A72: NESTLE PURINA | B72: COSTA | C72: BARRANQUILLA | D72: ESPECIALIZADO | E72: ESPECIALIZADO | F72: ESPECIALIZADO | G72: COSTA | H72: 425892 | I72: 425892 | J72: 425892 - UNIMED | K72: 0 | L72: STO 039 CHIQUINQUIRA | M72: 1 | N72: AUDITORIA MAYO 2026 | O72: SU CABELLO LUCE LIMPIO, ORGANIZADO O RECOGIDO | P72: SI | S72: 27/05/2026 09:33:10 | T72: 27/05/2026 09:33:15 | U72: 27/05/2026 09:34:04 | V72: 31389386 | W72: PRODUCTIVIDAD | Z72: User 5 | AA72: NestleP.5 | AB72: CAMILO MONTAÑO RESTREPO | AC72: camilo.montano
A73: NESTLE PURINA | B73: COSTA | C73: BARRANQUILLA | D73: ESPECIALIZADO | E73: ESPECIALIZADO | F73: ESPECIALIZADO | G73: COSTA | H73: 425892 | I73: 425892 | J73: 425892 - UNIMED | K73: 0 | L73: STO 039 CHIQUINQUIRA | M73: 1 | N73: AUDITORIA MAYO 2026 | O73: PRESENTA EXCESO DE MAQUILLAJE QUE NO CUMPLE CON EL CODIGO DE VESTIMENTA | P73: NO | S73: 27/05/2026 09:33:10 | T73: 27/05/2026 09:33:15 | U73: 27/05/2026 09:34:07 | V73: 31389386 | W73: PRODUCTIVIDAD | Z73: User 5 | AA73: NestleP.5 | AB73: CAMILO MONTAÑO RESTREPO | AC73: camilo.montano
A74: NESTLE PURINA | B74: COSTA | C74: BARRANQUILLA | D74: ESPECIALIZADO | E74: ESPECIALIZADO | F74: ESPECIALIZADO | G74: COSTA | H74: 425892 | I74: 425892 | J74: 425892 - UNIMED | K74: 0 | L74: STO 039 CHIQUINQUIRA | M74: 1 | N74: AUDITORIA MAYO 2026 | O74: TIENE TATUAJES O PIERCINGS VISIBLES QUE NO CUMPLE CON EL CODIGO DE VESTIMENTA | P74: NO | S74: 27/05/2026 09:33:10 | T74: 27/05/2026 09:33:15 | U74: 27/05/2026 09:34:09 | V74: 31389386 | W74: PRODUCTIVIDAD | Z74: User 5 | AA74: NestleP.5 | AB74: CAMILO MONTAÑO RESTREPO | AC74: camilo.montano
A75: NESTLE PURINA | B75: COSTA | C75: BARRANQUILLA | D75: ESPECIALIZADO | E75: ESPECIALIZADO | F75: ESPECIALIZADO | G75: COSTA | H75: 425892 | I75: 425892 | J75: 425892 - UNIMED | K75: 0 | L75: STO 039 CHIQUINQUIRA | M75: 1 | N75: AUDITORIA MAYO 2026 | O75: TIENE UÑAS LLAMATIVAS Y/O LARGAS QUE NO CUMPLE CON EL CODIGO DE VESTIMENTA | P75: NO | S75: 27/05/2026 09:33:10 | T75: 27/05/2026 09:33:15 | U75: 27/05/2026 09:34:12 | V75: 31389386 | W75: PRODUCTIVIDAD | Z75: User 5 | AA75: NestleP.5 | AB75: CAMILO MONTAÑO RESTREPO | AC75: camilo.montano
A76: NESTLE PURINA | B76: COSTA | C76: BARRANQUILLA | D76: ESPECIALIZADO | E76: ESPECIALIZADO | F76: ESPECIALIZADO | G76: COSTA | H76: 425892 | I76: 425892 | J76: 425892 - UNIMED | K76: 0 | L76: STO 039 CHIQUINQUIRA | M76: 1 | N76: AUDITORIA MAYO 2026 | O76: USA ACCESORIOS QUE NO CUMPLE CON EL CODIGO DE VESTIMENTA | P76: NO | S76: 27/05/2026 09:33:10 | T76: 27/05/2026 09:33:15 | U76: 27/05/2026 09:34:35 | V76: 31389386 | W76: PRODUCTIVIDAD | Z76: User 5 | AA76: NestleP.5 | AB76: CAMILO MONTAÑO RESTREPO | AC76: camilo.montano
... A99: NESTLE PURINA | B99: CENTRO | C99: BOGOTA | D99: TRADICIONAL | E99: TRADICIONAL | F99: TRADICIONAL | G99: BOGOTA | H99: 103263 | I99: 103263 | J99: AUTOSERVICIO AHORRAMAS | K99: 0 | L99: AUTOSERVICIO AHORRAMAS | M99: 1 | N99: AUDITORIA MAYO 2026 | O99: INDIQUE OBSERVACIÓN/NOVEDAD | P99: El asesor o asesora no se encuentra en el punto de venta; se espero hasta pasadas las 8 am pero no se presentó, indican que se encuentra en incapacidad. | S99: 30/05/2026 00:00:00 | T99: 30/05/2026 08:51:34 | U99: 30/05/2026 08:54:29 | V99: 31465725 | W99: PRODUCTIVIDAD | Z99: User 1 | AA99: NestleP.1 | AB99: CAMILO MONTAÑO RESTREPO | AC99: camilo.montano

Sheet ENCUESTA
A1: TRADICIONAL | B1: ESPECIALIZADO | C1: MODERNO | D1: CLUSTER | E1: PESO | F1: TIPO | G1: PREGUNTA | H1: RTA CORRECTA | J1: CLUSTER | K1: PESO CLUSTER
A2: 0 | B2: 0 | C2: 0 | D2: N/A | E2: 0 | F2: UNICA | G2: SE LOGRA REALIZAR LA AUDITORIA? | J2: PRESENTACIÓN PERSONAL | K2: 0.1
A3: 20 | B3: 20 | C3: 20 | D3: HORARIO | E3: 20 | F3: UNICA | G3: ¿CUMPLE HORARIO DE ENTRADA O SALIDA DE LA TIENDA? | H3: SI | J3: HORARIO | K3: 0.2
A4: =10/10 -> 1 | B4: =10/10 -> 1 | C4: =10/10 -> 1 | D4: PRESENTACIÓN PERSONAL | E4: =10/10 -> 1 | F4: UNICA | G4: CUENTA CON PANTALON DEL UNIFORME SEGÚN EL CARGO (NEGRO / ROJO / TURQUESA / JEAN) | H4: SI | J4: EJECUCION DEL PDV | K4: 0.3
A5: =10/10 -> 1 | B5: =10/10 -> 1 | C5: =10/10 -> 1 | D5: PRESENTACIÓN PERSONAL | E5: =10/10 -> 1 | F5: UNICA | G5: CUENTA CON CAMISA DEL UNIFORME Y LOGOS SEGÚN EL CARGO (NEGRA / GRIS / ROJA / TURQUESA) (ES PERMITIDO USAR DEBAJO DE LA CAMISA BUSO MANGA LARGA NEGRO) | H5: SI | J5: ACTIVIDADES DEL MES | K5: 0.4
A6: =10/10 -> 1 | B6: =10/10 -> 1 | C6: =10/10 -> 1 | D6: PRESENTACIÓN PERSONAL | E6: =10/10 -> 1 | F6: UNICA | G6: CUENTA CON CALZADO DE ACUERDO AL UNIFORME | H6: SI | J6: TOTAL GENERAL | K6: =SUM(K2:K6) -> 1
A7: =10/10 -> 1 | B7: =10/10 -> 1 | C7: =10/10 -> 1 | D7: PRESENTACIÓN PERSONAL | E7: =10/10 -> 1 | F7: UNICA | G7: POSEE ALGUNA PRENDA ENCIMA DEL UNIFORME NO AUTORIZADA POR LA MARCA (UNICAMENTE ESTA PERMITIDO CHALECO DE SODIMAC Y EASY) | H7: NO
A8: =10/10 -> 1 | B8: =10/10 -> 1 | C8: =10/10 -> 1 | D8: PRESENTACIÓN PERSONAL | E8: =10/10 -> 1 | F8: UNICA | G8: EL UNIFORME Y ZAPATOS SE ENCUENTRAN LIMPIOS Y EN BUEN ESTADO | H8: SI
A9: =10/10 -> 1 | B9: =10/10 -> 1 | C9: =10/10 -> 1 | D9: PRESENTACIÓN PERSONAL | E9: =10/10 -> 1 | F9: UNICA | G9: SU CABELLO LUCE LIMPIO, ORGANIZADO O RECOGIDO | H9: SI
A10: =10/10 -> 1 | B10: =10/10 -> 1 | C10: =10/10 -> 1 | D10: PRESENTACIÓN PERSONAL | E10: =10/10 -> 1 | F10: UNICA | G10: PRESENTA EXCESO DE MAQUILLAJE QUE NO CUMPLE CON EL CODIGO DE VESTIMENTA | H10: NO
A11: =10/10 -> 1 | B11: =10/10 -> 1 | C11: =10/10 -> 1 | D11: PRESENTACIÓN PERSONAL | E11: =10/10 -> 1 | F11: UNICA | G11: TIENE TATUAJES O PIERCINGS VISIBLES QUE NO CUMPLE CON EL CODIGO DE VESTIMENTA | H11: NO
A12: =10/10 -> 1 | B12: =10/10 -> 1 | C12: =10/10 -> 1 | D12: PRESENTACIÓN PERSONAL | E12: =10/10 -> 1 | F12: UNICA | G12: TIENE UÑAS LLAMATIVAS Y/O LARGAS QUE NO CUMPLE CON EL CODIGO DE VESTIMENTA | H12: NO
A13: =10/10 -> 1 | B13: =10/10 -> 1 | C13: =10/10 -> 1 | D13: PRESENTACIÓN PERSONAL | E13: =10/10 -> 1 | F13: UNICA | G13: USA ACCESORIOS QUE NO CUMPLE CON EL CODIGO DE VESTIMENTA | H13: NO
A14: =30/11 -> 2.7272727 | B14: =30/11 -> 2.7272727 | C14: =30/11 -> 2.7272727 | D14: EJECUCIÓN DEL PDV | E14: =30/11 -> 2.7272727 | F14: UNICA | G14: EL LINEAL SE ENCUENTRA LIMPIO Y ORGANIZADO (EVIDENCIA POLVO O TIERRA EN EL PRODUCTO Y/O LINEAL) | H14: SI
A15: =30/11 -> 2.7272727 | B15: =30/11 -> 2.7272727 | C15: =30/11 -> 2.7272727 | D15: EJECUCIÓN DEL PDV | E15: =30/11 -> 2.7272727 | F15: UNICA | G15: LOS PRODUCTOS TIENEN EL PRECIO Y ESTAN ACORDE O CORRESPONDIENTE A CADA REFERENCIA (REVISAR LA FECHA DE IMPRESIÓN DEL PRECIO) | H15: SI
A16: =30/11 -> 2.7272727 | B16: =30/11 -> 2.7272727 | C16: =30/11 -> 2.7272727 | D16: EJECUCIÓN DEL PDV | E16: =30/11 -> 2.7272727 | F16: UNICA | G16: LOS PRODUCTOS ESTAN SURTIDOS DE ACUERDO A PEPS O FIFO (REVISAR TANTO PRODUCTO SECO COMO HUMEDO) | H16: SI
A17: =30/11 -> 2.7272727 | B17: =30/11 -> 2.7272727 | C17: =30/11 -> 2.7272727 | D17: EJECUCIÓN DEL PDV | E17: =30/11 -> 2.7272727 | F17: UNICA | G17: CONOCE LOS INFALTABLES DEL PUNTO DE VENTA Y CUENTA CON EL MATERIAL DE APOYO (AYUDAVENTAS INFALTABLES) | H17: SI
A18: =30/11 -> 2.7272727 | B18: =30/11 -> 2.7272727 | C18: =30/11 -> 2.7272727 | D18: EJECUCIÓN DEL PDV | E18: =30/11 -> 2.7272727 | F18: UNICA | G18: CONOCE Y TIENE SURTIDO DE ACUERDO A LA ESTRATEGIA DE EXHIBICIÓN (ETAPAS DE VIDA - SEGMENTACIÓN DE MARCAS) | H18: SI
A19: 0 | B19: 0 | C19: 16 | D19: EJECUCIÓN DEL PDV | E19: =30/11 -> 2.7272727 | F19: UNICA | G19: CONOCE EL % DE PARTICIPACIÓN QUE TIENE EN EL PUNTO DE VENTA E INFORMA CUAL ES ESE % (REALIZAR EL EJERCICIO DE CONTAR LAS CARAS PARA VALIDAR SI ES CORRECTO) | H19: SI
A20: =16/2 -> 8 | B20: 0 | C20: 0 | D20: EJECUCIÓN DEL PDV | E20: =30/11 -> 2.7272727 | F20: UNICA | G20: MANEJA MARCA DE PERROS, GATOS O AMBOS, Y HAY PRESENCIA DE LA COMPETENCIA? (EN EL VIDEO DEBE QUEDAR LA VISUAL DE LAS MARCAS DE LA COMPETENCIA PRESENTES EN EL PDV) | H20: SI
A21: =16/2 -> 8 | B21: 0 | C21: 0 | D21: EJECUCIÓN DEL PDV | E21: =30/11 -> 2.7272727 | F21: UNICA | G21: CONOCE EL % DE PARTICIPACIÓN QUE TIENEN LAS MARCAS PURINA DENTRO DEL UNIVERSO? | H21: SI
A22: 0 | B22: =16/3 -> 5.3333333 | C22: 0 | D22: EJECUCIÓN DEL PDV | E22: =30/11 -> 2.7272727 | F22: UNICA | G22: CONOCE LOS INFALTABLES DE PRO PLAN (GATOS Y PERROS) ALIMENTO SECO | H22: SI
A23: 0 | B23: =16/3 -> 5.3333333 | C23: 0 | D23: EJECUCIÓN DEL PDV | E23: =30/11 -> 2.7272727 | F23: UNICA | G23: EL PDV CUENTA CON EXHIBICIONES ADICIONALES? (REVISAR Y QUE SE VEA EN EL VIDEO) | H23: SI
A24: 0 | B24: =16/3 -> 5.3333333 | C24: 0 | D24: EJECUCIÓN DEL PDV | E24: =30/11 -> 2.7272727 | F24: UNICA | G24: LOS PRECIOS ESTAN EN LINEA CON LOS SUGERIDOS DEL CANAL? (REVISAR Y QUE SE VEA EN EL VIDEO) | H24: SI
A25: 0 | B25: 0 | C25: 0 | D25: N/A | E25: 0 | F25: UNICA | G25: SELECCIONE EL CANAL DEL PDV AUDITADO?
A26: 0 | B26: 0 | C26: =40/4 -> 10 | D26: ACTIVIDADES DEL MES | E26: =40/15 -> 2.6666667 | F26: UNICA | G26: CM - TIENE IMPLEMENTADO EL MATERIAL POP CORRECPONDIENTE A LAS PROMOCIONES QUE APLICAN EN EL PDV? | H26: SI | J26: cm - tiene implementado el material pop correcpondiente a las promociones que aplican en el pdv?
A27: 0 | B27: 0 | C27: =40/4 -> 10 | D27: ACTIVIDADES DEL MES | E27: =40/15 -> 2.6666667 | F27: UNICA | G27: CM - TIENE ACTIVIDADES DE PLAN PEGA EN EL PDV? | H27: SI | J27: cm - tiene actividades de plan pega en el pdv?
A28: 0 | B28: 0 | C28: 0 | D28: N/A | E28: 0 | F28: ABIERTA | G28: CM - DESCRIBA CUALES ACTIVIDADES DE PLAN PEGA TIENE EL PDV | J28: cm - describa cuales actividades de plan pega tiene el pdv
A29: 0 | B29: 0 | C29: =40/4 -> 10 | D29: ACTIVIDADES DEL MES | E29: =40/15 -> 2.6666667 | F29: UNICA | G29: CM - TIENE MATERIAL PRMO COOPORATIVA | H29: SI | J29: cm - tiene codificadas las dos nuevas referencias feliz multiproteina y cuenta con el pop correspondiente?
A30: 0 | B30: 0 | C30: =40/4 -> 10 | D30: ACTIVIDADES DEL MES | E30: =40/15 -> 2.6666667 | F30: UNICA | G30: CM - TIENE IMPLEMENTADAS LAS EXHIBICIONES NEGOCIADAS EN EL PDV? | H30: SI | J30: cm - tiene implementadas las exhibiciones negociadas en el pdv?
A31: 0 | B31: =40/6 -> 6.6666667 | C31: 0 | D31: ACTIVIDADES DEL MES | E31: =40/13 -> 3.0769231 | F31: UNICA | G31: CE - SE ENCUENTRAN LAS INNOVACIONES (RENOVACIÓN DE POCUHES PRO PLAN, "FANCY 15 MARZO" FELIX TRIPLE DELICIUS Y MEGAMIX, DOG CHOW POUCHES DE ALTA PROTEINA Y MULTIPROTEINA) | H31: SI | J31: ce - se encuentran las innovaciones (renovación de pocuhes pro plan, "fancy 15 marzo" felix triple delicius y megamix, dog chow pouches de alta proteina y multiproteina)
A32: 0 | B32: =40/6 -> 6.6666667 | C32: 0 | D32: ACTIVIDADES DEL MES | E32: =40/13 -> 3.0769231 | F32: UNICA | G32: CE - SE ENCUENTRA EN EL LINEAL LAS REFERENCIAS 1,5 EN PU Y ADU DE LA MARCA EXCELLENT? | H32: SI | J32: ce - se encuentra en el lineal las referencias 1,5 en pu y adu de la marca excellent?
A33: 0 | B33: =40/6 -> 6.6666667 | C33: 0 | D33: ACTIVIDADES DEL MES | E33: =40/13 -> 3.0769231 | F33: UNICA | G33: CE - SE ENCUENTRA LA NUEVA REFERENCIA DE EXCELLENT ESTIRILIZADO DE 1K? | H33: SI | J33: ce - se encuentra la nueva referencia de excellent estirilizado de 1k?
A34: 0 | B34: =40/6 -> 6.6666667 | C34: 0 | D34: ACTIVIDADES DEL MES | E34: =40/13 -> 3.0769231 | F34: UNICA | G34: CE - SE ENCUENTRA LA REFERENCIA PRO PLAN WET DE SALMON Y/URINARIO | H34: SI | J34: ce - se encuentra la referencia pro plan wet de salmon y/urinario
A35: 0 | B35: =40/6 -> 6.6666667 | C35: 0 | D35: ACTIVIDADES DEL MES | E35: =40/15 -> 2.6666667 | F35: UNICA | G35: CE - CUENTA CON LA PLANOMETRIA EN PDV (HORIZONTAL/VERTICAL) NO LADEADO? | H35: SI | J35: ce - el pdv maneja categoria de snacks? (en el video debe quedar la visual de las marcas de purina presentes en el pdv)
A36: 0 | B36: =40/6 -> 6.6666667 | C36: 0 | D36: ACTIVIDADES DEL MES | E36: =40/15 -> 2.6666667 | F36: UNICA | G36: CE - EL PDV MANEJA SNACKS, ESTAMOS PRESENTES? (REVISAR Y QUE SE VEA EN EL VIDEO) | H36: SI
A37: =40/5 -> 8 | B37: 0 | C37: 0 | D37: ACTIVIDADES DEL MES | E37: =40/13 -> 3.0769231 | F37: UNICA | G37: CT - CONOCE EL PRECIO DE LA PAQUETERIA (DOG CHOW 350G / 475G; CAT CHOW 200G? (Si el mercaderista informa que el PDV no lo permite implementar quedaria como N/A) | H37: SI | J37: ct - conoce el precio de la paqueteria (dog chow 350g / 475g; cat chow 200g? (si el mercaderista informa que el pdv no lo permite implementar quedaria como n/a)
