Workbook
Name SegmentaciónDeDatos_CANAL: #N/A
Name SegmentaciónDeDatos_CIUDAD: #N/A
Name SegmentaciónDeDatos_NOMBRE_COMERCIAL: #N/A

Sheet INFORME
D3: EJECUCION DEL PLAN
D4: CIUDAD | E4: #PDV Obj. | F4: #PDV Eje. | G4: .% Ejecucion | H4: Obj Mystery | I4: Mystery Eje. | J4: % Efectividad.
D5: CALI | E5: 4 | F5: 4 | G5: 1 | H5: 4 | I5: 4 | J5: 1
D6: BOGOTA | E6: 9 | F6: 9 | G6: 1 | H6: 9 | I6: 6 | J6: 0.66666667
D7: MEDELLIN | E7: 2 | F7: 2 | G7: 1 | H7: 2 | I7: 1 | J7: 0.5
D8: BARRANQUILLA | E8: 1 | F8: 1 | G8: 1 | H8: 1 | I8: 0 | J8: 0
D9: Total general | E9: 16 | F9: 16 | G9: 1 | H9: 16 | I9: 11 | J9: 0.6875
D13: MYSTERY POR CLUSTER
D14: Suma de % MYSTERY | E14: Etiquetas de columna
D15: CLUSTER | E15: ESPECIALIZADO | F15: MODERNO | G15: TRADICIONAL | H15: %
D16: ABORDAJE | E16: 1 | F16: 1 | G16: 1 | H16: 1
D17: HORARIO | E17: 1 | F17: 1 | G17: 1 | H17: 1
D18: UNIFORME | E18: 0.9 | F18: 0.93333333 | G18: 1 | H18: 0.91818182
D19: PORTAFOLIO Y MANEJO DE OBJECIONES | E19: 0.83760684 | F19: 0.63143631 | G19: 0.64285714 | H19: 0.76190476
D20: LABOR DE VENTA | E20: 0.64285714 | F20: 0.66666667 | G20: 0.5 | H20: 0.63636364
D21: % | E21: 0.88769036 | F21: 0.84073291 | G21: 0.86607143 | H21: 0.87255692
D26: MYSTERY POR CLUSTER - CIUDAD
D27: Suma de % MYSTERY | E27: Etiquetas de columna
D28: CLUSTER | E28: BOGOTA | F28: CALI | G28: MEDELLIN | H28: %
D29: ABORDAJE | E29: 1 | F29: 1 | G29: 1 | H29: 1
D30: HORARIO | E30: 1 | F30: 1 | G30: 1 | H30: 1
D31: UNIFORME | E31: 0.9 | F31: 0.975 | G31: 0.8 | H31: 0.91818182
D32: PORTAFOLIO Y MANEJO DE OBJECIONES | E32: 0.83579882 | F32: 0.64776119 | G32: 0.64705882 | H32: 0.76190476
D33: LABOR DE VENTA | E33: 0.58333333 | F33: 0.625 | G33: 1 | H33: 0.63636364
D34: % | E34: 0.87626081 | F34: 0.86282421 | G34: 0.88716814 | H34: 0.87255692
D36: MYSTERY EFECTIVO | E36: (Todas)
A37: v | D37: MYSTERY POR PDV
D38: Suma de % MYSTERY | G38: CLUSTER
D39: CIUDAD | E39: CANAL | F39: NOMBRE COMERCIAL | G39: ABORDAJE | H39: HORARIO | I39: LABOR DE VENTA | J39: PORTAFOLIO Y MANEJO DE OBJECIONES | K39: UNIFORME | L39: %
D40: BOGOTA | E40: ESPECIALIZADO | F40: CONCENTRADOS EL RANCHO LTDA DROGUERIA VETERINARIA | G40: 1 | H40: 1 | I40: 1 | J40: 1 | K40: 0.8 | L40: 0.96681416
D41: BOGOTA | E41: ESPECIALIZADO | F41: PUPPIS CARRERA 15 | G41: 1 | H41: 1 | I41: 0.5 | J41: 0.88235294 | K41: 0.9 | L41: 0.87389381
D42: BOGOTA | E42: ESPECIALIZADO | F42: AGROCAMPO S.A.S. | G42: 1 | H42: 1 | I42: 0.5 | J42: 0.71428571 | K42: 1 | L42: 0.84558824
D43: BOGOTA | E43: ESPECIALIZADO | F43: PLAZA PETS S.A.S. | G43: 1 | H43: 1 | I43: 0 | J43: 0.83333333 | K43: 0.9 | L43: 0.77840909
D44: BOGOTA | E44: MODERNO | F44: HOMECENTER AUTOPISTA NORTE BOGOTA | G44: 1 | H44: 1 | I44: 1 | J44: 1 | K44: 0.9 | L44: 0.98430962
D45: BOGOTA | E45: MODERNO | F45: HOMECENTER CALLE 80 CR 68 | G45: 1 | H45: 1 | I45: 0.5 | J45: 0.625 | K45: 0.9 | L45: 0.80543933
D46: CALI | E46: ESPECIALIZADO | F46: SUPERMASCOTAS CIUDAD JARDIN | G46: 1 | H46: 1 | I46: 1 | J46: 1 | K46: 0.9 | L46: 0.98295455
D47: CALI | E47: ESPECIALIZADO | F47: DEGANADO NORTE | G47: 1 | H47: 1 | I47: 0.5 | J47: 0.83333333 | K47: 1 | L47: 0.88068182
D48: CALI | E48: MODERNO | F48: MERCAMIO CALLE 5 | G48: 1 | H48: 1 | I48: 0.5 | J48: 0.22123894 | K48: 1 | L48: 0.72894168
D49: CALI | E49: TRADICIONAL | F49: LA CASA DE LOS TENDEROS | G49: 1 | H49: 1 | I49: 0.5 | J49: 0.64285714 | K49: 1 | L49: 0.86607143
D50: MEDELLIN | E50: ESPECIALIZADO | F50: MUNDIAL DE GRANOS Y PANELAS S.A.S. | G50: 1 | H50: 1 | I50: 1 | J50: 0.64705882 | K50: 0.8 | L50: 0.88716814
...

Sheet PUNTAJES
A1: ACTIVIDAD | B1: CIUDAD | C1: CANAL | D1: CADENA | E1: CODIGO PDV | F1: NOMBRE COMERCIAL | G1: PREGUNTA | H1: RTA | I1: FECHA VISITA | J1: CODIGO RUTA | K1: USUARIO | L1: MYSTERY EFECTIVO | M1: CLUSTER | N1: TOTAL PUNTAJE | O1: RTA CORRECTA | P1: PUNTAJE OBTENIDO | Q1: Columna1 | T1: SI(O(G17="Dog Chow";G17="Cat Chow";G17="Alpo";G17="Gatsy";G17="Feliz");N17;0) | U1: SI(O(G29="Dog Chow húmedo";G29="Cat Chow húmedo";G29="Fancy Feast";G29="Felix";G29="Proplan húmedo";G29="One húmedo";G29="Snack Abrazzos";G29="Snak Dentalife";G29="Arenilla Tidy Cat");N29;0)
A2: NESTLE PURINA | B2: CALI | C2: TRADICIONAL | D2: SUPERETE | E2: 66552 | F2: LA CASA DE LOS TENDEROS | G2: ¿CUMPLE HORARIO DE ENTRADA O SALIDA DE LA TIENDA? | H2: SI | I2: 45729 | J2: 26388644 | K2: NestleP.7 | L2: =_xlfn.XLOOKUP(Tabla2__2[[#This Row],[CODIGO RUTA]],'DATA INFORME'!I:I,'DATA INFORME'!K:K) -> SI | M2: =IF(Tabla2__2[[#This Row],[MYSTERY EFECTIVO]]="SI",_xlfn.XLOOKUP(Tabla2__2[[#This Row],[PREGUNTA]],ENCUESTA!G:G,ENCUESTA!D:D),"N/A") -> HORARIO | N2: =IF(Tabla2__2[[#This Row],[MYSTERY EFECTIVO]]="SI",(IF(Tabla2__2[[#This Row],[CANAL]]="TRADICIONAL",_xlfn.XLOOKUP(Tabla2__2[[#This Row],[PREGUNTA]],ENCUESTA!G:G,ENCUESTA!A:A),IF(Tabla2__2[[#This Row],[CANAL]]="ESPECIALIZADO",_xlfn.XLOOKUP(Tabla2__2[[#This Row],[PREGUNTA]],ENCUESTA!G:G,ENCUESTA!B:B),IF(Tabla2__2[[#This Row],[CANAL]]="MODERNO",_xlfn.XLOOKUP(Tabla2__2[[#This Row],[PREGUNTA]],ENCUESTA!G:G,ENCUESTA!C:C))))),0) -> 20 | O2: =_xlfn.XLOOKUP(Tabla2__2[[#This Row],[PREGUNTA]],ENCUESTA!G:G,ENCUESTA!H:H) -> SI | P2: =IF(Tabla2__2[[#This Row],[RTA]]=Tabla2__2[[#This Row],[RTA CORRECTA]],Tabla2__2[[#This Row],[TOTAL PUNTAJE]],0) -> 20 | Q2: =IF(OR(H2="Dog Chow húmedo",H2="Cat Chow húmedo",H2="Fancy Feast",H2="Felix",H2="Proplan húmedo",H2="One húmedo",H2="Snack Abrazzos",H2="Snak Dentalife",H2="Arenilla Tidy Cat"),N2,0) -> 0
A3: NESTLE PURINA | B3: CALI | C3: TRADICIONAL | D3: SUPERETE | E3: 66552 | F3: LA CASA DE LOS TENDEROS | G3: M. OFRECE PURINA ONE: (APLICA SOLO EN CANAL MODERNO, CADENAS, SI EL PRODUCTO ESTA EN EL PDV) | H3: NO | I3: 45729 | J3: 26388644 | K3: NestleP.7 | L3: =_xlfn.XLOOKUP(Tabla2__2[[#This Row],[CODIGO RUTA]],'DATA INFORME'!I:I,'DATA INFORME'!K:K) -> SI | M3: =IF(Tabla2__2[[#This Row],[MYSTERY EFECTIVO]]="SI",_xlfn.XLOOKUP(Tabla2__2[[#This Row],[PREGUNTA]],ENCUESTA!G:G,ENCUESTA!D:D),"N/A") -> PORTAFOLIO Y MANEJO DE OBJECIONES | N3: =IF(Tabla2__2[[#This Row],[MYSTERY EFECTIVO]]="SI",(IF(Tabla2__2[[#This Row],[CANAL]]="TRADICIONAL",_xlfn.XLOOKUP(Tabla2__2[[#This Row],[PREGUNTA]],ENCUESTA!G:G,ENCUESTA!A:A),IF(Tabla2__2[[#This Row],[CANAL]]="ESPECIALIZADO",_xlfn.XLOOKUP(Tabla2__2[[#This Row],[PREGUNTA]],ENCUESTA!G:G,ENCUESTA!B:B),IF(Tabla2__2[[#This Row],[CANAL]]="MODERNO",_xlfn.XLOOKUP(Tabla2__2[[#This Row],[PREGUNTA]],ENCUESTA!G:G,ENCUESTA!C:C))))),0) -> 0 | O3: =_xlfn.XLOOKUP(Tabla2__2[[#This Row],[PREGUNTA]],ENCUESTA!G:G,ENCUESTA!H:H) -> SI | P3: =IF(Tabla2__2[[#This Row],[RTA]]=Tabla2__2[[#This Row],[RTA CORRECTA]],Tabla2__2[[#This Row],[TOTAL PUNTAJE]],0) -> 0 | Q3: =IF(OR(H3="Dog Chow húmedo",H3="Cat Chow húmedo",H3="Fancy Feast",H3="Felix",H3="Proplan húmedo",H3="One húmedo",H3="Snack Abrazzos",H3="Snak Dentalife",H3="Arenilla Tidy Cat"),N3,0) -> 0
A4: NESTLE PURINA | B4: CALI | C4: TRADICIONAL | D4: SUPERETE | E4: 66552 | F4: LA CASA DE LOS TENDEROS | G4: QUE CANAL VA A REALIZAR | H4: TRADICIONAL | I4: 45729 | J4: 26388644 | K4: NestleP.7 | L4: =_xlfn.XLOOKUP(Tabla2__2[[#This Row],[CODIGO RUTA]],'DATA INFORME'!I:I,'DATA INFORME'!K:K) -> SI | M4: =IF(Tabla2__2[[#This Row],[MYSTERY EFECTIVO]]="SI",_xlfn.XLOOKUP(Tabla2__2[[#This Row],[PREGUNTA]],ENCUESTA!G:G,ENCUESTA!D:D),"N/A") -> N/A | N4: =IF(Tabla2__2[[#This Row],[MYSTERY EFECTIVO]]="SI",(IF(Tabla2__2[[#This Row],[CANAL]]="TRADICIONAL",_xlfn.XLOOKUP(Tabla2__2[[#This Row],[PREGUNTA]],ENCUESTA!G:G,ENCUESTA!A:A),IF(Tabla2__2[[#This Row],[CANAL]]="ESPECIALIZADO",_xlfn.XLOOKUP(Tabla2__2[[#This Row],[PREGUNTA]],ENCUESTA!G:G,ENCUESTA!B:B),IF(Tabla2__2[[#This Row],[CANAL]]="MODERNO",_xlfn.XLOOKUP(Tabla2__2[[#This Row],[PREGUNTA]],ENCUESTA!G:G,ENCUESTA!C:C))))),0) -> 0 | O4: =_xlfn.XLOOKUP(Tabla2__2[[#This Row],[PREGUNTA]],ENCUESTA!G:G,ENCUESTA!H:H) -> 0 | P4: =IF(Tabla2__2[[#This Row],[RTA]]=Tabla2__2[[#This Row],[RTA CORRECTA]],Tabla2__2[[#This Row],[TOTAL PUNTAJE]],0) -> 0 | Q4: =IF(OR(H4="Dog Chow húmedo",H4="Cat Chow húmedo",H4="Fancy Feast",H4="Felix",H4="Proplan húmedo",H4="One húmedo",H4="Snack Abrazzos",H4="Snak Dentalife",H4="Arenilla Tidy Cat"),N4,0) -> 0
A5: NESTLE PURINA | B5: CALI | C5: TRADICIONAL | D5: SUPERETE | E5: 66552 | F5: LA CASA DE LOS TENDEROS | G5: OFRECIO ALGUN PRODUCTO DEL PORTAFOLIO PURINA DE PRODUCTOS HUMEDOS, SNACK U OTROS COMUNICANDO LOS BENEFICIOS DEL PRODUCTO | H5: NO | I5: 45729 | J5: 26388644 | K5: NestleP.7 | L5: =_xlfn.XLOOKUP(Tabla2__2[[#This Row],[CODIGO RUTA]],'DATA INFORME'!I:I,'DATA INFORME'!K:K) -> SI | M5: =IF(Tabla2__2[[#This Row],[MYSTERY EFECTIVO]]="SI",_xlfn.XLOOKUP(Tabla2__2[[#This Row],[PREGUNTA]],ENCUESTA!G:G,ENCUESTA!D:D),"N/A") -> PORTAFOLIO Y MANEJO DE OBJECIONES | N5: =IF(Tabla2__2[[#This Row],[MYSTERY EFECTIVO]]="SI",(IF(Tabla2__2[[#This Row],[CANAL]]="TRADICIONAL",_xlfn.XLOOKUP(Tabla2__2[[#This Row],[PREGUNTA]],ENCUESTA!G:G,ENCUESTA!A:A),IF(Tabla2__2[[#This Row],[CANAL]]="ESPECIALIZADO",_xlfn.XLOOKUP(Tabla2__2[[#This Row],[PREGUNTA]],ENCUESTA!G:G,ENCUESTA!B:B),IF(Tabla2__2[[#This Row],[CANAL]]="MODERNO",_xlfn.XLOOKUP(Tabla2__2[[#This Row],[PREGUNTA]],ENCUESTA!G:G,ENCUESTA!C:C))))),0) -> 3 | O5: =_xlfn.XLOOKUP(Tabla2__2[[#This Row],[PREGUNTA]],ENCUESTA!G:G,ENCUESTA!H:H) -> SI | P5: =IF(Tabla2__2[[#This Row],[RTA]]=Tabla2__2[[#This Row],[RTA CORRECTA]],Tabla2__2[[#This Row],[TOTAL PUNTAJE]],0) -> 0 | Q5: =IF(OR(H5="Dog Chow húmedo",H5="Cat Chow húmedo",H5="Fancy Feast",H5="Felix",H5="Proplan húmedo",H5="One húmedo",H5="Snack Abrazzos",H5="Snak Dentalife",H5="Arenilla Tidy Cat"),N5,0) -> 0
A6: NESTLE PURINA | B6: CALI | C6: TRADICIONAL | D6: SUPERETE | E6: 66552 | F6: LA CASA DE LOS TENDEROS | G6: OFRECIO ALGUN PRODUCTO DEL PORTAFOLIO PURINA DE PRODUCTOS SECOS COMUNICANDO LOS BENEFICIOS DEL PRODUCTO | H6: SI | I6: 45729 | J6: 26388644 | K6: NestleP.7 | L6: =_xlfn.XLOOKUP(Tabla2__2[[#This Row],[CODIGO RUTA]],'DATA INFORME'!I:I,'DATA INFORME'!K:K) -> SI | M6: =IF(Tabla2__2[[#This Row],[MYSTERY EFECTIVO]]="SI",_xlfn.XLOOKUP(Tabla2__2[[#This Row],[PREGUNTA]],ENCUESTA!G:G,ENCUESTA!D:D),"N/A") -> PORTAFOLIO Y MANEJO DE OBJECIONES | N6: =IF(Tabla2__2[[#This Row],[MYSTERY EFECTIVO]]="SI",(IF(Tabla2__2[[#This Row],[CANAL]]="TRADICIONAL",_xlfn.XLOOKUP(Tabla2__2[[#This Row],[PREGUNTA]],ENCUESTA!G:G,ENCUESTA!A:A),IF(Tabla2__2[[#This Row],[CANAL]]="ESPECIALIZADO",_xlfn.XLOOKUP(Tabla2__2[[#This Row],[PREGUNTA]],ENCUESTA!G:G,ENCUESTA!B:B),IF(Tabla2__2[[#This Row],[CANAL]]="MODERNO",_xlfn.XLOOKUP(Tabla2__2[[#This Row],[PREGUNTA]],ENCUESTA!G:G,ENCUESTA!C:C))))),0) -> 3 | O6: =_xlfn.XLOOKUP(Tabla2__2[[#This Row],[PREGUNTA]],ENCUESTA!G:G,ENCUESTA!H:H) -> SI | P6: =IF(Tabla2__2[[#This Row],[RTA]]=Tabla2__2[[#This Row],[RTA CORRECTA]],Tabla2__2[[#This Row],[TOTAL PUNTAJE]],0) -> 3 | Q6: =IF(OR(H6="Dog Chow húmedo",H6="Cat Chow húmedo",H6="Fancy Feast",H6="Felix",H6="Proplan húmedo",H6="One húmedo",H6="Snack Abrazzos",H6="Snak Dentalife",H6="Arenilla Tidy Cat"),N6,0) -> 0
A7: NESTLE PURINA | B7: CALI | C7: TRADICIONAL | D7: SUPERETE | E7: 66552 | F7: LA CASA DE LOS TENDEROS | G7: SE PRODUCE ABORDO PROACTIVO (ANTES DE LOS 3 MIN) | H7: SI | I7: 45729 | J7: 26388644 | K7: NestleP.7 | L7: =_xlfn.XLOOKUP(Tabla2__2[[#This Row],[CODIGO RUTA]],'DATA INFORME'!I:I,'DATA INFORME'!K:K) -> SI | M7: =IF(Tabla2__2[[#This Row],[MYSTERY EFECTIVO]]="SI",_xlfn.XLOOKUP(Tabla2__2[[#This Row],[PREGUNTA]],ENCUESTA!G:G,ENCUESTA!D:D),"N/A") -> ABORDAJE | N7: =IF(Tabla2__2[[#This Row],[MYSTERY EFECTIVO]]="SI",(IF(Tabla2__2[[#This Row],[CANAL]]="TRADICIONAL",_xlfn.XLOOKUP(Tabla2__2[[#This Row],[PREGUNTA]],ENCUESTA!G:G,ENCUESTA!A:A),IF(Tabla2__2[[#This Row],[CANAL]]="ESPECIALIZADO",_xlfn.XLOOKUP(Tabla2__2[[#This Row],[PREGUNTA]],ENCUESTA!G:G,ENCUESTA!B:B),IF(Tabla2__2[[#This Row],[CANAL]]="MODERNO",_xlfn.XLOOKUP(Tabla2__2[[#This Row],[PREGUNTA]],ENCUESTA!G:G,ENCUESTA!C:C))))),0) -> 20 | O7: =_xlfn.XLOOKUP(Tabla2__2[[#This Row],[PREGUNTA]],ENCUESTA!G:G,ENCUESTA!H:H) -> SI | P7: =IF(Tabla2__2[[#This Row],[RTA]]=Tabla2__2[[#This Row],[RTA CORRECTA]],Tabla2__2[[#This Row],[TOTAL PUNTAJE]],0) -> 20 | Q7: =IF(OR(H7="Dog Chow húmedo",H7="Cat Chow húmedo",H7="Fancy Feast",H7="Felix",H7="Proplan húmedo",H7="One húmedo",H7="Snack Abrazzos",H7="Snak Dentalife",H7="Arenilla Tidy Cat"),N7,0) -> 0
A8: NESTLE PURINA | B8: CALI | C8: TRADICIONAL | D8: SUPERETE | E8: 66552 | F8: LA CASA DE LOS TENDEROS | G8: M. MENCIONA QUE LOS RESULTADOS DE PURINA ONE SON VISIBLES EN 28 DIAS? | H8: NO | I8: 45729 | J8: 26388644 | K8: NestleP.7 | L8: =_xlfn.XLOOKUP(Tabla2__2[[#This Row],[CODIGO RUTA]],'DATA INFORME'!I:I,'DATA INFORME'!K:K) -> SI | M8: =IF(Tabla2__2[[#This Row],[MYSTERY EFECTIVO]]="SI",_xlfn.XLOOKUP(Tabla2__2[[#This Row],[PREGUNTA]],ENCUESTA!G:G,ENCUESTA!D:D),"N/A") -> PORTAFOLIO Y MANEJO DE OBJECIONES | N8: =IF(Tabla2__2[[#This Row],[MYSTERY EFECTIVO]]="SI",(IF(Tabla2__2[[#This Row],[CANAL]]="TRADICIONAL",_xlfn.XLOOKUP(Tabla2__2[[#This Row],[PREGUNTA]],ENCUESTA!G:G,ENCUESTA!A:A),IF(Tabla2__2[[#This Row],[CANAL]]="ESPECIALIZADO",_xlfn.XLOOKUP(Tabla2__2[[#This Row],[PREGUNTA]],ENCUESTA!G:G,ENCUESTA!B:B),IF(Tabla2__2[[#This Row],[CANAL]]="MODERNO",_xlfn.XLOOKUP(Tabla2__2[[#This Row],[PREGUNTA]],ENCUESTA!G:G,ENCUESTA!C:C))))),0) -> 0 | O8: =_xlfn.XLOOKUP(Tabla2__2[[#This Row],[PREGUNTA]],ENCUESTA!G:G,ENCUESTA!H:H) -> SI | P8: =IF(Tabla2__2[[#This Row],[RTA]]=Tabla2__2[[#This Row],[RTA CORRECTA]],Tabla2__2[[#This Row],[TOTAL PUNTAJE]],0) -> 0 | Q8: =IF(OR(H8="Dog Chow húmedo",H8="Cat Chow húmedo",H8="Fancy Feast",H8="Felix",H8="Proplan húmedo",H8="One húmedo",H8="Snack Abrazzos",H8="Snak Dentalife",H8="Arenilla Tidy Cat"),N8,0) -> 0
A9: NESTLE PURINA | B9: CALI | C9: TRADICIONAL | D9: SUPERETE | E9: 66552 | F9: LA CASA DE LOS TENDEROS | G9: USA ACCESORIOS QUE NO CUMPLE CON EL CODIGO DE VESTIMENTA | H9: NO | I9: 45729 | J9: 26388644 | K9: NestleP.7 | L9: =_xlfn.XLOOKUP(Tabla2__2[[#This Row],[CODIGO RUTA]],'DATA INFORME'!I:I,'DATA INFORME'!K:K) -> SI | M9: =IF(Tabla2__2[[#This Row],[MYSTERY EFECTIVO]]="SI",_xlfn.XLOOKUP(Tabla2__2[[#This Row],[PREGUNTA]],ENCUESTA!G:G,ENCUESTA!D:D),"N/A") -> UNIFORME | N9: =IF(Tabla2__2[[#This Row],[MYSTERY EFECTIVO]]="SI",(IF(Tabla2__2[[#This Row],[CANAL]]="TRADICIONAL",_xlfn.XLOOKUP(Tabla2__2[[#This Row],[PREGUNTA]],ENCUESTA!G:G,ENCUESTA!A:A),IF(Tabla2__2[[#This Row],[CANAL]]="ESPECIALIZADO",_xlfn.XLOOKUP(Tabla2__2[[#This Row],[PREGUNTA]],ENCUESTA!G:G,ENCUESTA!B:B),IF(Tabla2__2[[#This Row],[CANAL]]="MODERNO",_xlfn.XLOOKUP(Tabla2__2[[#This Row],[PREGUNTA]],ENCUESTA!G:G,ENCUESTA!C:C))))),0) -> 1.5 | O9: =_xlfn.XLOOKUP(Tabla2__2[[#This Row],[PREGUNTA]],ENCUESTA!G:G,ENCUESTA!H:H) -> NO | P9: =IF(Tabla2__2[[#This Row],[RTA]]=Tabla2__2[[#This Row],[RTA CORRECTA]],Tabla2__2[[#This Row],[TOTAL PUNTAJE]],0) -> 1.5 | Q9: =IF(OR(H9="Dog Chow húmedo",H9="Cat Chow húmedo",H9="Fancy Feast",H9="Felix",H9="Proplan húmedo",H9="One húmedo",H9="Snack Abrazzos",H9="Snak Dentalife",H9="Arenilla Tidy Cat"),N9,0) -> 0
A10: NESTLE PURINA | B10: CALI | C10: TRADICIONAL | D10: SUPERETE | E10: 66552 | F10: LA CASA DE LOS TENDEROS | G10: TIENE TATUAJES O PIERCINGS VISIBLES QUE NO CUMPLE CON EL CODIGO DE VESTIMENTA | H10: NO | I10: 45729 | J10: 26388644 | K10: NestleP.7 | L10: =_xlfn.XLOOKUP(Tabla2__2[[#This Row],[CODIGO RUTA]],'DATA INFORME'!I:I,'DATA INFORME'!K:K) -> SI | M10: =IF(Tabla2__2[[#This Row],[MYSTERY EFECTIVO]]="SI",_xlfn.XLOOKUP(Tabla2__2[[#This Row],[PREGUNTA]],ENCUESTA!G:G,ENCUESTA!D:D),"N/A") -> UNIFORME | N10: =IF(Tabla2__2[[#This Row],[MYSTERY EFECTIVO]]="SI",(IF(Tabla2__2[[#This Row],[CANAL]]="TRADICIONAL",_xlfn.XLOOKUP(Tabla2__2[[#This Row],[PREGUNTA]],ENCUESTA!G:G,ENCUESTA!A:A),IF(Tabla2__2[[#This Row],[CANAL]]="ESPECIALIZADO",_xlfn.XLOOKUP(Tabla2__2[[#This Row],[PREGUNTA]],ENCUESTA!G:G,ENCUESTA!B:B),IF(Tabla2__2[[#This Row],[CANAL]]="MODERNO",_xlfn.XLOOKUP(Tabla2__2[[#This Row],[PREGUNTA]],ENCUESTA!G:G,ENCUESTA!C:C))))),0) -> 1.5 | O10: =_xlfn.XLOOKUP(Tabla2__2[[#This Row],[PREGUNTA]],ENCUESTA!G:G,ENCUESTA!H:H) -> NO | P10: =IF(Tabla2__2[[#This Row],[RTA]]=Tabla2__2[[#This Row],[RTA CORRECTA]],Tabla2__2[[#This Row],[TOTAL PUNTAJE]],0) -> 1.5 | Q10: =IF(OR(H10="Dog Chow húmedo",H10="Cat Chow húmedo",H10="Fancy Feast",H10="Felix",H10="Proplan húmedo",H10="One húmedo",H10="Snack Abrazzos",H10="Snak Dentalife",H10="Arenilla Tidy Cat"),N10,0) -> 0
A11: NESTLE PURINA | B11: CALI | C11: TRADICIONAL | D11: SUPERETE | E11: 66552 | F11: LA CASA DE LOS TENDEROS | G11: PRESENTA EXCESO DE MAQUILLAJE QUE NO CUMPLE CON EL CODIGO DE VESTIMENTA | H11: NO | I11: 45729 | J11: 26388644 | K11: NestleP.7 | L11: =_xlfn.XLOOKUP(Tabla2__2[[#This Row],[CODIGO RUTA]],'DATA INFORME'!I:I,'DATA INFORME'!K:K) -> SI | M11: =IF(Tabla2__2[[#This Row],[MYSTERY EFECTIVO]]="SI",_xlfn.XLOOKUP(Tabla2__2[[#This Row],[PREGUNTA]],ENCUESTA!G:G,ENCUESTA!D:D),"N/A") -> UNIFORME | N11: =IF(Tabla2__2[[#This Row],[MYSTERY EFECTIVO]]="SI",(IF(Tabla2__2[[#This Row],[CANAL]]="TRADICIONAL",_xlfn.XLOOKUP(Tabla2__2[[#This Row],[PREGUNTA]],ENCUESTA!G:G,ENCUESTA!A:A),IF(Tabla2__2[[#This Row],[CANAL]]="ESPECIALIZADO",_xlfn.XLOOKUP(Tabla2__2[[#This Row],[PREGUNTA]],ENCUESTA!G:G,ENCUESTA!B:B),IF(Tabla2__2[[#This Row],[CANAL]]="MODERNO",_xlfn.XLOOKUP(Tabla2__2[[#This Row],[PREGUNTA]],ENCUESTA!G:G,ENCUESTA!C:C))))),0) -> 1.5 | O11: =_xlfn.XLOOKUP(Tabla2__2[[#This Row],[PREGUNTA]],ENCUESTA!G:G,ENCUESTA!H:H) -> NO | P11: =IF(Tabla2__2[[#This Row],[RTA]]=Tabla2__2[[#This Row],[RTA CORRECTA]],Tabla2__2[[#This Row],[TOTAL PUNTAJE]],0) -> 1.5 | Q11: =IF(OR(H11="Dog Chow húmedo",H11="Cat Chow húmedo",H11="Fancy Feast",H11="Felix",H11="Proplan húmedo",H11="One húmedo",H11="Snack Abrazzos",H11="Snak Dentalife",H11="Arenilla Tidy Cat"),N11,0) -> 0
A12: NESTLE PURINA | B12: CALI | C12: TRADICIONAL | D12: SUPERETE | E12: 66552 | F12: LA CASA DE LOS TENDEROS | G12: SU CABELLO LUCE LIMPIO, ORGANIZADO O RECOGIDO | H12: SI | I12: 45729 | J12: 26388644 | K12: NestleP.7 | L12: =_xlfn.XLOOKUP(Tabla2__2[[#This Row],[CODIGO RUTA]],'DATA INFORME'!I:I,'DATA INFORME'!K:K) -> SI | M12: =IF(Tabla2__2[[#This Row],[MYSTERY EFECTIVO]]="SI",_xlfn.XLOOKUP(Tabla2__2[[#This Row],[PREGUNTA]],ENCUESTA!G:G,ENCUESTA!D:D),"N/A") -> UNIFORME | N12: =IF(Tabla2__2[[#This Row],[MYSTERY EFECTIVO]]="SI",(IF(Tabla2__2[[#This Row],[CANAL]]="TRADICIONAL",_xlfn.XLOOKUP(Tabla2__2[[#This Row],[PREGUNTA]],ENCUESTA!G:G,ENCUESTA!A:A),IF(Tabla2__2[[#This Row],[CANAL]]="ESPECIALIZADO",_xlfn.XLOOKUP(Tabla2__2[[#This Row],[PREGUNTA]],ENCUESTA!G:G,ENCUESTA!B:B),IF(Tabla2__2[[#This Row],[CANAL]]="MODERNO",_xlfn.XLOOKUP(Tabla2__2[[#This Row],[PREGUNTA]],ENCUESTA!G:G,ENCUESTA!C:C))))),0) -> 1.5 | O12: =_xlfn.XLOOKUP(Tabla2__2[[#This Row],[PREGUNTA]],ENCUESTA!G:G,ENCUESTA!H:H) -> SI | P12: =IF(Tabla2__2[[#This Row],[RTA]]=Tabla2__2[[#This Row],[RTA CORRECTA]],Tabla2__2[[#This Row],[TOTAL PUNTAJE]],0) -> 1.5 | Q12: =IF(OR(H12="Dog Chow húmedo",H12="Cat Chow húmedo",H12="Fancy Feast",H12="Felix",H12="Proplan húmedo",H12="One húmedo",H12="Snack Abrazzos",H12="Snak Dentalife",H12="Arenilla Tidy Cat"),N12,0) -> 0
A13: NESTLE PURINA | B13: CALI | C13: TRADICIONAL | D13: SUPERETE | E13: 66552 | F13: LA CASA DE LOS TENDEROS | G13: EL UNIFORME Y ZAPATOS SE ENCUENTRAN LIMPIOS Y EN BUEN ESTADO | H13: SI | I13: 45729 | J13: 26388644 | K13: NestleP.7 | L13: =_xlfn.XLOOKUP(Tabla2__2[[#This Row],[CODIGO RUTA]],'DATA INFORME'!I:I,'DATA INFORME'!K:K) -> SI | M13: =IF(Tabla2__2[[#This Row],[MYSTERY EFECTIVO]]="SI",_xlfn.XLOOKUP(Tabla2__2[[#This Row],[PREGUNTA]],ENCUESTA!G:G,ENCUESTA!D:D),"N/A") -> UNIFORME | N13: =IF(Tabla2__2[[#This Row],[MYSTERY EFECTIVO]]="SI",(IF(Tabla2__2[[#This Row],[CANAL]]="TRADICIONAL",_xlfn.XLOOKUP(Tabla2__2[[#This Row],[PREGUNTA]],ENCUESTA!G:G,ENCUESTA!A:A),IF(Tabla2__2[[#This Row],[CANAL]]="ESPECIALIZADO",_xlfn.XLOOKUP(Tabla2__2[[#This Row],[PREGUNTA]],ENCUESTA!G:G,ENCUESTA!B:B),IF(Tabla2__2[[#This Row],[CANAL]]="MODERNO",_xlfn.XLOOKUP(Tabla2__2[[#This Row],[PREGUNTA]],ENCUESTA!G:G,ENCUESTA!C:C))))),0) -> 1.5 | O13: =_xlfn.XLOOKUP(Tabla2__2[[#This Row],[PREGUNTA]],ENCUESTA!G:G,ENCUESTA!H:H) -> SI | P13: =IF(Tabla2__2[[#This Row],[RTA]]=Tabla2__2[[#This Row],[RTA CORRECTA]],Tabla2__2[[#This Row],[TOTAL PUNTAJE]],0) -> 1.5 | Q13: =IF(OR(H13="Dog Chow húmedo",H13="Cat Chow húmedo",H13="Fancy Feast",H13="Felix",H13="Proplan húmedo",H13="One húmedo",H13="Snack Abrazzos",H13="Snak Dentalife",H13="Arenilla Tidy Cat"),N13,0) -> 0
... A341: NESTLE PURINA | B341: CALI | C341: MODERNO | D341: SUPERETE | E341: 29714 | F341: MERCAMIO CALLE 5 | G341: PRESENTA ALGUNA NOVEDAD? | H341: NO | I341: 45738 | J341: 26693598 | K341: NestleP.7 | L341: =_xlfn.XLOOKUP(Tabla2__2[[#This Row],[CODIGO RUTA]],'DATA INFORME'!I:I,'DATA INFORME'!K:K) -> SI | M341: =IF(Tabla2__2[[#This Row],[MYSTERY EFECTIVO]]="SI",_xlfn.XLOOKUP(Tabla2__2[[#This Row],[PREGUNTA]],ENCUESTA!G:G,ENCUESTA!D:D),"N/A") -> N/A | N341: =IF(Tabla2__2[[#This Row],[MYSTERY EFECTIVO]]="SI",(IF(Tabla2__2[[#This Row],[CANAL]]="TRADICIONAL",_xlfn.XLOOKUP(Tabla2__2[[#This Row],[PREGUNTA]],ENCUESTA!G:G,ENCUESTA!A:A),IF(Tabla2__2[[#This Row],[CANAL]]="ESPECIALIZADO",_xlfn.XLOOKUP(Tabla2__2[[#This Row],[PREGUNTA]],ENCUESTA!G:G,ENCUESTA!B:B),IF(Tabla2__2[[#This Row],[CANAL]]="MODERNO",_xlfn.XLOOKUP(Tabla2__2[[#This Row],[PREGUNTA]],ENCUESTA!G:G,ENCUESTA!C:C))))),0) -> 0 | O341: =_xlfn.XLOOKUP(Tabla2__2[[#This Row],[PREGUNTA]],ENCUESTA!G:G,ENCUESTA!H:H) -> 0 | P341: =IF(Tabla2__2[[#This Row],[RTA]]=Tabla2__2[[#This Row],[RTA CORRECTA]],Tabla2__2[[#This Row],[TOTAL PUNTAJE]],0) -> 0 | Q341: =IF(OR(H341="Dog Chow húmedo",H341="Cat Chow húmedo",H341="Fancy Feast",H341="Felix",H341="Proplan húmedo",H341="One húmedo",H341="Snack Abrazzos",H341="Snak Dentalife",H341="Arenilla Tidy Cat"),N341,0) -> 0

Sheet Panel
A1: CANAL | B1: CIUDAD | C1: CODIGO PDV | D1: NOMBRE COMERCIAL | E1: Objetivo Mystery | F1: #PDV Objetivos | G1: #PDV Ejecutados | H1: # Visitas | I1: Mystery Ejecutado
A2: ESPECIALIZADO | B2: BARRANQUILLA | C2: 424883 | D2: CLINICA VETERINARIA DON PERRO BARRANQUILLA | E2: 1 | F2: 1 | G2: =IF(COUNTIFS(Export!I:I,Tabla1[[#This Row],[CODIGO PDV]])>0,1,0) -> 1 | H2: =COUNTIFS('DATA INFORME'!D:D,Tabla1[[#This Row],[CODIGO PDV]]) -> 1 | I2: =COUNTIFS('DATA INFORME'!D:D,Tabla1[[#This Row],[CODIGO PDV]],'DATA INFORME'!K:K,"SI") -> 0
A3: ESPECIALIZADO | B3: BOGOTA | C3: 109096 | D3: PLAZA PETS S.A.S. | E3: 1 | F3: 1 | G3: =IF(COUNTIFS(Export!I:I,Tabla1[[#This Row],[CODIGO PDV]])>0,1,0) -> 1 | H3: =COUNTIFS('DATA INFORME'!D:D,Tabla1[[#This Row],[CODIGO PDV]]) -> 1 | I3: =COUNTIFS('DATA INFORME'!D:D,Tabla1[[#This Row],[CODIGO PDV]],'DATA INFORME'!K:K,"SI") -> 1
A4: ESPECIALIZADO | B4: BOGOTA | C4: 125788 | D4: PUPPIS CALLE 85 | E4: 1 | F4: 1 | G4: =IF(COUNTIFS(Export!I:I,Tabla1[[#This Row],[CODIGO PDV]])>0,1,0) -> 1 | H4: =COUNTIFS('DATA INFORME'!D:D,Tabla1[[#This Row],[CODIGO PDV]]) -> 1 | I4: =COUNTIFS('DATA INFORME'!D:D,Tabla1[[#This Row],[CODIGO PDV]],'DATA INFORME'!K:K,"SI") -> 0
A5: ESPECIALIZADO | B5: BOGOTA | C5: 180619 | D5: PUPPIS CALIMA | E5: 1 | F5: 1 | G5: =IF(COUNTIFS(Export!I:I,Tabla1[[#This Row],[CODIGO PDV]])>0,1,0) -> 1 | H5: =COUNTIFS('DATA INFORME'!D:D,Tabla1[[#This Row],[CODIGO PDV]]) -> 1 | I5: =COUNTIFS('DATA INFORME'!D:D,Tabla1[[#This Row],[CODIGO PDV]],'DATA INFORME'!K:K,"SI") -> 0
A6: ESPECIALIZADO | B6: BOGOTA | C6: 180621 | D6: PUPPIS CARRERA 15 | E6: 1 | F6: 1 | G6: =IF(COUNTIFS(Export!I:I,Tabla1[[#This Row],[CODIGO PDV]])>0,1,0) -> 1 | H6: =COUNTIFS('DATA INFORME'!D:D,Tabla1[[#This Row],[CODIGO PDV]]) -> 1 | I6: =COUNTIFS('DATA INFORME'!D:D,Tabla1[[#This Row],[CODIGO PDV]],'DATA INFORME'!K:K,"SI") -> 1
A7: ESPECIALIZADO | B7: BOGOTA | C7: 188203 | D7: CONCENTRADOS EL RANCHO LTDA DROGUERIA VETERINARIA | E7: 1 | F7: 1 | G7: =IF(COUNTIFS(Export!I:I,Tabla1[[#This Row],[CODIGO PDV]])>0,1,0) -> 1 | H7: =COUNTIFS('DATA INFORME'!D:D,Tabla1[[#This Row],[CODIGO PDV]]) -> 1 | I7: =COUNTIFS('DATA INFORME'!D:D,Tabla1[[#This Row],[CODIGO PDV]],'DATA INFORME'!K:K,"SI") -> 1
A8: ESPECIALIZADO | B8: BOGOTA | C8: 424858 | D8: AGROCAMPO S.A.S. | E8: 1 | F8: 1 | G8: =IF(COUNTIFS(Export!I:I,Tabla1[[#This Row],[CODIGO PDV]])>0,1,0) -> 1 | H8: =COUNTIFS('DATA INFORME'!D:D,Tabla1[[#This Row],[CODIGO PDV]]) -> 1 | I8: =COUNTIFS('DATA INFORME'!D:D,Tabla1[[#This Row],[CODIGO PDV]],'DATA INFORME'!K:K,"SI") -> 1
A9: MODERNO | B9: BOGOTA | C9: 12390 | D9: EXITO COUNTRY | E9: 1 | F9: 1 | G9: =IF(COUNTIFS(Export!I:I,Tabla1[[#This Row],[CODIGO PDV]])>0,1,0) -> 1 | H9: =COUNTIFS('DATA INFORME'!D:D,Tabla1[[#This Row],[CODIGO PDV]]) -> 1 | I9: =COUNTIFS('DATA INFORME'!D:D,Tabla1[[#This Row],[CODIGO PDV]],'DATA INFORME'!K:K,"SI") -> 0
A10: MODERNO | B10: BOGOTA | C10: 424893 | D10: HOMECENTER CALLE 80 CR 68 | E10: 1 | F10: 1 | G10: =IF(COUNTIFS(Export!I:I,Tabla1[[#This Row],[CODIGO PDV]])>0,1,0) -> 1 | H10: =COUNTIFS('DATA INFORME'!D:D,Tabla1[[#This Row],[CODIGO PDV]]) -> 1 | I10: =COUNTIFS('DATA INFORME'!D:D,Tabla1[[#This Row],[CODIGO PDV]],'DATA INFORME'!K:K,"SI") -> 1
A11: MODERNO | B11: BOGOTA | C11: 105381 | D11: HOMECENTER AUTOPISTA NORTE BOGOTA | E11: 1 | F11: 1 | G11: =IF(COUNTIFS(Export!I:I,Tabla1[[#This Row],[CODIGO PDV]])>0,1,0) -> 1 | H11: =COUNTIFS('DATA INFORME'!D:D,Tabla1[[#This Row],[CODIGO PDV]]) -> 1 | I11: =COUNTIFS('DATA INFORME'!D:D,Tabla1[[#This Row],[CODIGO PDV]],'DATA INFORME'!K:K,"SI") -> 1
A12: ESPECIALIZADO | B12: CALI | C12: 191506 | D12: DEGANADO NORTE | E12: 1 | F12: 1 | G12: =IF(COUNTIFS(Export!I:I,Tabla1[[#This Row],[CODIGO PDV]])>0,1,0) -> 1 | H12: =COUNTIFS('DATA INFORME'!D:D,Tabla1[[#This Row],[CODIGO PDV]]) -> 1 | I12: =COUNTIFS('DATA INFORME'!D:D,Tabla1[[#This Row],[CODIGO PDV]],'DATA INFORME'!K:K,"SI") -> 1
A13: ESPECIALIZADO | B13: CALI | C13: 356594 | D13: SUPERMASCOTAS CIUDAD JARDIN | E13: 1 | F13: 1 | G13: =IF(COUNTIFS(Export!I:I,Tabla1[[#This Row],[CODIGO PDV]])>0,1,0) -> 1 | H13: =COUNTIFS('DATA INFORME'!D:D,Tabla1[[#This Row],[CODIGO PDV]]) -> 1 | I13: =COUNTIFS('DATA INFORME'!D:D,Tabla1[[#This Row],[CODIGO PDV]],'DATA INFORME'!K:K,"SI") -> 1
... A17: MODERNO | B17: MEDELLIN | C17: 12130 | D17: EXITO LAURELES. | E17: 1 | F17: 1 | G17: =IF(COUNTIFS(Export!I:I,Tabla1[[#This Row],[CODIGO PDV]])>0,1,0) -> 1 | H17: =COUNTIFS('DATA INFORME'!D:D,Tabla1[[#This Row],[CODIGO PDV]]) -> 1 | I17: =COUNTIFS('DATA INFORME'!D:D,Tabla1[[#This Row],[CODIGO PDV]],'DATA INFORME'!K:K,"SI") -> 0
A20: CANAL | B20: CIUDAD | C20: VUM | D20: NOMBRE PDV | E20: NOVEDAD
A21: ESPECIALIZADO | B21: BARRANQUILLA | C21: 424883 | D21: CRONICAS PET | E21: CAMBIO DE RUTA POR IMPULSO DE GANA AL INSTANTE EN VETERINARIA DON PERRO
A22: ESPECIALIZADO | B22: BOGOTA | C22: 125788 | D22: PUPPIS CALLE 85 | E22: CAMBIO DE RUTA - IMPLEMENTACION GANA AL INSTANTE
A23: ESPECIALIZADO | B23: BOGOTA | C23: 180619 | D23: PUPPIS CALIMA | E23: EVENTO DE APERTURA DIVERPOOL
A24: MODERNO | B24: BOGOTA | C24: 12390 | D24: EXITO COUNTRY | E24: PERSONAL EN CURSO DE ALTURAS
A25: MODERNO | B25: MEDELLIN | C25: 12130 | D25: EXITO LAURELES. | E25: CAMBIO DE RUTA - PLAN CANGURO EN LAS VAQUITAS
A30: CANAL | B30: CIUDAD | C30: VUM | D30: NOMBRE PDV
A31: ESPECIALIZADO | B31: BOGOTA | C31: 109096 | D31: PLAZA PETS S.A.S.
A32: ESPECIALIZADO | B32: BOGOTA | C32: 180621 | D32: PUPPIS CARRERA 15
A33: ESPECIALIZADO | B33: BOGOTA | C33: 188203 | D33: CONCENTRADOS EL RANCHO LTDA DROGUERIA VETERINARIA
A34: ESPECIALIZADO | B34: BOGOTA | C34: 424858 | D34: AGROCAMPO S.A.S.
A35: MODERNO | B35: BOGOTA | C35: 424893 | D35: HOMECENTER CALLE 80 CR 68
A36: MODERNO | B36: BOGOTA | C36: 105381 | D36: HOMECENTER AUTOPISTA NORTE BOGOTA
A37: ESPECIALIZADO | B37: CALI | C37: 191506 | D37: DEGANADO NORTE
A38: ESPECIALIZADO | B38: CALI | C38: 356594 | D38: SUPERMASCOTAS CIUDAD JARDIN
A39: MODERNO | B39: CALI | C39: 29714 | D39: MERCAMIO CALLE 5
A40: TRADICIONAL | B40: CALI | C40: 66552 | D40: LA CASA DE LOS TENDEROS
A41: ESPECIALIZADO | B41: MEDELLIN | C41: 424842 | D41: MUNDIAL DE GRANOS Y PANELAS S.A.S.

Sheet DATA INFORME
A1: ACTIVIDAD | B1: CIUDAD | C1: CADENA | D1: CODIGO PDV | E1: NOMBRE COMERCIAL | F1: CONSECUTIVO ENCUESTA | G1: NOMBRE ENCUESTA | H1: FECHA VISITA | I1: CODIGO RUTA | J1: USUARIO | K1: ¿CUMPLE HORARIO DE ENTRADA O SALIDA DE LA TIENDA? | L1: CUENTA CON PANTALON DEL UNIFORME SEGUN EL CARGO (NEGRO / ROJO / TURQUESA / JEAN) | M1: CUENTA CON CAMISA DEL UNIFORME Y LOGOS SEGÚN EL CARGO (NEGRA / GRIS / ROJA / TURQUESA) (PERMITIDO USAR DEBAJO DE CAMISA BUSO MANGA LARGA NEGRO) | N1: CUENTA CON CALZADO DE ACUERDO AL UNIFORME | O1: POSEE ALGUNA PRENDA ENCIMA DEL UNIFORME NO AUTORIZADA POR LA MARCA (SOLO PERMITIDO CHALECO DE SODIMAC Y EASY) | P1: EL UNIFORME Y ZAPATOS SE ENCUENTRAN LIMPIOS Y EN BUEN ESTADO | Q1: SU CABELLO LUCE LIMPIO, ORGANIZADO O RECOGIDO | R1: PRESENTA EXCESO DE MAQUILLAJE QUE NO CUMPLE CON EL CODIGO DE VESTIMENTA | S1: TIENE TATUAJES O PIERCINGS VISIBLES QUE NO CUMPLE CON EL CODIGO DE VESTIMENTA | T1: TIENE UÑAS LLAMATIVAS Y/O LARGAS QUE NO CUMPLE CON EL CODIGO DE VESTIMENTA | U1: USA ACCESORIOS QUE NO CUMPLE CON EL CODIGO DE VESTIMENTA | V1: SE PRODUCE ABORDO PROACTIVO (ANTES DE LOS 3 MIN) | W1: OFRECIO ALGUN PRODUCTO DEL PORTAFOLIO PURINA DE PRODUCTOS SECOS COMUNICANDO LOS BENEFICIOS DEL PRODUCTO | X1: OFRECIO ALGUN PRODUCTO DEL PORTAFOLIO PURINA DE PRODUCTOS HUMEDOS, SNACK U OTROS COMUNICANDO LOS BENEFICIOS DEL PRODUCTO | Y1: QUE CANAL VA A REALIZAR | Z1: M. OFRECE PURINA ONE: (APLICA SOLO EN CANAL MODERNO, CADENAS, SI EL PRODUCTO ESTA EN EL PDV) | AA1: M. MENCIONA QUE LOS RESULTADOS DE PURINA ONE SON VISIBLES EN 28 DIAS? | AB1: M. MENCIONA QUE TIENE CARNE DE VERDAD COMO INGREDIENTE NO.1 E INGREDIENTES NATURALES Y FUNCIONALES? | AC1: M. MENCIONA QUE PURINA ONE CUENTA CON ALIMENTO HUMEDO Y MENCIONA LAS 3 VARIADADES ( SUPER FOODS, SUPER NUTRIENTES Y MULTI PROTEINAS);PERRO Y GATO | AD1: M. MANEJA LA OBJECION DE ALTO PRECIO, COMUNICANDO LA BAJA DE PRECIOS DE LAS MARCAS O LAS OFERTAS DISPONIBLES EN EL PUNTO DE VENTA. | AE1: M. AL PRESENTAR OBJECIÓN "PRECIO MUY COSTOSO", EL ASESOR OFRECE LOS PRODUCTOS EN ORDEN DE SEGMENTACIÓN: P: PURINA ONE - DOG CHOW - ALPO G: PURINA ONE - CAT CHOW - FELIX - GATSY ( "DICE AHORA ES MAS SABROSO") | AF1: M. EL ASESOR COMUNICA SOBRE LA ACTIVIDAD "HOY GANAS MAÑANA TAMBIEN" | AG1: M. EL ASESOR EXPLICA CON CLARIDAD LA DINAMICA DE PARTICIPACIÓN | AH1: SE PRESENTARON OBJECIONES | AI1: DE QUE TIPO ES LA OBJECION | AJ1: RESUELVE LA OBJECION SATISFACTORIAMENTE | AK1: SE ENCUENTRA LIMPIA EL AREA DE DEMOSTRACION | AL1: REALIZA CIERRE CON FRASES " DESEA LLEVARLO" ,"CUANTOS DESEARIA LLEVAR" ," LE GUSTARIA ADQUIRIRLO" , " CUANTAS UNIDADES DESEA LLEVAR" , " LE GUSTARIA LLEVARLO EN PRESENTACIÓN HUMEDA O SECA" | AM1: CONSIDERO QUE INDEPENDIENTEMENTE DEL SPEECH, LA LABOR DE VENTA ES BUENA | AN1: EN CANAL E. LO PRIMERO QUE OFRECE EL ASESOR ES LA MARCA PRO PLAN? | AO1: EN CANAL E. DESPUES DE OBJECION DE PRECIO, EL ASESOR OFRECIO LA MARCA EXCELLENT? | AP1: EN CANAL E. EL ASESOR COMUNICA QUE LA MARCA EXCELLENT ESTA DENTRO DE LA CATEGORIA SUPERPREMIUM PERO A UN COSTO MAS ACCESIBLE. | AQ1: EN CANAL E. EL ASESOR COMUNICA LOS BENEFICIOS O CARACTERISTICAS DEL PRODUCTO EXCELLENT E INFORMA QUE EL PRODUCTO CAMBIO DE IMAGEN PERO CONTINUA CON LA MISMA FORMULA? | AR1: EN CANAL E., EL ASESOR OFRECE PRODUCTO HUMEDO Y COMUNICA LA DINAMICA DE MULTIPRICE (POR LA COMPRA DE MAS CANTIDADES TIENE DESCUENTO). | AS1: EN CANAL E., EL ASESOR COMUNICA PROACTIVAMENTE LA ACTIVIDAD DE "GANA AL INSTANTE" (A PARTIR DEL 17 DE MARZO) | AT1: EN CANAL E., EL ASESOR EXPLICA CON CLARIDAD LA ACTIVIDAD DE "GANA AL INSTANTE" (A PARTIR DEL 17 DE MARZO) | AU1: PRESENTA ALGUNA NOVEDAD? | AV1: CUAL ES LA NOVEDAD
A2: NESTLE PURINA | B2: BARRANQUILLA | C2: AGRO/PSHOP/VET | D2: 424883 | E2: CLINICA VETERINARIA DON PERRO BARRANQUILLA | F2: 1 | G2: MISTERY SHOPPER - IMPULSO MARZ0 2025 V0 | H2: 45730 | I2: 26400532 | J2: NestleP.5 | K2: NO | L2: NO | M2: NO | N2: NO | O2: NO | P2: NO | Q2: NO | R2: NO | S2: NO | T2: NO | U2: NO | V2: NO | W2: NINGUNO | X2: NO | Y2: CANAL ESPECIALIZADO | AH2: NO | AK2: NO | AL2: NO | AM2: NO | AN2: NO | AO2: NO | AP2: NO | AQ2: NO | AR2: NO | AS2: NO | AT2: NO
A3: NESTLE PURINA | B3: BOGOTA | C3: AGRO/PSHOP/VET | D3: 109096 | E3: PLAZA PETS S.A.S. | F3: 1 | G3: MISTERY SHOPPER - IMPULSO MARZ0 2025 V1 | H3: 45734 | I3: 26424986 | J3: NestleP.2 | K3: SI | L3: SI | M3: SI | N3: SI | O3: NO | P3: SI | Q3: SI | R3: NO | S3: NO | T3: NO | U3: SI | V3: SI | X3: NO | Y3: CANAL ESPECIALIZADO | AH3: SI | AJ3: NO | AK3: SI | AL3: NO | AM3: NO | AN3: SI | AO3: SI | AP3: SI | AQ3: SI | AU3: NO
A4: NESTLE PURINA | B4: BOGOTA | C4: AGRO/PSHOP/VET | D4: 125788 | E4: PUPPIS CALLE 85 | F4: 1 | G4: MISTERY SHOPPER - IMPULSO MARZ0 2025 V1 | H4: 45737 | I4: 26440851 | J4: NestleP.1 | K4: NO | AU4: SI | AV4: No se encuentra asesora en punto de venta , se espera por más de 45 minutos
A5: NESTLE PURINA | B5: BOGOTA | C5: AGRO/PSHOP/VET | D5: 180619 | E5: PUPPIS CALIMA | F5: 1 | G5: MISTERY SHOPPER - IMPULSO MARZ0 2025 V1 | H5: 45731 | I5: 26420000 | J5: NestleP.1 | K5: NO | AU5: SI | AV5: Se visita el punto en dos ocasiones por más de 40 minutos y no se encuentra ningún asesor o asesora de purina, por lo tanto me atienden los asesores de Puppis
A6: NESTLE PURINA | B6: BOGOTA | C6: AGRO/PSHOP/VET | D6: 180621 | E6: PUPPIS CARRERA 15 | F6: 1 | G6: MISTERY SHOPPER - IMPULSO MARZ0 2025 V1 | H6: 45731 | I6: 26419998 | J6: NestleP.1 | K6: SI | L6: SI | M6: SI | N6: SI | O6: NO | P6: SI | Q6: SI | R6: NO | S6: NO | T6: NO | U6: SI | V6: SI | W6: SI | X6: SI | Y6: CANAL ESPECIALIZADO | AH6: SI | AJ6: SI | AK6: SI | AL6: NO | AM6: SI | AN6: SI | AO6: SI | AP6: SI | AQ6: SI | AR6: NO | AU6: NO
A7: NESTLE PURINA | B7: BOGOTA | C7: AGRO/PSHOP/VET | D7: 188203 | E7: CONCENTRADOS EL RANCHO LTDA DROGUERIA VETERINARIA | F7: 1 | G7: MISTERY SHOPPER - IMPULSO MARZ0 2025 V1 | H7: 45734 | I7: 26424985 | J7: NestleP.2 | K7: SI | L7: SI | M7: SI | N7: SI | O7: NO | P7: SI | Q7: SI | R7: NO | S7: SI | T7: NO | U7: SI | V7: SI | X7: SI | Y7: CANAL ESPECIALIZADO | AH7: SI | AI7: NO TIENE DINERO | AJ7: SI | AK7: SI | AL7: SI | AM7: SI | AN7: SI | AO7: SI | AP7: SI | AQ7: SI | AR7: SI | AU7: NO
A8: NESTLE PURINA | B8: BOGOTA | C8: AGRO/PSHOP/VET | D8: 424858 | E8: AGROCAMPO S.A.S. | F8: 1 | G8: MISTERY SHOPPER - IMPULSO MARZ0 2025 V1 | H8: 45730 | I8: 26419994 | J8: NestleP.1 | K8: SI | L8: SI | M8: SI | N8: SI | O8: NO | P8: SI | Q8: SI | R8: NO | S8: NO | T8: NO | U8: NO | V8: SI | W8: SI | X8: SI | Y8: CANAL ESPECIALIZADO | AH8: SI | AJ8: SI | AK8: SI | AL8: NO | AM8: SI | AN8: SI | AO8: SI | AP8: SI | AQ8: SI | AR8: NO | AS8: NO | AT8: NO | AU8: SI | AV8: Se realiza la visita dos veces y la primera no se encuentra nadie y me atiende un asesor de agrocampo .
A9: NESTLE PURINA | B9: BOGOTA | C9: EXITO | D9: 12390 | E9: EXITO COUNTRY | F9: 1 | G9: MISTERY SHOPPER - IMPULSO MARZ0 2025 V1 | H9: 45735 | I9: 26429011 | J9: NestleP.1 | K9: NO | AU9: SI | AV9: No se encuentra asesor en punto de venta , se espera por más de 40 minutos
A10: NESTLE PURINA | B10: BOGOTA | C10: MODERNO | D10: 424893 | E10: HOMECENTER CALLE 80 CR 68 | F10: 1 | G10: MISTERY SHOPPER - IMPULSO MARZ0 2025 V1 | H10: 45736 | I10: 26439536 | J10: NestleP.1 | K10: SI | L10: SI | M10: SI | N10: SI | O10: NO | P10: SI | Q10: SI | R10: NO | S10: SI | T10: NO | U10: NO | V10: SI | X10: NINGUNO | Y10: CANAL MODERNO | Z10: SI | AA10: SI | AB10: SI | AC10: NO | AD10: SI | AE10: SI | AF10: NO | AG10: NO | AH10: SI | AJ10: SI | AK10: SI | AL10: NO | AM10: SI | AU10: NO
A11: NESTLE PURINA | B11: BOGOTA | C11: SODIMAC | D11: 105381 | E11: HOMECENTER AUTOPISTA NORTE BOGOTA | F11: 1 | G11: MISTERY SHOPPER - IMPULSO MARZ0 2025 V1 | H11: 45730 | I11: 26415788 | J11: NestleP.2 | K11: SI | L11: SI | M11: SI | N11: SI | O11: SI | P11: SI | Q11: SI | R11: NO | S11: NO | T11: NO | U11: NO | V11: SI | W11: SI | X11: SI | Y11: CANAL MODERNO | Z11: SI | AA11: SI | AB11: SI | AC11: SI | AD11: SI | AE11: SI | AF11: SI | AG11: SI | AH11: SI | AJ11: SI | AK11: SI | AL11: SI | AM11: SI | AU11: NO
A12: NESTLE PURINA | B12: CALI | C12: AGRO/PSHOP/VET | D12: 191506 | E12: DEGANADO NORTE | F12: 1 | G12: MISTERY SHOPPER - IMPULSO MARZ0 2025 V1 | H12: 45738 | I12: 26444245 | J12: NestleP.7 | K12: SI | L12: SI | M12: SI | N12: SI | O12: NO | P12: SI | Q12: SI | R12: NO | S12: NO | T12: NO | U12: NO | V12: SI | X12: NINGUNO | Y12: CANAL ESPECIALIZADO | AH12: SI | AI12: NO LE INTERESA EL PRODUCTO | AJ12: SI | AK12: SI | AL12: NO | AM12: SI | AN12: SI | AO12: SI | AP12: SI | AQ12: SI | AU12: NO
A13: NESTLE PURINA | B13: CALI | C13: AGRO/PSHOP/VET | D13: 356594 | E13: SUPERMASCOTAS CIUDAD JARDIN | F13: 1 | G13: MISTERY SHOPPER - IMPULSO MARZ0 2025 V1 | H13: 45731 | I13: 26404720 | J13: NestleP.7 | K13: SI | L13: SI | M13: SI | N13: SI | O13: NO | P13: SI | Q13: SI | R13: NO | S13: NO | T13: NO | U13: SI | V13: SI | X13: SI | Y13: CANAL ESPECIALIZADO | AH13: SI | AI13: NO TIENE DINERO | AJ13: SI | AK13: SI | AL13: SI | AM13: SI | AN13: SI | AO13: SI | AP13: SI | AQ13: SI | AU13: NO
A14: NESTLE PURINA | B14: CALI | C14: SUPERETE | D14: 29714 | E14: MERCAMIO CALLE 5 | F14: 1 | G14: MISTERY SHOPPER - IMPULSO MARZ0 2025 V1 | H14: 45738 | I14: 26693598 | J14: NestleP.7 | K14: SI | L14: SI | M14: SI | N14: SI | O14: NO | P14: SI | Q14: SI | R14: NO | S14: NO | T14: NO | U14: NO | V14: SI | W14: SI | Y14: CANAL MODERNO | Z14: NO | AA14: NO | AB14: NO | AC14: NO | AD14: NO | AE14: NO | AF14: NO | AG14: NO | AH14: SI | AI14: NO TIENE DINERO | AJ14: SI | AK14: SI | AL14: NO | AM14: SI | AU14: NO
A15: NESTLE PURINA | B15: CALI | C15: SUPERETE | D15: 66552 | E15: LA CASA DE LOS TENDEROS | F15: 1 | G15: MISTERY SHOPPER - IMPULSO MARZ0 2025 V0 | H15: 45729 | I15: 26388644 | J15: NestleP.7 | K15: SI | L15: SI | M15: SI | N15: SI | O15: NO | P15: SI | Q15: SI | R15: NO | S15: NO | T15: NO | U15: NO | V15: SI | X15: NO | Y15: TRADICIONAL | Z15: NO | AA15: NO | AB15: NO | AC15: NO | AD15: SI | AE15: SI | AF15: NO | AG15: SI | AH15: SI | AI15: NO TIENE DINERO | AJ15: SI | AK15: SI | AL15: NO | AM15: SI
A16: NESTLE PURINA | B16: MEDELLIN | C16: AGRO/PSHOP/VET | D16: 424842 | E16: MUNDIAL DE GRANOS Y PANELAS S.A.S. | F16: 1 | G16: MISTERY SHOPPER - IMPULSO MARZ0 2025 V1 | H16: 45737 | I16: 26442456 | J16: NestleP.10 | K16: SI | L16: SI | M16: SI | N16: SI | O16: NO | P16: SI | Q16: SI | R16: NO | S16: SI | T16: SI | U16: NO | V16: SI | X16: SI | Y16: CANAL ESPECIALIZADO | AH16: NO | AJ16: NO | AK16: SI | AL16: SI | AM16: SI | AN16: SI | AO16: NO | AP16: SI | AQ16: NO | AR16: NO | AU16: SI | AV16: La asesora cuenta con buena presentacion personal tiene tatuajes y uñas largas pero no son muy alarmantes, ella tiene guantes, y tiene muy buena presentacion
A17: NESTLE PURINA | B17: MEDELLIN | C17: EXITO | D17: 12130 | E17: EXITO LAURELES. | F17: 1 | G17: MISTERY SHOPPER - IMPULSO MARZ0 2025 V1 | H17: 45733 | I17: 26409010 | J17: NestleP.11 | K17: NO | AU17: SI | AV17: No se encontró personal de purina, estuve en tienda desde antes de las 9 am y me retiro cerca de las 10 am.

Sheet Videos
A1: CIUDAD | B1: NOMBRE COMERCIAL | C1: 1 | D1: 2 | E1: 3 | F1: 4 | G1: 5 | H1: 6 | I1: 7
A2: BARRANQUILLA | B2: CLINICA VETERINARIA DON PERRO BARRANQUILLA | C2: https://drive.google.com/file/d/1dJxfoE_vUxSahdw-az_5R2Y84xAeemD7/view?usp=drive_link | D2: -
A3: BOGOTA | B3: PUPPIS CALLE 85 | C3: https://drive.google.com/file/d/1ljUI_lnCpc2-SbOsvH03E1fx4JS54xVY/view?usp=drive_link | D3: -
A4: BOGOTA | B4: PUPPIS CALIMA | C4: https://drive.google.com/file/d/1BrG4MHtSiM_2ZNf8xsQvK6aOIVB5aqm6/view?usp=drive_link | D4: -
A5: BOGOTA | B5: EXITO COUNTRY | C5: https://drive.google.com/file/d/1nqGduGSqwsvOYr4D-W09T3hsPVHqfEAX/view?usp=drive_link | D5: https://drive.google.com/file/d/1grCa5EKfFhvayyMVnxgOgylHg2LG6k8A/view?usp=drive_link | E5: -
A6: CALI | B6: MERCAMIO CALLE 5 | C6: https://drive.google.com/file/d/1aroLMzUAo0E_mzfvoAd9tHSNPoiw5wvS/view?usp=drive_link | D6: -
A7: MEDELLIN | B7: EXITO LAURELES. | C7: https://drive.google.com/file/d/1kns1O4hCb6ruM3uToQ_ttxjO1TH66ngP/view?usp=drive_link | D7: -
A8: BOGOTA | B8: PLAZA PETS S.A.S. | C8: https://drive.google.com/file/d/1L94Xal8rBSqMOSN_gaUUukC8a2IRCnBt/view?usp=drive_link | D8: https://drive.google.com/file/d/1J2RwmsEJ6KQmRNb4NJ7km3iHKWuB674K/view?usp=drive_link | E8: https://drive.google.com/file/d/1UxBUCpGIs7Js5jgt8W_Vt0Uyo2foAmzm/view?usp=drive_link | F8: https://drive.google.com/file/d/12Aco7R0rMEmkXd65a55WkdCQv_3STEF1/view?usp=drive_link | G8: -
A9: BOGOTA | B9: PUPPIS CARRERA 15 | C9: https://drive.google.com/file/d/1NSN6PYCyxB6pHEG-xGpCJY23j3VbSAqC/view?usp=drive_link | D9: https://drive.google.com/file/d/1jm67uv-mxUO84GtwnJ9hevxEot9gsJv4/view?usp=drive_link | E9: -
A10: BOGOTA | B10: CONCENTRADOS EL RANCHO LTDA DROGUERIA VETERINARIA | C10: https://drive.google.com/file/d/1HG3zfZkUZ2oCgxhI19idftU6LHRpxQQ6/view?usp=drive_link | D10: https://drive.google.com/file/d/10Can88WBFtYz8-FLEJcjIlKIMafZT5_8/view?usp=drive_link | E10: https://drive.google.com/file/d/10RW1DRakbwUhhm7M7sRADCK7qOQXi0X0/view?usp=drive_link | F10: https://drive.google.com/file/d/1YL9UpMHiJTilf4jzMehw7t6hVkBuwvYS/view?usp=drive_link | G10: https://drive.google.com/file/d/1KXz_TUilebE10jKM4xcsJpv_-jFdbXd3/view?usp=drive_link | H10: https://drive.google.com/file/d/1HaJ-7XVtVzU6iLyoWfcZ8bqnS249fYHA/view?usp=drive_link | I10: https://drive.google.com/file/d/1X2kM8aKfRG6IDESM5kWFdyJYXT3MfSms/view?usp=drive_link
A11: BOGOTA | B11: AGROCAMPO S.A.S. | C11: https://drive.google.com/file/d/17uyCkyq02OLI43aOGEXZnXc31TDbgnP1/view?usp=drive_link | D11: -
A12: BOGOTA | B12: HOMECENTER CALLE 80 CR 68 | C12: https://drive.google.com/file/d/1l2qkzqvqd-zBG-tnCyPqgnKxCgga0Ac2/view?usp=drive_link | D12: -
A13: BOGOTA | B13: HOMECENTER AUTOPISTA NORTE BOGOTA | C13: https://drive.google.com/file/d/1I_83Tcy1Eo5VZlAAc4H1gtgfA175ec6x/view?usp=drive_link | D13: https://drive.google.com/file/d/1RRTofXpOTb7vs1iAyZ6mIpFQDUoES8iw/view?usp=drive_link | E13: https://drive.google.com/file/d/1tQ6hU_aoKFgSVChhj2wPSCqMtkzRy8eC/view?usp=drive_link | F13: https://drive.google.com/file/d/1lHcPHLjFNxjrzwK2wW7URnpdt-mJzTPp/view?usp=drive_link | G13: -
A14: CALI | B14: DEGANADO NORTE | C14: https://drive.google.com/file/d/1t94Yxm3Vf9iuIUp9vKytMJoEDHHmrwf4/view?usp=drive_link | D14: -
A15: CALI | B15: SUPERMASCOTAS CIUDAD JARDIN | C15: https://drive.google.com/file/d/1AEGI8-BxfeO7iR4wNs44BXMumfOQVkp6/view?usp=drive_link | D15: -
A16: CALI | B16: LA CASA DE LOS TENDEROS | C16: https://drive.google.com/file/d/1-NutpgAScNBQoIaJScTeSIhSVYBKvOnr/view?usp=drive_link | D16: -
A17: MEDELLIN | B17: MUNDIAL DE GRANOS Y PANELAS S.A.S. | C17: https://drive.google.com/file/d/1OKHEBXQmDXiS4v0I0kSdTCPZ84Z1vZbp/view?usp=drive_link | D17: -

Sheet Hoja2
A1: MYSTERY EFECTIVO | B1: SI
L2: CANAL | M2: CIUDAD | N2: VUM | O2: NOMBRE PDV | P2: DIRECCION | Q2: FECHA | R2: NOVEDAD
A3: Suma de TOTAL PUNTAJE | B3: Etiquetas de columna | L3: ESPECIALIZADO | M3: BOGOTA | N3: 425937 | O3: SERVICE CAN COLOMBIA | P3: CL CL 20A # 103A-15 | Q3: 45712 | R3: Asesor no Encontrado en primera visita
A4: Etiquetas de fila | B4: ABORDAJE | C4: HORARIO | D4: LABOR DE VENTA | E4: N/A | F4: PORTAFOLIO Y MANEJO DE OBJECIONES | G4: UNIFORME | H4: Total general | L4: MODERNO | M4: BOGOTA | N4: 442601 | O4: OLIMPICA 405 PLAZA DE LAS AMERICAS | P4: TV 64A # 26-50 | Q4: 45708 | R4: Asesor no Encontrado en primera visita
A5: 26415788 | B5: 20 | C5: 20 | D5: 15 | E5: 0 | F5: 25.6 | G5: 15 | H5: 95.6 | L5: MODERNO | M5: BOGOTA | N5: 443809 | O5: AHORRE MAS | P5: CR 111A # 22A - 23 | Q5: 45709 | R5: Asesor no Encontrado en primera visita
A6: 26439536 | B6: 20 | C6: 20 | D6: 15 | E6: 0 | F6: 25.6 | G6: 15 | H6: 95.6 | L6: TRADICIONAL | M6: CALI | N6: 127066 | O6: MERCAFAMILIAR LAS PALMAS S.A.S. | P6: CR 29 # 19-64 | Q6: 45708 | R6: Asesor no Encontrado en primera visita
A7: 26419994 | B7: 20 | C7: 20 | D7: 15 | E7: 0 | F7: 25.2 | G7: 15 | H7: 95.2
A8: 26693598 | B8: 20 | C8: 20 | D8: 15 | E8: 0 | F8: 22.6 | G8: 15 | H8: 92.6 | L8: CANAL | M8: CIUDAD | N8: VUM | O8: NOMBRE PDV | P8: DIRECCION | Q8: FECHA
A9: 26442456 | B9: 20 | C9: 20 | D9: 15 | E9: 0 | F9: 20.4 | G9: 15 | H9: 90.4
A10: 26419998 | B10: 20 | C10: 20 | D10: 15 | E10: 0 | F10: 20.4 | G10: 15 | H10: 90.4
A11: 26424985 | B11: 20 | C11: 20 | D11: 15 | E11: 0 | F11: 20.4 | G11: 15 | H11: 90.4
A12: 26404720 | B12: 20 | C12: 20 | D12: 15 | E12: 0 | F12: 18 | G12: 15 | H12: 88
A13: 26424986 | B13: 20 | C13: 20 | D13: 15 | E13: 0 | F13: 18 | G13: 15 | H13: 88
A14: 26444245 | B14: 20 | C14: 20 | D14: 15 | E14: 0 | F14: 18 | G14: 15 | H14: 88
A15: 26388644 | B15: 20 | C15: 20 | D15: 15 | E15: 0 | F15: 8.4 | G15: 15 | H15: 78.4
A16: Total general | B16: 220 | C16: 220 | D16: 165 | E16: 0 | F16: 222.6 | G16: 165 | H16: 992.6
A18: 26400581 | B18: eliminado generico

Sheet Export
A1: ACTIVIDAD | B1: REGIONAL | C1: CIUDAD | D1: CANAL | E1: CADENA | F1: SUBCADENA | G1: ZONA | H1: RV | I1: CODIGO PDV | J1: NOMBRE COMERCIAL | K1: CODIGO EAN | L1: TIPO PUNTO VENTA | M1: CONSECUTIVO ENCUESTA | N1: NOMBRE ENCUESTA | O1: PREGUNTA | P1: RESPUESTA | Q1: CODIGO FOTO | R1: OBSERVACION | S1: FECHA VISITA | T1: FECHA INICIO VISITA | U1: FECHA CREACIÓN RESPUESTA | V1: CODIGO RUTA | W1: CLIENTE | X1: CODIGO EXHIBICION | Y1: NOMBRE EXHIBICION | Z1: NOMBRE USUARIO | AA1: USUARIO | AB1: NOMBRE SUPERVISOR | AC1: USUARIO SUPERVISOR
A2: NESTLE PURINA | B2: PACIFICO | C2: CALI | D2: TRADICIONAL | E2: SUPERETE | F2: SUPERETES | G2: CALI | I2: 66552 | J2: LA CASA DE LOS TENDEROS | K2: 0 | L2: Mercadeo | M2: 1 | N2: MISTERY SHOPPER - IMPULSO MARZ0 2025 V0 | O2: ¿CUMPLE HORARIO DE ENTRADA O SALIDA DE LA TIENDA? | P2: SI | S2: 45729 | T2: 13/03/2025 18:51:58 | U2: 13/03/2025 18:58:17 | V2: 26388644 | W2: PRODUCTIVIDAD | Z2: User 7 | AA2: NestleP.7 | AB2: CAMILO MONTAÑO RESTREPO | AC2: camilo.montano
A3: NESTLE PURINA | B3: PACIFICO | C3: CALI | D3: TRADICIONAL | E3: SUPERETE | F3: SUPERETES | G3: CALI | I3: 66552 | J3: LA CASA DE LOS TENDEROS | K3: 0 | L3: Mercadeo | M3: 1 | N3: MISTERY SHOPPER - IMPULSO MARZ0 2025 V0 | O3: CUENTA CON PANTALON DEL UNIFORME SEGUN EL CARGO (NEGRO / ROJO / TURQUESA / JEAN) | P3: SI | S3: 45729 | T3: 13/03/2025 18:51:58 | U3: 13/03/2025 18:58:17 | V3: 26388644 | W3: PRODUCTIVIDAD | Z3: User 7 | AA3: NestleP.7 | AB3: CAMILO MONTAÑO RESTREPO | AC3: camilo.montano
A4: NESTLE PURINA | B4: PACIFICO | C4: CALI | D4: TRADICIONAL | E4: SUPERETE | F4: SUPERETES | G4: CALI | I4: 66552 | J4: LA CASA DE LOS TENDEROS | K4: 0 | L4: Mercadeo | M4: 1 | N4: MISTERY SHOPPER - IMPULSO MARZ0 2025 V0 | O4: CUENTA CON CAMISA DEL UNIFORME Y LOGOS SEGÚN EL CARGO (NEGRA / GRIS / ROJA / TURQUESA) (PERMITIDO USAR DEBAJO DE CAMISA BUSO MANGA LARGA NEGRO) | P4: SI | S4: 45729 | T4: 13/03/2025 18:51:58 | U4: 13/03/2025 18:58:17 | V4: 26388644 | W4: PRODUCTIVIDAD | Z4: User 7 | AA4: NestleP.7 | AB4: CAMILO MONTAÑO RESTREPO | AC4: camilo.montano
A5: NESTLE PURINA | B5: PACIFICO | C5: CALI | D5: TRADICIONAL | E5: SUPERETE | F5: SUPERETES | G5: CALI | I5: 66552 | J5: LA CASA DE LOS TENDEROS | K5: 0 | L5: Mercadeo | M5: 1 | N5: MISTERY SHOPPER - IMPULSO MARZ0 2025 V0 | O5: CUENTA CON CALZADO DE ACUERDO AL UNIFORME | P5: SI | S5: 45729 | T5: 13/03/2025 18:51:58 | U5: 13/03/2025 18:58:17 | V5: 26388644 | W5: PRODUCTIVIDAD | Z5: User 7 | AA5: NestleP.7 | AB5: CAMILO MONTAÑO RESTREPO | AC5: camilo.montano
A6: NESTLE PURINA | B6: PACIFICO | C6: CALI | D6: TRADICIONAL | E6: SUPERETE | F6: SUPERETES | G6: CALI | I6: 66552 | J6: LA CASA DE LOS TENDEROS | K6: 0 | L6: Mercadeo | M6: 1 | N6: MISTERY SHOPPER - IMPULSO MARZ0 2025 V0 | O6: POSEE ALGUNA PRENDA ENCIMA DEL UNIFORME NO AUTORIZADA POR LA MARCA (SOLO PERMITIDO CHALECO DE SODIMAC Y EASY) | P6: NO | S6: 45729 | T6: 13/03/2025 18:51:58 | U6: 13/03/2025 18:58:17 | V6: 26388644 | W6: PRODUCTIVIDAD | Z6: User 7 | AA6: NestleP.7 | AB6: CAMILO MONTAÑO RESTREPO | AC6: camilo.montano
A7: NESTLE PURINA | B7: PACIFICO | C7: CALI | D7: TRADICIONAL | E7: SUPERETE | F7: SUPERETES | G7: CALI | I7: 66552 | J7: LA CASA DE LOS TENDEROS | K7: 0 | L7: Mercadeo | M7: 1 | N7: MISTERY SHOPPER - IMPULSO MARZ0 2025 V0 | O7: EL UNIFORME Y ZAPATOS SE ENCUENTRAN LIMPIOS Y EN BUEN ESTADO | P7: SI | S7: 45729 | T7: 13/03/2025 18:51:58 | U7: 13/03/2025 18:58:17 | V7: 26388644 | W7: PRODUCTIVIDAD | Z7: User 7 | AA7: NestleP.7 | AB7: CAMILO MONTAÑO RESTREPO | AC7: camilo.montano
A8: NESTLE PURINA | B8: PACIFICO | C8: CALI | D8: TRADICIONAL | E8: SUPERETE | F8: SUPERETES | G8: CALI | I8: 66552 | J8: LA CASA DE LOS TENDEROS | K8: 0 | L8: Mercadeo | M8: 1 | N8: MISTERY SHOPPER - IMPULSO MARZ0 2025 V0 | O8: SU CABELLO LUCE LIMPIO, ORGANIZADO O RECOGIDO | P8: SI | S8: 45729 | T8: 13/03/2025 18:51:58 | U8: 13/03/2025 18:58:17 | V8: 26388644 | W8: PRODUCTIVIDAD | Z8: User 7 | AA8: NestleP.7 | AB8: CAMILO MONTAÑO RESTREPO | AC8: camilo.montano
A9: NESTLE PURINA | B9: PACIFICO | C9: CALI | D9: TRADICIONAL | E9: SUPERETE | F9: SUPERETES | G9: CALI | I9: 66552 | J9: LA CASA DE LOS TENDEROS | K9: 0 | L9: Mercadeo | M9: 1 | N9: MISTERY SHOPPER - IMPULSO MARZ0 2025 V0 | O9: PRESENTA EXCESO DE MAQUILLAJE QUE NO CUMPLE CON EL CODIGO DE VESTIMENTA | P9: NO | S9: 45729 | T9: 13/03/2025 18:51:58 | U9: 13/03/2025 18:58:17 | V9: 26388644 | W9: PRODUCTIVIDAD | Z9: User 7 | AA9: NestleP.7 | AB9: CAMILO MONTAÑO RESTREPO | AC9: camilo.montano
A10: NESTLE PURINA | B10: PACIFICO | C10: CALI | D10: TRADICIONAL | E10: SUPERETE | F10: SUPERETES | G10: CALI | I10: 66552 | J10: LA CASA DE LOS TENDEROS | K10: 0 | L10: Mercadeo | M10: 1 | N10: MISTERY SHOPPER - IMPULSO MARZ0 2025 V0 | O10: TIENE TATUAJES O PIERCINGS VISIBLES QUE NO CUMPLE CON EL CODIGO DE VESTIMENTA | P10: NO | S10: 45729 | T10: 13/03/2025 18:51:58 | U10: 13/03/2025 18:58:17 | V10: 26388644 | W10: PRODUCTIVIDAD | Z10: User 7 | AA10: NestleP.7 | AB10: CAMILO MONTAÑO RESTREPO | AC10: camilo.montano
A11: NESTLE PURINA | B11: PACIFICO | C11: CALI | D11: TRADICIONAL | E11: SUPERETE | F11: SUPERETES | G11: CALI | I11: 66552 | J11: LA CASA DE LOS TENDEROS | K11: 0 | L11: Mercadeo | M11: 1 | N11: MISTERY SHOPPER - IMPULSO MARZ0 2025 V0 | O11: TIENE UÑAS LLAMATIVAS Y/O LARGAS QUE NO CUMPLE CON EL CODIGO DE VESTIMENTA | P11: NO | S11: 45729 | T11: 13/03/2025 18:51:58 | U11: 13/03/2025 18:58:17 | V11: 26388644 | W11: PRODUCTIVIDAD | Z11: User 7 | AA11: NestleP.7 | AB11: CAMILO MONTAÑO RESTREPO | AC11: camilo.montano
A12: NESTLE PURINA | B12: PACIFICO | C12: CALI | D12: TRADICIONAL | E12: SUPERETE | F12: SUPERETES | G12: CALI | I12: 66552 | J12: LA CASA DE LOS TENDEROS | K12: 0 | L12: Mercadeo | M12: 1 | N12: MISTERY SHOPPER - IMPULSO MARZ0 2025 V0 | O12: USA ACCESORIOS QUE NO CUMPLE CON EL CODIGO DE VESTIMENTA | P12: NO | S12: 45729 | T12: 13/03/2025 18:51:58 | U12: 13/03/2025 18:58:17 | V12: 26388644 | W12: PRODUCTIVIDAD | Z12: User 7 | AA12: NestleP.7 | AB12: CAMILO MONTAÑO RESTREPO | AC12: camilo.montano
A13: NESTLE PURINA | B13: PACIFICO | C13: CALI | D13: TRADICIONAL | E13: SUPERETE | F13: SUPERETES | G13: CALI | I13: 66552 | J13: LA CASA DE LOS TENDEROS | K13: 0 | L13: Mercadeo | M13: 1 | N13: MISTERY SHOPPER - IMPULSO MARZ0 2025 V0 | O13: SE PRODUCE ABORDO PROACTIVO (ANTES DE LOS 3 MIN) | P13: SI | S13: 45729 | T13: 13/03/2025 18:51:58 | U13: 13/03/2025 18:58:17 | V13: 26388644 | W13: PRODUCTIVIDAD | Z13: User 7 | AA13: NestleP.7 | AB13: CAMILO MONTAÑO RESTREPO | AC13: camilo.montano
... A90: NESTLE PURINA | B90: ANTIOQUIA | C90: MEDELLIN | D90: MODERNO | E90: EXITO | F90: 037 EXITO LAURELES | G90: MEDELLIN | I90: 12130 | J90: EXITO LAURELES. | K90: SAP7701001003702909919 | L90: Impulso | M90: 1 | N90: MISTERY SHOPPER - IMPULSO MARZ0 2025 V1 | O90: CUAL ES LA NOVEDAD | P90: No se encontró personal de purina, estuve en tienda desde antes de las 9 am y me retiro cerca de las 10 am. | S90: 45733 | T90: 17/03/2025 10:05:43 | U90: 17/03/2025 10:07:10 | V90: 26409010 | W90: PRODUCTIVIDAD | Z90: User 11 | AA90: NestleP.11 | AB90: CAMILO MONTAÑO RESTREPO | AC90: camilo.montano
A91: NESTLE PURINA | B91: CENTRO | C91: BOGOTA | D91: MODERNO | E91: SODIMAC | F91: SODIMAC | G91: CENTRO | I91: 105381 | J91: HOMECENTER AUTOPISTA NORTE BOGOTA | K91: 7703670900702 | L91: Impulso | M91: 1 | N91: MISTERY SHOPPER - IMPULSO MARZ0 2025 V1 | O91: ¿CUMPLE HORARIO DE ENTRADA O SALIDA DE LA TIENDA? | P91: SI | S91: 45730 | T91: 45730.385 | U91: 45730.397 | V91: 26415788 | W91: PRODUCTIVIDAD | Z91: User 2 | AA91: NestleP.2 | AB91: CAMILO MONTAÑO RESTREPO | AC91: camilo.montano
A92: NESTLE PURINA | B92: CENTRO | C92: BOGOTA | D92: MODERNO | E92: SODIMAC | F92: SODIMAC | G92: CENTRO | I92: 105381 | J92: HOMECENTER AUTOPISTA NORTE BOGOTA | K92: 7703670900702 | L92: Impulso | M92: 1 | N92: MISTERY SHOPPER - IMPULSO MARZ0 2025 V1 | O92: CUENTA CON PANTALON DEL UNIFORME SEGUN EL CARGO (NEGRO / ROJO / TURQUESA / JEAN) | P92: SI | S92: 45730 | T92: 45730.385 | U92: 45730.397 | V92: 26415788 | W92: PRODUCTIVIDAD | Z92: User 2 | AA92: NestleP.2 | AB92: CAMILO MONTAÑO RESTREPO | AC92: camilo.montano
A93: NESTLE PURINA | B93: CENTRO | C93: BOGOTA | D93: MODERNO | E93: SODIMAC | F93: SODIMAC | G93: CENTRO | I93: 105381 | J93: HOMECENTER AUTOPISTA NORTE BOGOTA | K93: 7703670900702 | L93: Impulso | M93: 1 | N93: MISTERY SHOPPER - IMPULSO MARZ0 2025 V1 | O93: CUENTA CON CAMISA DEL UNIFORME Y LOGOS SEGÚN EL CARGO (NEGRA / GRIS / ROJA / TURQUESA) (PERMITIDO USAR DEBAJO DE CAMISA BUSO MANGA LARGA NEGRO) | P93: SI | S93: 45730 | T93: 45730.385 | U93: 45730.397 | V93: 26415788 | W93: PRODUCTIVIDAD | Z93: User 2 | AA93: NestleP.2 | AB93: CAMILO MONTAÑO RESTREPO | AC93: camilo.montano
A94: NESTLE PURINA | B94: CENTRO | C94: BOGOTA | D94: MODERNO | E94: SODIMAC | F94: SODIMAC | G94: CENTRO | I94: 105381 | J94: HOMECENTER AUTOPISTA NORTE BOGOTA | K94: 7703670900702 | L94: Impulso | M94: 1 | N94: MISTERY SHOPPER - IMPULSO MARZ0 2025 V1 | O94: CUENTA CON CALZADO DE ACUERDO AL UNIFORME | P94: SI | S94: 45730 | T94: 45730.385 | U94: 45730.397 | V94: 26415788 | W94: PRODUCTIVIDAD | Z94: User 2 | AA94: NestleP.2 | AB94: CAMILO MONTAÑO RESTREPO | AC94: camilo.montano
A95: NESTLE PURINA | B95: CENTRO | C95: BOGOTA | D95: MODERNO | E95: SODIMAC | F95: SODIMAC | G95: CENTRO | I95: 105381 | J95: HOMECENTER AUTOPISTA NORTE BOGOTA | K95: 7703670900702 | L95: Impulso | M95: 1 | N95: MISTERY SHOPPER - IMPULSO MARZ0 2025 V1 | O95: POSEE ALGUNA PRENDA ENCIMA DEL UNIFORME NO AUTORIZADA POR LA MARCA (SOLO PERMITIDO CHALECO DE SODIMAC Y EASY) | P95: SI | S95: 45730 | T95: 45730.385 | U95: 45730.397 | V95: 26415788 | W95: PRODUCTIVIDAD | Z95: User 2 | AA95: NestleP.2 | AB95: CAMILO MONTAÑO RESTREPO | AC95: camilo.montano
A96: NESTLE PURINA | B96: CENTRO | C96: BOGOTA | D96: MODERNO | E96: SODIMAC | F96: SODIMAC | G96: CENTRO | I96: 105381 | J96: HOMECENTER AUTOPISTA NORTE BOGOTA | K96: 7703670900702 | L96: Impulso | M96: 1 | N96: MISTERY SHOPPER - IMPULSO MARZ0 2025 V1 | O96: EL UNIFORME Y ZAPATOS SE ENCUENTRAN LIMPIOS Y EN BUEN ESTADO | P96: SI | S96: 45730 | T96: 45730.385 | U96: 45730.397 | V96: 26415788 | W96: PRODUCTIVIDAD | Z96: User 2 | AA96: NestleP.2 | AB96: CAMILO MONTAÑO RESTREPO | AC96: camilo.montano
A97: NESTLE PURINA | B97: CENTRO | C97: BOGOTA | D97: MODERNO | E97: SODIMAC | F97: SODIMAC | G97: CENTRO | I97: 105381 | J97: HOMECENTER AUTOPISTA NORTE BOGOTA | K97: 7703670900702 | L97: Impulso | M97: 1 | N97: MISTERY SHOPPER - IMPULSO MARZ0 2025 V1 | O97: SU CABELLO LUCE LIMPIO, ORGANIZADO O RECOGIDO | P97: SI | S97: 45730 | T97: 45730.385 | U97: 45730.397 | V97: 26415788 | W97: PRODUCTIVIDAD | Z97: User 2 | AA97: NestleP.2 | AB97: CAMILO MONTAÑO RESTREPO | AC97: camilo.montano
A98: NESTLE PURINA | B98: CENTRO | C98: BOGOTA | D98: MODERNO | E98: SODIMAC | F98: SODIMAC | G98: CENTRO | I98: 105381 | J98: HOMECENTER AUTOPISTA NORTE BOGOTA | K98: 7703670900702 | L98: Impulso | M98: 1 | N98: MISTERY SHOPPER - IMPULSO MARZ0 2025 V1 | O98: PRESENTA EXCESO DE MAQUILLAJE QUE NO CUMPLE CON EL CODIGO DE VESTIMENTA | P98: NO | S98: 45730 | T98: 45730.385 | U98: 45730.397 | V98: 26415788 | W98: PRODUCTIVIDAD | Z98: User 2 | AA98: NestleP.2 | AB98: CAMILO MONTAÑO RESTREPO | AC98: camilo.montano
A99: NESTLE PURINA | B99: CENTRO | C99: BOGOTA | D99: MODERNO | E99: SODIMAC | F99: SODIMAC | G99: CENTRO | I99: 105381 | J99: HOMECENTER AUTOPISTA NORTE BOGOTA | K99: 7703670900702 | L99: Impulso | M99: 1 | N99: MISTERY SHOPPER - IMPULSO MARZ0 2025 V1 | O99: TIENE TATUAJES O PIERCINGS VISIBLES QUE NO CUMPLE CON EL CODIGO DE VESTIMENTA | P99: NO | S99: 45730 | T99: 45730.385 | U99: 45730.397 | V99: 26415788 | W99: PRODUCTIVIDAD | Z99: User 2 | AA99: NestleP.2 | AB99: CAMILO MONTAÑO RESTREPO | AC99: camilo.montano
A100: NESTLE PURINA | B100: CENTRO | C100: BOGOTA | D100: MODERNO | E100: SODIMAC | F100: SODIMAC | G100: CENTRO | I100: 105381 | J100: HOMECENTER AUTOPISTA NORTE BOGOTA | K100: 7703670900702 | L100: Impulso | M100: 1 | N100: MISTERY SHOPPER - IMPULSO MARZ0 2025 V1 | O100: TIENE UÑAS LLAMATIVAS Y/O LARGAS QUE NO CUMPLE CON EL CODIGO DE VESTIMENTA | P100: NO | S100: 45730 | T100: 45730.385 | U100: 45730.397 | V100: 26415788 | W100: PRODUCTIVIDAD | Z100: User 2 | AA100: NestleP.2 | AB100: CAMILO MONTAÑO RESTREPO | AC100: camilo.montano
A101: NESTLE PURINA | B101: CENTRO | C101: BOGOTA | D101: MODERNO | E101: SODIMAC | F101: SODIMAC | G101: CENTRO | I101: 105381 | J101: HOMECENTER AUTOPISTA NORTE BOGOTA | K101: 7703670900702 | L101: Impulso | M101: 1 | N101: MISTERY SHOPPER - IMPULSO MARZ0 2025 V1 | O101: USA ACCESORIOS QUE NO CUMPLE CON EL CODIGO DE VESTIMENTA | P101: NO | S101: 45730 | T101: 45730.385 | U101: 45730.397 | V101: 26415788 | W101: PRODUCTIVIDAD | Z101: User 2 | AA101: NestleP.2 | AB101: CAMILO MONTAÑO RESTREPO | AC101: camilo.montano
A102: NESTLE PURINA | B102: CENTRO | C102: BOGOTA | D102: MODERNO | E102: SODIMAC | F102: SODIMAC | G102: CENTRO | I102: 105381 | J102: HOMECENTER AUTOPISTA NORTE BOGOTA | K102: 7703670900702 | L102: Impulso | M102: 1 | N102: MISTERY SHOPPER - IMPULSO MARZ0 2025 V1 | O102: SE PRODUCE ABORDO PROACTIVO (ANTES DE LOS 3 MIN) | P102: SI | S102: 45730 | T102: 45730.385 | U102: 45730.397 | V102: 26415788 | W102: PRODUCTIVIDAD | Z102: User 2 | AA102: NestleP.2 | AB102: CAMILO MONTAÑO RESTREPO | AC102: camilo.montano
... A119: NESTLE PURINA | B119: CENTRO | C119: BOGOTA | D119: MODERNO | E119: SODIMAC | F119: SODIMAC | G119: CENTRO | I119: 105381 | J119: HOMECENTER AUTOPISTA NORTE BOGOTA | K119: 7703670900702 | L119: Impulso | M119: 1 | N119: MISTERY SHOPPER - IMPULSO MARZ0 2025 V1 | O119: PRESENTA ALGUNA NOVEDAD? | P119: NO | S119: 45730 | T119: 45730.385 | U119: 45730.397 | V119: 26415788 | W119: PRODUCTIVIDAD | Z119: User 2 | AA119: NestleP.2 | AB119: CAMILO MONTAÑO RESTREPO | AC119: camilo.montano
A120: NESTLE PURINA | B120: CENTRO | C120: BOGOTA | D120: ESPECIALIZADO | E120: AGRO/PSHOP/VET | F120: AGRO/PSHOP/VET | G120: CENTRO | I120: 424858 | J120: AGROCAMPO S.A.S. | K120: 0 | L120: Impulso | M120: 1 | N120: MISTERY SHOPPER - IMPULSO MARZ0 2025 V1 | O120: ¿CUMPLE HORARIO DE ENTRADA O SALIDA DE LA TIENDA? | P120: SI | S120: 45730 | T120: 18/03/2025 20:08:05 | U120: 18/03/2025 20:16:54 | V120: 26419994 | W120: PRODUCTIVIDAD | Z120: User 1 | AA120: NestleP.1 | AB120: CAMILO MONTAÑO RESTREPO | AC120: camilo.montano
A121: NESTLE PURINA | B121: CENTRO | C121: BOGOTA | D121: ESPECIALIZADO | E121: AGRO/PSHOP/VET | F121: AGRO/PSHOP/VET | G121: CENTRO | I121: 424858 | J121: AGROCAMPO S.A.S. | K121: 0 | L121: Impulso | M121: 1 | N121: MISTERY SHOPPER - IMPULSO MARZ0 2025 V1 | O121: CUENTA CON PANTALON DEL UNIFORME SEGUN EL CARGO (NEGRO / ROJO / TURQUESA / JEAN) | P121: SI | S121: 45730 | T121: 18/03/2025 20:08:05 | U121: 18/03/2025 20:16:54 | V121: 26419994 | W121: PRODUCTIVIDAD | Z121: User 1 | AA121: NestleP.1 | AB121: CAMILO MONTAÑO RESTREPO | AC121: camilo.montano
