Workbook
Name SegmentaciónDeDatos_CANAL: #N/A
Name SegmentaciónDeDatos_CIUDAD: #N/A
Name SegmentaciónDeDatos_NOMBRE_COMERCIAL: #N/A

Sheet INFORME
D3: EJECUCION DEL PLAN
D4: CIUDAD | E4: #PDV Obj. | F4: #PDV Eje. | G4: .% Ejecucion | H4: Obj Auditoria | I4: Auditoria Eje. | J4: % Efectividad.
D5: MEDELLIN | E5: 1 | F5: 1 | G5: 1 | H5: 1 | I5: 1 | J5: 1
D6: CALI | E6: 1 | F6: 1 | G6: 1 | H6: 1 | I6: 1 | J6: 1
D7: BARRANQUILLA | E7: 2 | F7: 2 | G7: 1 | H7: 2 | I7: 1 | J7: 0.5
D8: Total general | E8: 4 | F8: 4 | G8: 1 | H8: 4 | I8: 3 | J8: 0.75
D12: MYSTERY EFECTIVO | E12: SI
D13: MYSTERY POR CLUSTER
D14: Suma de % MYSTERY | E14: Etiquetas de columna
D15: CLUSTER | E15: TRADICIONAL | F15: % MYSTERY
D16: ACTIVIDADES DEL MES | E16: 1 | F16: 1
D17: EJECUCION DEL PDV | E17: 1 | F17: 1
D18: HORARIO | E18: 1 | F18: 1
D19: PRESENTACIÓN PERSONAL | E19: 0.96666667 | F19: 0.96666667
D20: % MYSTERY | E20: 0.99615385 | F20: 0.99615385
D25: MYSTERY EFECTIVO | E25: SI
D26: MYSTERY POR CLUSTER - CIUDAD
D27: Suma de % MYSTERY | E27: Etiquetas de columna
D28: CLUSTER | E28: MEDELLIN | F28: BARRANQUILLA | G28: CALI | H28: % MYSTERY
D29: HORARIO | E29: 1 | F29: 1 | G29: 1 | H29: 1
D30: PRESENTACIÓN PERSONAL | E30: 0.9 | F30: 1 | G30: 1 | H30: 0.96666667
D31: EJECUCION DEL PDV | E31: 1 | F31: 1 | G31: 1 | H31: 1
D32: ACTIVIDADES DEL MES | E32: 1 | F32: 1 | G32: N/A | H32: 1
D33: % MYSTERY | E33: 0.99 | F33: 1 | G33: 1 | H33: 0.99615385
D38: MYSTERY EFECTIVO | E38: SI
D39: MYSTERY POR PDV
D40: Suma de % MYSTERY | G40: CLUSTER
D41: CIUDAD | E41: CANAL | F41: NOMBRE COMERCIAL | G41: HORARIO | H41: PRESENTACIÓN PERSONAL | I41: EJECUCION DEL PDV | J41: ACTIVIDADES DEL MES | K41: % MYSTERY
D42: MEDELLIN | E42: TRADICIONAL | F42: SUPERMERCADO MAXIFRUVER PREMIUM | G42: 1 | H42: 0.9 | I42: 1 | J42: 1 | K42: 0.99
D43: BARRANQUILLA | E43: TRADICIONAL | F43: DISTRIBUCIONES MILENA | G43: 1 | H43: 1 | I43: 1 | J43: 1 | K43: 1
D44: CALI | E44: TRADICIONAL | F44: LA CASA DE LOS TENDEROS | G44: 1 | H44: 1 | I44: 1 | J44: N/A | K44: 1
D45: % MYSTERY | G45: 1 | H45: 0.96666667 | I45: 1 | J45: 1 | K45: 0.99615385

Sheet PUNTAJES
A1: ACTIVIDAD | B1: CIUDAD | C1: CANAL | D1: CADENA | E1: CODIGO PDV | F1: NOMBRE COMERCIAL | G1: PREGUNTA | H1: NOMBRE ENCUESTA | I1: RESPUESTA | J1: FECHA VISITA | K1: CODIGO RUTA | L1: USUARIO | M1: MYSTERY EFECTIVO | N1: CLUSTER | O1: TOTAL PUNTAJE | P1: RTA CORRECTA | Q1: PUNTAJE OBTENIDO
A2: NESTLE PURINA | B2: BARRANQUILLA | C2: TRADICIONAL | D2: SUPERETE | E2: 65453 | F2: DISTRIBUCIONES MILENA | G2: ¿CUMPLE HORARIO DE ENTRADA O SALIDA DE LA TIENDA? | H2: AUDITORIA - MERCADEO PURINA MARZO 2025 | I2: SI | J2: 45733 | K2: 26407885 | L2: NestleP.4 | M2: =_xlfn.XLOOKUP(PUNTAJE[[#This Row],[CODIGO RUTA]],'DATA INFORME'!G:G,'DATA INFORME'!I:I) -> SI | N2: =IF(PUNTAJE[[#This Row],[MYSTERY EFECTIVO]]="SI",(_xlfn.XLOOKUP(PUNTAJE[[#This Row],[PREGUNTA]],ENCUESTA!G:G,ENCUESTA!E:E)),"N/A") -> HORARIO | O2: =IF(PUNTAJE[[#This Row],[MYSTERY EFECTIVO]]="SI",(IF(PUNTAJE[[#This Row],[CANAL]]="TRADICIONAL",_xlfn.XLOOKUP(PUNTAJE[[#This Row],[PREGUNTA]],ENCUESTA!G:G,ENCUESTA!A:A),IF(PUNTAJE[[#This Row],[CANAL]]="ESPECIALIZADO",_xlfn.XLOOKUP(PUNTAJE[[#This Row],[PREGUNTA]],ENCUESTA!G:G,ENCUESTA!B:B),IF(PUNTAJE[[#This Row],[CANAL]]="MODERNO",_xlfn.XLOOKUP(PUNTAJE[[#This Row],[PREGUNTA]],ENCUESTA!G:G,ENCUESTA!C:C))))),0) -> 20 | P2: =_xlfn.XLOOKUP(PUNTAJE[[#This Row],[PREGUNTA]],ENCUESTA!G:G,ENCUESTA!H:H) -> SI | Q2: =IF(PUNTAJE[[#This Row],[RESPUESTA]]=PUNTAJE[[#This Row],[RTA CORRECTA]],PUNTAJE[[#This Row],[TOTAL PUNTAJE]],0) -> 20
A3: NESTLE PURINA | B3: BARRANQUILLA | C3: TRADICIONAL | D3: SUPERETE | E3: 65453 | F3: DISTRIBUCIONES MILENA | G3: CUENTA CON PANTALON DEL UNIFORME SEGÚN EL CARGO (NEGRO / ROJO / TURQUESA / JEAN) | H3: AUDITORIA - MERCADEO PURINA MARZO 2025 | I3: SI | J3: 45733 | K3: 26407885 | L3: NestleP.4 | M3: =_xlfn.XLOOKUP(PUNTAJE[[#This Row],[CODIGO RUTA]],'DATA INFORME'!G:G,'DATA INFORME'!I:I) -> SI | N3: =IF(PUNTAJE[[#This Row],[MYSTERY EFECTIVO]]="SI",(_xlfn.XLOOKUP(PUNTAJE[[#This Row],[PREGUNTA]],ENCUESTA!G:G,ENCUESTA!E:E)),"N/A") -> PRESENTACIÓN PERSONAL | O3: =IF(PUNTAJE[[#This Row],[MYSTERY EFECTIVO]]="SI",(IF(PUNTAJE[[#This Row],[CANAL]]="TRADICIONAL",_xlfn.XLOOKUP(PUNTAJE[[#This Row],[PREGUNTA]],ENCUESTA!G:G,ENCUESTA!A:A),IF(PUNTAJE[[#This Row],[CANAL]]="ESPECIALIZADO",_xlfn.XLOOKUP(PUNTAJE[[#This Row],[PREGUNTA]],ENCUESTA!G:G,ENCUESTA!B:B),IF(PUNTAJE[[#This Row],[CANAL]]="MODERNO",_xlfn.XLOOKUP(PUNTAJE[[#This Row],[PREGUNTA]],ENCUESTA!G:G,ENCUESTA!C:C))))),0) -> 1 | P3: =_xlfn.XLOOKUP(PUNTAJE[[#This Row],[PREGUNTA]],ENCUESTA!G:G,ENCUESTA!H:H) -> SI | Q3: =IF(PUNTAJE[[#This Row],[RESPUESTA]]=PUNTAJE[[#This Row],[RTA CORRECTA]],PUNTAJE[[#This Row],[TOTAL PUNTAJE]],0) -> 1
A4: NESTLE PURINA | B4: BARRANQUILLA | C4: TRADICIONAL | D4: SUPERETE | E4: 65453 | F4: DISTRIBUCIONES MILENA | G4: CUENTA CON CAMISA DEL UNIFORME Y LOGOS SEGÚN EL CARGO (NEGRA / GRIS / ROJA / TURQUESA) (ES PERMITIDO USAR DEBAJO DE LA CAMISA BUSO MANGA LARGA NEGRO) | H4: AUDITORIA - MERCADEO PURINA MARZO 2025 | I4: SI | J4: 45733 | K4: 26407885 | L4: NestleP.4 | M4: =_xlfn.XLOOKUP(PUNTAJE[[#This Row],[CODIGO RUTA]],'DATA INFORME'!G:G,'DATA INFORME'!I:I) -> SI | N4: =IF(PUNTAJE[[#This Row],[MYSTERY EFECTIVO]]="SI",(_xlfn.XLOOKUP(PUNTAJE[[#This Row],[PREGUNTA]],ENCUESTA!G:G,ENCUESTA!E:E)),"N/A") -> PRESENTACIÓN PERSONAL | O4: =IF(PUNTAJE[[#This Row],[MYSTERY EFECTIVO]]="SI",(IF(PUNTAJE[[#This Row],[CANAL]]="TRADICIONAL",_xlfn.XLOOKUP(PUNTAJE[[#This Row],[PREGUNTA]],ENCUESTA!G:G,ENCUESTA!A:A),IF(PUNTAJE[[#This Row],[CANAL]]="ESPECIALIZADO",_xlfn.XLOOKUP(PUNTAJE[[#This Row],[PREGUNTA]],ENCUESTA!G:G,ENCUESTA!B:B),IF(PUNTAJE[[#This Row],[CANAL]]="MODERNO",_xlfn.XLOOKUP(PUNTAJE[[#This Row],[PREGUNTA]],ENCUESTA!G:G,ENCUESTA!C:C))))),0) -> 1 | P4: =_xlfn.XLOOKUP(PUNTAJE[[#This Row],[PREGUNTA]],ENCUESTA!G:G,ENCUESTA!H:H) -> SI | Q4: =IF(PUNTAJE[[#This Row],[RESPUESTA]]=PUNTAJE[[#This Row],[RTA CORRECTA]],PUNTAJE[[#This Row],[TOTAL PUNTAJE]],0) -> 1
A5: NESTLE PURINA | B5: BARRANQUILLA | C5: TRADICIONAL | D5: SUPERETE | E5: 65453 | F5: DISTRIBUCIONES MILENA | G5: CUENTA CON CALZADO DE ACUERDO AL UNIFORME | H5: AUDITORIA - MERCADEO PURINA MARZO 2025 | I5: SI | J5: 45733 | K5: 26407885 | L5: NestleP.4 | M5: =_xlfn.XLOOKUP(PUNTAJE[[#This Row],[CODIGO RUTA]],'DATA INFORME'!G:G,'DATA INFORME'!I:I) -> SI | N5: =IF(PUNTAJE[[#This Row],[MYSTERY EFECTIVO]]="SI",(_xlfn.XLOOKUP(PUNTAJE[[#This Row],[PREGUNTA]],ENCUESTA!G:G,ENCUESTA!E:E)),"N/A") -> PRESENTACIÓN PERSONAL | O5: =IF(PUNTAJE[[#This Row],[MYSTERY EFECTIVO]]="SI",(IF(PUNTAJE[[#This Row],[CANAL]]="TRADICIONAL",_xlfn.XLOOKUP(PUNTAJE[[#This Row],[PREGUNTA]],ENCUESTA!G:G,ENCUESTA!A:A),IF(PUNTAJE[[#This Row],[CANAL]]="ESPECIALIZADO",_xlfn.XLOOKUP(PUNTAJE[[#This Row],[PREGUNTA]],ENCUESTA!G:G,ENCUESTA!B:B),IF(PUNTAJE[[#This Row],[CANAL]]="MODERNO",_xlfn.XLOOKUP(PUNTAJE[[#This Row],[PREGUNTA]],ENCUESTA!G:G,ENCUESTA!C:C))))),0) -> 1 | P5: =_xlfn.XLOOKUP(PUNTAJE[[#This Row],[PREGUNTA]],ENCUESTA!G:G,ENCUESTA!H:H) -> SI | Q5: =IF(PUNTAJE[[#This Row],[RESPUESTA]]=PUNTAJE[[#This Row],[RTA CORRECTA]],PUNTAJE[[#This Row],[TOTAL PUNTAJE]],0) -> 1
A6: NESTLE PURINA | B6: BARRANQUILLA | C6: TRADICIONAL | D6: SUPERETE | E6: 65453 | F6: DISTRIBUCIONES MILENA | G6: POSEE ALGUNA PRENDA ENCIMA DEL UNIFORME NO AUTORIZADA POR LA MARCA (SOLO PERMITIDO CHALECO DE SODIMAC Y EASY) | H6: AUDITORIA - MERCADEO PURINA MARZO 2025 | I6: NO | J6: 45733 | K6: 26407885 | L6: NestleP.4 | M6: =_xlfn.XLOOKUP(PUNTAJE[[#This Row],[CODIGO RUTA]],'DATA INFORME'!G:G,'DATA INFORME'!I:I) -> SI | N6: =IF(PUNTAJE[[#This Row],[MYSTERY EFECTIVO]]="SI",(_xlfn.XLOOKUP(PUNTAJE[[#This Row],[PREGUNTA]],ENCUESTA!G:G,ENCUESTA!E:E)),"N/A") -> PRESENTACIÓN PERSONAL | O6: =IF(PUNTAJE[[#This Row],[MYSTERY EFECTIVO]]="SI",(IF(PUNTAJE[[#This Row],[CANAL]]="TRADICIONAL",_xlfn.XLOOKUP(PUNTAJE[[#This Row],[PREGUNTA]],ENCUESTA!G:G,ENCUESTA!A:A),IF(PUNTAJE[[#This Row],[CANAL]]="ESPECIALIZADO",_xlfn.XLOOKUP(PUNTAJE[[#This Row],[PREGUNTA]],ENCUESTA!G:G,ENCUESTA!B:B),IF(PUNTAJE[[#This Row],[CANAL]]="MODERNO",_xlfn.XLOOKUP(PUNTAJE[[#This Row],[PREGUNTA]],ENCUESTA!G:G,ENCUESTA!C:C))))),0) -> 1 | P6: =_xlfn.XLOOKUP(PUNTAJE[[#This Row],[PREGUNTA]],ENCUESTA!G:G,ENCUESTA!H:H) -> NO | Q6: =IF(PUNTAJE[[#This Row],[RESPUESTA]]=PUNTAJE[[#This Row],[RTA CORRECTA]],PUNTAJE[[#This Row],[TOTAL PUNTAJE]],0) -> 1
A7: NESTLE PURINA | B7: BARRANQUILLA | C7: TRADICIONAL | D7: SUPERETE | E7: 65453 | F7: DISTRIBUCIONES MILENA | G7: EL UNIFORME Y ZAPATOS SE ENCUENTRAN LIMPIOS Y EN BUEN ESTADO | H7: AUDITORIA - MERCADEO PURINA MARZO 2025 | I7: SI | J7: 45733 | K7: 26407885 | L7: NestleP.4 | M7: =_xlfn.XLOOKUP(PUNTAJE[[#This Row],[CODIGO RUTA]],'DATA INFORME'!G:G,'DATA INFORME'!I:I) -> SI | N7: =IF(PUNTAJE[[#This Row],[MYSTERY EFECTIVO]]="SI",(_xlfn.XLOOKUP(PUNTAJE[[#This Row],[PREGUNTA]],ENCUESTA!G:G,ENCUESTA!E:E)),"N/A") -> PRESENTACIÓN PERSONAL | O7: =IF(PUNTAJE[[#This Row],[MYSTERY EFECTIVO]]="SI",(IF(PUNTAJE[[#This Row],[CANAL]]="TRADICIONAL",_xlfn.XLOOKUP(PUNTAJE[[#This Row],[PREGUNTA]],ENCUESTA!G:G,ENCUESTA!A:A),IF(PUNTAJE[[#This Row],[CANAL]]="ESPECIALIZADO",_xlfn.XLOOKUP(PUNTAJE[[#This Row],[PREGUNTA]],ENCUESTA!G:G,ENCUESTA!B:B),IF(PUNTAJE[[#This Row],[CANAL]]="MODERNO",_xlfn.XLOOKUP(PUNTAJE[[#This Row],[PREGUNTA]],ENCUESTA!G:G,ENCUESTA!C:C))))),0) -> 1 | P7: =_xlfn.XLOOKUP(PUNTAJE[[#This Row],[PREGUNTA]],ENCUESTA!G:G,ENCUESTA!H:H) -> SI | Q7: =IF(PUNTAJE[[#This Row],[RESPUESTA]]=PUNTAJE[[#This Row],[RTA CORRECTA]],PUNTAJE[[#This Row],[TOTAL PUNTAJE]],0) -> 1
A8: NESTLE PURINA | B8: BARRANQUILLA | C8: TRADICIONAL | D8: SUPERETE | E8: 65453 | F8: DISTRIBUCIONES MILENA | G8: SU CABELLO LUCE LIMPIO, ORGANIZADO O RECOGIDO | H8: AUDITORIA - MERCADEO PURINA MARZO 2025 | I8: SI | J8: 45733 | K8: 26407885 | L8: NestleP.4 | M8: =_xlfn.XLOOKUP(PUNTAJE[[#This Row],[CODIGO RUTA]],'DATA INFORME'!G:G,'DATA INFORME'!I:I) -> SI | N8: =IF(PUNTAJE[[#This Row],[MYSTERY EFECTIVO]]="SI",(_xlfn.XLOOKUP(PUNTAJE[[#This Row],[PREGUNTA]],ENCUESTA!G:G,ENCUESTA!E:E)),"N/A") -> PRESENTACIÓN PERSONAL | O8: =IF(PUNTAJE[[#This Row],[MYSTERY EFECTIVO]]="SI",(IF(PUNTAJE[[#This Row],[CANAL]]="TRADICIONAL",_xlfn.XLOOKUP(PUNTAJE[[#This Row],[PREGUNTA]],ENCUESTA!G:G,ENCUESTA!A:A),IF(PUNTAJE[[#This Row],[CANAL]]="ESPECIALIZADO",_xlfn.XLOOKUP(PUNTAJE[[#This Row],[PREGUNTA]],ENCUESTA!G:G,ENCUESTA!B:B),IF(PUNTAJE[[#This Row],[CANAL]]="MODERNO",_xlfn.XLOOKUP(PUNTAJE[[#This Row],[PREGUNTA]],ENCUESTA!G:G,ENCUESTA!C:C))))),0) -> 1 | P8: =_xlfn.XLOOKUP(PUNTAJE[[#This Row],[PREGUNTA]],ENCUESTA!G:G,ENCUESTA!H:H) -> SI | Q8: =IF(PUNTAJE[[#This Row],[RESPUESTA]]=PUNTAJE[[#This Row],[RTA CORRECTA]],PUNTAJE[[#This Row],[TOTAL PUNTAJE]],0) -> 1
A9: NESTLE PURINA | B9: BARRANQUILLA | C9: TRADICIONAL | D9: SUPERETE | E9: 65453 | F9: DISTRIBUCIONES MILENA | G9: PRESENTA EXCESO DE MAQUILLAJE QUE NO CUMPLE CON EL CODIGO DE VESTIMENTA | H9: AUDITORIA - MERCADEO PURINA MARZO 2025 | I9: NO | J9: 45733 | K9: 26407885 | L9: NestleP.4 | M9: =_xlfn.XLOOKUP(PUNTAJE[[#This Row],[CODIGO RUTA]],'DATA INFORME'!G:G,'DATA INFORME'!I:I) -> SI | N9: =IF(PUNTAJE[[#This Row],[MYSTERY EFECTIVO]]="SI",(_xlfn.XLOOKUP(PUNTAJE[[#This Row],[PREGUNTA]],ENCUESTA!G:G,ENCUESTA!E:E)),"N/A") -> PRESENTACIÓN PERSONAL | O9: =IF(PUNTAJE[[#This Row],[MYSTERY EFECTIVO]]="SI",(IF(PUNTAJE[[#This Row],[CANAL]]="TRADICIONAL",_xlfn.XLOOKUP(PUNTAJE[[#This Row],[PREGUNTA]],ENCUESTA!G:G,ENCUESTA!A:A),IF(PUNTAJE[[#This Row],[CANAL]]="ESPECIALIZADO",_xlfn.XLOOKUP(PUNTAJE[[#This Row],[PREGUNTA]],ENCUESTA!G:G,ENCUESTA!B:B),IF(PUNTAJE[[#This Row],[CANAL]]="MODERNO",_xlfn.XLOOKUP(PUNTAJE[[#This Row],[PREGUNTA]],ENCUESTA!G:G,ENCUESTA!C:C))))),0) -> 1 | P9: =_xlfn.XLOOKUP(PUNTAJE[[#This Row],[PREGUNTA]],ENCUESTA!G:G,ENCUESTA!H:H) -> NO | Q9: =IF(PUNTAJE[[#This Row],[RESPUESTA]]=PUNTAJE[[#This Row],[RTA CORRECTA]],PUNTAJE[[#This Row],[TOTAL PUNTAJE]],0) -> 1
A10: NESTLE PURINA | B10: BARRANQUILLA | C10: TRADICIONAL | D10: SUPERETE | E10: 65453 | F10: DISTRIBUCIONES MILENA | G10: TIENE TATUAJES O PIERCINGS VISIBLES QUE NO CUMPLE CON EL CODIGO DE VESTIMENTA | H10: AUDITORIA - MERCADEO PURINA MARZO 2025 | I10: NO | J10: 45733 | K10: 26407885 | L10: NestleP.4 | M10: =_xlfn.XLOOKUP(PUNTAJE[[#This Row],[CODIGO RUTA]],'DATA INFORME'!G:G,'DATA INFORME'!I:I) -> SI | N10: =IF(PUNTAJE[[#This Row],[MYSTERY EFECTIVO]]="SI",(_xlfn.XLOOKUP(PUNTAJE[[#This Row],[PREGUNTA]],ENCUESTA!G:G,ENCUESTA!E:E)),"N/A") -> PRESENTACIÓN PERSONAL | O10: =IF(PUNTAJE[[#This Row],[MYSTERY EFECTIVO]]="SI",(IF(PUNTAJE[[#This Row],[CANAL]]="TRADICIONAL",_xlfn.XLOOKUP(PUNTAJE[[#This Row],[PREGUNTA]],ENCUESTA!G:G,ENCUESTA!A:A),IF(PUNTAJE[[#This Row],[CANAL]]="ESPECIALIZADO",_xlfn.XLOOKUP(PUNTAJE[[#This Row],[PREGUNTA]],ENCUESTA!G:G,ENCUESTA!B:B),IF(PUNTAJE[[#This Row],[CANAL]]="MODERNO",_xlfn.XLOOKUP(PUNTAJE[[#This Row],[PREGUNTA]],ENCUESTA!G:G,ENCUESTA!C:C))))),0) -> 1 | P10: =_xlfn.XLOOKUP(PUNTAJE[[#This Row],[PREGUNTA]],ENCUESTA!G:G,ENCUESTA!H:H) -> NO | Q10: =IF(PUNTAJE[[#This Row],[RESPUESTA]]=PUNTAJE[[#This Row],[RTA CORRECTA]],PUNTAJE[[#This Row],[TOTAL PUNTAJE]],0) -> 1
A11: NESTLE PURINA | B11: BARRANQUILLA | C11: TRADICIONAL | D11: SUPERETE | E11: 65453 | F11: DISTRIBUCIONES MILENA | G11: TIENE UÑAS LLAMATIVAS Y/O LARGAS QUE NO CUMPLE CON EL CODIGO DE VESTIMENTA | H11: AUDITORIA - MERCADEO PURINA MARZO 2025 | I11: NO | J11: 45733 | K11: 26407885 | L11: NestleP.4 | M11: =_xlfn.XLOOKUP(PUNTAJE[[#This Row],[CODIGO RUTA]],'DATA INFORME'!G:G,'DATA INFORME'!I:I) -> SI | N11: =IF(PUNTAJE[[#This Row],[MYSTERY EFECTIVO]]="SI",(_xlfn.XLOOKUP(PUNTAJE[[#This Row],[PREGUNTA]],ENCUESTA!G:G,ENCUESTA!E:E)),"N/A") -> PRESENTACIÓN PERSONAL | O11: =IF(PUNTAJE[[#This Row],[MYSTERY EFECTIVO]]="SI",(IF(PUNTAJE[[#This Row],[CANAL]]="TRADICIONAL",_xlfn.XLOOKUP(PUNTAJE[[#This Row],[PREGUNTA]],ENCUESTA!G:G,ENCUESTA!A:A),IF(PUNTAJE[[#This Row],[CANAL]]="ESPECIALIZADO",_xlfn.XLOOKUP(PUNTAJE[[#This Row],[PREGUNTA]],ENCUESTA!G:G,ENCUESTA!B:B),IF(PUNTAJE[[#This Row],[CANAL]]="MODERNO",_xlfn.XLOOKUP(PUNTAJE[[#This Row],[PREGUNTA]],ENCUESTA!G:G,ENCUESTA!C:C))))),0) -> 1 | P11: =_xlfn.XLOOKUP(PUNTAJE[[#This Row],[PREGUNTA]],ENCUESTA!G:G,ENCUESTA!H:H) -> NO | Q11: =IF(PUNTAJE[[#This Row],[RESPUESTA]]=PUNTAJE[[#This Row],[RTA CORRECTA]],PUNTAJE[[#This Row],[TOTAL PUNTAJE]],0) -> 1
A12: NESTLE PURINA | B12: BARRANQUILLA | C12: TRADICIONAL | D12: SUPERETE | E12: 65453 | F12: DISTRIBUCIONES MILENA | G12: USA ACCESORIOS QUE NO CUMPLE CON EL CODIGO DE VESTIMENTA | H12: AUDITORIA - MERCADEO PURINA MARZO 2025 | I12: NO | J12: 45733 | K12: 26407885 | L12: NestleP.4 | M12: =_xlfn.XLOOKUP(PUNTAJE[[#This Row],[CODIGO RUTA]],'DATA INFORME'!G:G,'DATA INFORME'!I:I) -> SI | N12: =IF(PUNTAJE[[#This Row],[MYSTERY EFECTIVO]]="SI",(_xlfn.XLOOKUP(PUNTAJE[[#This Row],[PREGUNTA]],ENCUESTA!G:G,ENCUESTA!E:E)),"N/A") -> PRESENTACIÓN PERSONAL | O12: =IF(PUNTAJE[[#This Row],[MYSTERY EFECTIVO]]="SI",(IF(PUNTAJE[[#This Row],[CANAL]]="TRADICIONAL",_xlfn.XLOOKUP(PUNTAJE[[#This Row],[PREGUNTA]],ENCUESTA!G:G,ENCUESTA!A:A),IF(PUNTAJE[[#This Row],[CANAL]]="ESPECIALIZADO",_xlfn.XLOOKUP(PUNTAJE[[#This Row],[PREGUNTA]],ENCUESTA!G:G,ENCUESTA!B:B),IF(PUNTAJE[[#This Row],[CANAL]]="MODERNO",_xlfn.XLOOKUP(PUNTAJE[[#This Row],[PREGUNTA]],ENCUESTA!G:G,ENCUESTA!C:C))))),0) -> 1 | P12: =_xlfn.XLOOKUP(PUNTAJE[[#This Row],[PREGUNTA]],ENCUESTA!G:G,ENCUESTA!H:H) -> NO | Q12: =IF(PUNTAJE[[#This Row],[RESPUESTA]]=PUNTAJE[[#This Row],[RTA CORRECTA]],PUNTAJE[[#This Row],[TOTAL PUNTAJE]],0) -> 1
A13: NESTLE PURINA | B13: BARRANQUILLA | C13: TRADICIONAL | D13: SUPERETE | E13: 65453 | F13: DISTRIBUCIONES MILENA | G13: EL LINEAL SE ENCUENTRA LIMPIO Y ORGANIZADO | H13: AUDITORIA - MERCADEO PURINA MARZO 2025 | I13: SI | J13: 45733 | K13: 26407885 | L13: NestleP.4 | M13: =_xlfn.XLOOKUP(PUNTAJE[[#This Row],[CODIGO RUTA]],'DATA INFORME'!G:G,'DATA INFORME'!I:I) -> SI | N13: =IF(PUNTAJE[[#This Row],[MYSTERY EFECTIVO]]="SI",(_xlfn.XLOOKUP(PUNTAJE[[#This Row],[PREGUNTA]],ENCUESTA!G:G,ENCUESTA!E:E)),"N/A") -> EJECUCION DEL PDV | O13: =IF(PUNTAJE[[#This Row],[MYSTERY EFECTIVO]]="SI",(IF(PUNTAJE[[#This Row],[CANAL]]="TRADICIONAL",_xlfn.XLOOKUP(PUNTAJE[[#This Row],[PREGUNTA]],ENCUESTA!G:G,ENCUESTA!A:A),IF(PUNTAJE[[#This Row],[CANAL]]="ESPECIALIZADO",_xlfn.XLOOKUP(PUNTAJE[[#This Row],[PREGUNTA]],ENCUESTA!G:G,ENCUESTA!B:B),IF(PUNTAJE[[#This Row],[CANAL]]="MODERNO",_xlfn.XLOOKUP(PUNTAJE[[#This Row],[PREGUNTA]],ENCUESTA!G:G,ENCUESTA!C:C))))),0) -> 4.2 | P13: =_xlfn.XLOOKUP(PUNTAJE[[#This Row],[PREGUNTA]],ENCUESTA!G:G,ENCUESTA!H:H) -> SI | Q13: =IF(PUNTAJE[[#This Row],[RESPUESTA]]=PUNTAJE[[#This Row],[RTA CORRECTA]],PUNTAJE[[#This Row],[TOTAL PUNTAJE]],0) -> 4.2
... A67: NESTLE PURINA | B67: BARRANQUILLA | C67: MODERNO | D67: OLIMPICA | E67: 12108 | F67: OLIMPICA STO 053 PORTAL DEL PRADO | G67: DESCRIBA LA NOVEDAD | H67: AUDITORIA - MERCADEO PURINA MARZO 2025 | I67: No se encuentra en pdv | J67: 45731 | K67: 26451570 | L67: NestleP.4 | M67: =_xlfn.XLOOKUP(PUNTAJE[[#This Row],[CODIGO RUTA]],'DATA INFORME'!G:G,'DATA INFORME'!I:I) -> NO | N67: =IF(PUNTAJE[[#This Row],[MYSTERY EFECTIVO]]="SI",(_xlfn.XLOOKUP(PUNTAJE[[#This Row],[PREGUNTA]],ENCUESTA!G:G,ENCUESTA!E:E)),"N/A") -> N/A | O67: =IF(PUNTAJE[[#This Row],[MYSTERY EFECTIVO]]="SI",(IF(PUNTAJE[[#This Row],[CANAL]]="TRADICIONAL",_xlfn.XLOOKUP(PUNTAJE[[#This Row],[PREGUNTA]],ENCUESTA!G:G,ENCUESTA!A:A),IF(PUNTAJE[[#This Row],[CANAL]]="ESPECIALIZADO",_xlfn.XLOOKUP(PUNTAJE[[#This Row],[PREGUNTA]],ENCUESTA!G:G,ENCUESTA!B:B),IF(PUNTAJE[[#This Row],[CANAL]]="MODERNO",_xlfn.XLOOKUP(PUNTAJE[[#This Row],[PREGUNTA]],ENCUESTA!G:G,ENCUESTA!C:C))))),0) -> 0 | P67: =_xlfn.XLOOKUP(PUNTAJE[[#This Row],[PREGUNTA]],ENCUESTA!G:G,ENCUESTA!H:H) -> 0 | Q67: =IF(PUNTAJE[[#This Row],[RESPUESTA]]=PUNTAJE[[#This Row],[RTA CORRECTA]],PUNTAJE[[#This Row],[TOTAL PUNTAJE]],0) -> 0

Sheet Panel
A1: CANAL | B1: CIUDAD | C1: VUM | D1: NOMBRE PDV | E1: Objetivo Mystery | F1: #PDV Objetivos | G1: #PDV Ejecutados | H1: # Visitas | I1: Mystery Ejecutado
A2: MODERNO | B2: BARRANQUILLA | C2: 12108 | D2: OLIMPICA STO 053 PORTAL DEL PRADO | E2: 1 | F2: 1 | G2: =IF((COUNTIFS(Export!I:I,Tabla1[[#This Row],[VUM]]))>0,1,0) -> 1 | H2: =IF((COUNTIFS(Export!I:I,Tabla1[[#This Row],[VUM]]))>0,1,0) -> 1 | I2: =IF((_xlfn.XLOOKUP(Tabla1[[#This Row],[VUM]],'DATA INFORME'!D:D,'DATA INFORME'!I:I))="SI",1,0) -> 0
A3: TRADICIONAL | B3: BARRANQUILLA | C3: 65453 | D3: DISTRIBUCIONES MILENA | E3: 1 | F3: 1 | G3: =IF((COUNTIFS(Export!I:I,Tabla1[[#This Row],[VUM]]))>0,1,0) -> 1 | H3: =IF((COUNTIFS(Export!I:I,Tabla1[[#This Row],[VUM]]))>0,1,0) -> 1 | I3: =IF((_xlfn.XLOOKUP(Tabla1[[#This Row],[VUM]],'DATA INFORME'!D:D,'DATA INFORME'!I:I))="SI",1,0) -> 1
A4: TRADICIONAL | B4: CALI | C4: 66552 | D4: LA CASA DE LOS TENDEROS | E4: 1 | F4: 1 | G4: =IF((COUNTIFS(Export!I:I,Tabla1[[#This Row],[VUM]]))>0,1,0) -> 1 | H4: =IF((COUNTIFS(Export!I:I,Tabla1[[#This Row],[VUM]]))>0,1,0) -> 1 | I4: =IF((_xlfn.XLOOKUP(Tabla1[[#This Row],[VUM]],'DATA INFORME'!D:D,'DATA INFORME'!I:I))="SI",1,0) -> 1
A5: TRADICIONAL | B5: MEDELLIN | C5: 161719 | D5: SUPERMERCADO MAXIFRUVER PREMIUM | E5: 1 | F5: 1 | G5: =IF((COUNTIFS(Export!I:I,Tabla1[[#This Row],[VUM]]))>0,1,0) -> 1 | H5: =IF((COUNTIFS(Export!I:I,Tabla1[[#This Row],[VUM]]))>0,1,0) -> 1 | I5: =IF((_xlfn.XLOOKUP(Tabla1[[#This Row],[VUM]],'DATA INFORME'!D:D,'DATA INFORME'!I:I))="SI",1,0) -> 1
A9: CANAL | B9: CIUDAD | C9: VUM | D9: NOMBRE PDV | E9: Novedad
A10: MODERNO | B10: BARRANQUILLA | C10: 12108 | D10: OLIMPICA STO 053 PORTAL DEL PRADO | E10: CAMBIO DE HORARIO DE 10 AM A 7PM
A11: ESPECIALIZADO | B11: CALI | C11: 424775 | D11: ZOOMARPETS
A12: MODERNO | B12: BOGOTA | C12: 141269 | D12: ZAPATOCA CARVAJAL | E12: No se encontro dentro de los horarios visitados

Sheet DATA INFORME
A1: ACTIVIDAD | B1: CIUDAD | C1: CADENA | D1: CODIGO PDV | E1: NOMBRE COMERCIAL | F1: FECHA VISITA | G1: CODIGO RUTA | H1: USUARIO | I1: ¿CUMPLE HORARIO DE ENTRADA O SALIDA DE LA TIENDA? | J1: CUENTA CON PANTALON DEL UNIFORME SEGÚN EL CARGO (NEGRO / ROJO / TURQUESA / JEAN) | K1: CUENTA CON CAMISA DEL UNIFORME Y LOGOS SEGÚN EL CARGO (NEGRA / GRIS / ROJA / TURQUESA) (ES PERMITIDO USAR DEBAJO DE LA CAMISA BUSO MANGA LARGA NEGRO) | L1: CUENTA CON CALZADO DE ACUERDO AL UNIFORME | M1: POSEE ALGUNA PRENDA ENCIMA DEL UNIFORME NO AUTORIZADA POR LA MARCA (SOLO PERMITIDO CHALECO DE SODIMAC Y EASY) | N1: EL UNIFORME Y ZAPATOS SE ENCUENTRAN LIMPIOS Y EN BUEN ESTADO | O1: SU CABELLO LUCE LIMPIO, ORGANIZADO O RECOGIDO | P1: PRESENTA EXCESO DE MAQUILLAJE QUE NO CUMPLE CON EL CODIGO DE VESTIMENTA | Q1: TIENE TATUAJES O PIERCINGS VISIBLES QUE NO CUMPLE CON EL CODIGO DE VESTIMENTA | R1: TIENE UÑAS LLAMATIVAS Y/O LARGAS QUE NO CUMPLE CON EL CODIGO DE VESTIMENTA | S1: USA ACCESORIOS QUE NO CUMPLE CON EL CODIGO DE VESTIMENTA | T1: EL LINEAL SE ENCUENTRA LIMPIO Y ORGANIZADO | U1: LOS PRODUCTOS TIENEN EL PRECIO Y ESTAN ACORDE O CORRESPONDIENTE A CADA REFERENCIA | V1: LOS PRODUCTOS ESTAN SURTIDOS DE ACUERDO A PEPS O FIFO (REVISAR TANTO PRODUCTO SECO COMO HUMEDO) | W1: CONOCE LOS INFALTABLES DEL PUNTO DE VENTA Y CUENTA CON EL MATERIAL DE APOYO (AYUDAVENTAS INFALTABLES) | X1: CONOCE Y TIENE SURTIDO DE ACUERDO A LA ESTRATEGIA DE EXHIBICIÓN (ETAPAS DE VIDA - SEGMENTACIÓN DE MARCAS) | Y1: CUAL ES LA ESTRATEGIA DE EXHIBICIÓN PARA LAS MARCAS MAINSTRAIN (ALPO Y GATSY) DE PURINA Y PORQUE? | Z1: CONOCE EL % DE PARTICIPACIÓN QUE TIENE EN EL PUNTO DE VENTA E INFORMA CUAL ES ESE % | AA1: QUE CANAL VA A AUDITAR | AB1: T. ESTA IMPLEMENTADA LA NUEVA ESTRATEGIA DE BAJA DE PRECIOS (SI EL MERCADERISTA INFORMA QUE EL PDV NO LO PERMITE IMPLEMENTAR QUEDARIA COMO N/A) | AC1: SE PRESENTA ALGUNA NOVEDAD? | AD1: DESCRIBA LA NOVEDAD
A2: NESTLE PURINA | B2: BARRANQUILLA | C2: OLIMPICA | D2: 12108 | E2: OLIMPICA STO 053 PORTAL DEL PRADO | F2: 45731 | G2: 26451570 | H2: NestleP.4 | I2: NO | AC2: SI | AD2: No se encuentra en pdv
A3: NESTLE PURINA | B3: BARRANQUILLA | C3: SUPERETE | D3: 65453 | E3: DISTRIBUCIONES MILENA | F3: 45733 | G3: 26407885 | H3: NestleP.4 | I3: SI | J3: SI | K3: SI | L3: SI | M3: NO | N3: SI | O3: SI | P3: NO | Q3: NO | R3: NO | S3: NO | T3: SI | U3: SI | V3: SI | W3: SI | X3: SI | Y3: SI | Z3: SI | AA3: CANAL TRADICIONAL | AB3: SI | AC3: NO
A4: NESTLE PURINA | B4: CALI | C4: SUPERETE | D4: 66552 | E4: LA CASA DE LOS TENDEROS | F4: 45737 | G4: 26440178 | H4: NestleP.7 | I4: SI | J4: SI | K4: SI | L4: SI | M4: NO | N4: SI | O4: SI | P4: NO | Q4: NO | R4: NO | S4: NO | T4: SI | U4: SI | V4: SI | W4: SI | X4: SI | Y4: SI | Z4: SI | AA4: CANAL TRADICIONAL | AC4: NO
A5: NESTLE PURINA | B5: MEDELLIN | C5: SUPERETE | D5: 161719 | E5: SUPERMERCADO MAXIFRUVER PREMIUM | F5: 45735 | G5: 26426261 | H5: NestleP.10 | I5: SI | J5: SI | K5: SI | L5: SI | M5: NO | N5: SI | O5: SI | P5: NO | Q5: SI | R5: NO | S5: NO | T5: SI | U5: SI | V5: SI | W5: SI | X5: SI | Y5: SI | Z5: SI | AA5: CANAL TRADICIONAL | AB5: SI | AC5: SI | AD5: El vídeo se me movió un poco y se ve mucho la otra marca, pero a la chica de le hizo mistery y auditoría de purina, se le hizo compra porque su asesoría fue muy buena. Nos manifiesta que tiene muchos agotados, que ya los reporto y por el tema de agotados está perdiendo participación en el PDV de nuestra marca purina.

Sheet Export
A1: ACTIVIDAD | B1: REGIONAL | C1: CIUDAD | D1: CANAL | E1: CADENA | F1: SUBCADENA | G1: ZONA | H1: RV | I1: CODIGO PDV | J1: NOMBRE COMERCIAL | K1: CODIGO EAN | L1: TIPO PUNTO VENTA | M1: CONSECUTIVO ENCUESTA | N1: NOMBRE ENCUESTA | O1: PREGUNTA | P1: RESPUESTA | Q1: CODIGO FOTO | R1: OBSERVACION | S1: FECHA VISITA | T1: FECHA INICIO VISITA | U1: FECHA CREACIÓN RESPUESTA | V1: CODIGO RUTA | W1: CLIENTE | X1: CODIGO EXHIBICION | Y1: NOMBRE EXHIBICION | Z1: NOMBRE USUARIO | AA1: USUARIO | AB1: NOMBRE SUPERVISOR | AC1: USUARIO SUPERVISOR
A2: NESTLE PURINA | B2: COSTA | C2: BARRANQUILLA | D2: TRADICIONAL | E2: SUPERETE | F2: SUPERETES | G2: BARRANQUILLA | I2: 65453 | J2: DISTRIBUCIONES MILENA | K2: 0 | L2: Mercadeo | M2: 1 | N2: AUDITORIA - MERCADEO PURINA MARZO 2025 | O2: ¿CUMPLE HORARIO DE ENTRADA O SALIDA DE LA TIENDA? | P2: SI | S2: 45733 | T2: 17/03/2025 07:12:24 | U2: 17/03/2025 07:54:07 | V2: 26407885 | W2: PRODUCTIVIDAD | Z2: User 4 | AA2: NestleP.4 | AB2: CAMILO MONTAÑO RESTREPO | AC2: camilo.montano
A3: NESTLE PURINA | B3: COSTA | C3: BARRANQUILLA | D3: TRADICIONAL | E3: SUPERETE | F3: SUPERETES | G3: BARRANQUILLA | I3: 65453 | J3: DISTRIBUCIONES MILENA | K3: 0 | L3: Mercadeo | M3: 1 | N3: AUDITORIA - MERCADEO PURINA MARZO 2025 | O3: CUENTA CON PANTALON DEL UNIFORME SEGÚN EL CARGO (NEGRO / ROJO / TURQUESA / JEAN) | P3: SI | S3: 45733 | T3: 17/03/2025 07:12:24 | U3: 17/03/2025 07:54:14 | V3: 26407885 | W3: PRODUCTIVIDAD | Z3: User 4 | AA3: NestleP.4 | AB3: CAMILO MONTAÑO RESTREPO | AC3: camilo.montano
A4: NESTLE PURINA | B4: COSTA | C4: BARRANQUILLA | D4: TRADICIONAL | E4: SUPERETE | F4: SUPERETES | G4: BARRANQUILLA | I4: 65453 | J4: DISTRIBUCIONES MILENA | K4: 0 | L4: Mercadeo | M4: 1 | N4: AUDITORIA - MERCADEO PURINA MARZO 2025 | O4: CUENTA CON CAMISA DEL UNIFORME Y LOGOS SEGÚN EL CARGO (NEGRA / GRIS / ROJA / TURQUESA) (ES PERMITIDO USAR DEBAJO DE LA CAMISA BUSO MANGA LARGA NEGRO) | P4: SI | S4: 45733 | T4: 17/03/2025 07:12:24 | U4: 17/03/2025 07:54:17 | V4: 26407885 | W4: PRODUCTIVIDAD | Z4: User 4 | AA4: NestleP.4 | AB4: CAMILO MONTAÑO RESTREPO | AC4: camilo.montano
A5: NESTLE PURINA | B5: COSTA | C5: BARRANQUILLA | D5: TRADICIONAL | E5: SUPERETE | F5: SUPERETES | G5: BARRANQUILLA | I5: 65453 | J5: DISTRIBUCIONES MILENA | K5: 0 | L5: Mercadeo | M5: 1 | N5: AUDITORIA - MERCADEO PURINA MARZO 2025 | O5: CUENTA CON CALZADO DE ACUERDO AL UNIFORME | P5: SI | S5: 45733 | T5: 17/03/2025 07:12:24 | U5: 17/03/2025 07:54:21 | V5: 26407885 | W5: PRODUCTIVIDAD | Z5: User 4 | AA5: NestleP.4 | AB5: CAMILO MONTAÑO RESTREPO | AC5: camilo.montano
A6: NESTLE PURINA | B6: COSTA | C6: BARRANQUILLA | D6: TRADICIONAL | E6: SUPERETE | F6: SUPERETES | G6: BARRANQUILLA | I6: 65453 | J6: DISTRIBUCIONES MILENA | K6: 0 | L6: Mercadeo | M6: 1 | N6: AUDITORIA - MERCADEO PURINA MARZO 2025 | O6: POSEE ALGUNA PRENDA ENCIMA DEL UNIFORME NO AUTORIZADA POR LA MARCA (SOLO PERMITIDO CHALECO DE SODIMAC Y EASY) | P6: NO | S6: 45733 | T6: 17/03/2025 07:12:24 | U6: 17/03/2025 07:54:27 | V6: 26407885 | W6: PRODUCTIVIDAD | Z6: User 4 | AA6: NestleP.4 | AB6: CAMILO MONTAÑO RESTREPO | AC6: camilo.montano
A7: NESTLE PURINA | B7: COSTA | C7: BARRANQUILLA | D7: TRADICIONAL | E7: SUPERETE | F7: SUPERETES | G7: BARRANQUILLA | I7: 65453 | J7: DISTRIBUCIONES MILENA | K7: 0 | L7: Mercadeo | M7: 1 | N7: AUDITORIA - MERCADEO PURINA MARZO 2025 | O7: EL UNIFORME Y ZAPATOS SE ENCUENTRAN LIMPIOS Y EN BUEN ESTADO | P7: SI | S7: 45733 | T7: 17/03/2025 07:12:24 | U7: 17/03/2025 07:54:32 | V7: 26407885 | W7: PRODUCTIVIDAD | Z7: User 4 | AA7: NestleP.4 | AB7: CAMILO MONTAÑO RESTREPO | AC7: camilo.montano
A8: NESTLE PURINA | B8: COSTA | C8: BARRANQUILLA | D8: TRADICIONAL | E8: SUPERETE | F8: SUPERETES | G8: BARRANQUILLA | I8: 65453 | J8: DISTRIBUCIONES MILENA | K8: 0 | L8: Mercadeo | M8: 1 | N8: AUDITORIA - MERCADEO PURINA MARZO 2025 | O8: SU CABELLO LUCE LIMPIO, ORGANIZADO O RECOGIDO | P8: SI | S8: 45733 | T8: 17/03/2025 07:12:24 | U8: 17/03/2025 07:54:35 | V8: 26407885 | W8: PRODUCTIVIDAD | Z8: User 4 | AA8: NestleP.4 | AB8: CAMILO MONTAÑO RESTREPO | AC8: camilo.montano
A9: NESTLE PURINA | B9: COSTA | C9: BARRANQUILLA | D9: TRADICIONAL | E9: SUPERETE | F9: SUPERETES | G9: BARRANQUILLA | I9: 65453 | J9: DISTRIBUCIONES MILENA | K9: 0 | L9: Mercadeo | M9: 1 | N9: AUDITORIA - MERCADEO PURINA MARZO 2025 | O9: PRESENTA EXCESO DE MAQUILLAJE QUE NO CUMPLE CON EL CODIGO DE VESTIMENTA | P9: NO | S9: 45733 | T9: 17/03/2025 07:12:24 | U9: 17/03/2025 07:54:38 | V9: 26407885 | W9: PRODUCTIVIDAD | Z9: User 4 | AA9: NestleP.4 | AB9: CAMILO MONTAÑO RESTREPO | AC9: camilo.montano
A10: NESTLE PURINA | B10: COSTA | C10: BARRANQUILLA | D10: TRADICIONAL | E10: SUPERETE | F10: SUPERETES | G10: BARRANQUILLA | I10: 65453 | J10: DISTRIBUCIONES MILENA | K10: 0 | L10: Mercadeo | M10: 1 | N10: AUDITORIA - MERCADEO PURINA MARZO 2025 | O10: TIENE TATUAJES O PIERCINGS VISIBLES QUE NO CUMPLE CON EL CODIGO DE VESTIMENTA | P10: NO | S10: 45733 | T10: 17/03/2025 07:12:24 | U10: 17/03/2025 07:54:45 | V10: 26407885 | W10: PRODUCTIVIDAD | Z10: User 4 | AA10: NestleP.4 | AB10: CAMILO MONTAÑO RESTREPO | AC10: camilo.montano
A11: NESTLE PURINA | B11: COSTA | C11: BARRANQUILLA | D11: TRADICIONAL | E11: SUPERETE | F11: SUPERETES | G11: BARRANQUILLA | I11: 65453 | J11: DISTRIBUCIONES MILENA | K11: 0 | L11: Mercadeo | M11: 1 | N11: AUDITORIA - MERCADEO PURINA MARZO 2025 | O11: TIENE UÑAS LLAMATIVAS Y/O LARGAS QUE NO CUMPLE CON EL CODIGO DE VESTIMENTA | P11: NO | S11: 45733 | T11: 17/03/2025 07:12:24 | U11: 17/03/2025 07:54:51 | V11: 26407885 | W11: PRODUCTIVIDAD | Z11: User 4 | AA11: NestleP.4 | AB11: CAMILO MONTAÑO RESTREPO | AC11: camilo.montano
A12: NESTLE PURINA | B12: COSTA | C12: BARRANQUILLA | D12: TRADICIONAL | E12: SUPERETE | F12: SUPERETES | G12: BARRANQUILLA | I12: 65453 | J12: DISTRIBUCIONES MILENA | K12: 0 | L12: Mercadeo | M12: 1 | N12: AUDITORIA - MERCADEO PURINA MARZO 2025 | O12: USA ACCESORIOS QUE NO CUMPLE CON EL CODIGO DE VESTIMENTA | P12: NO | S12: 45733 | T12: 17/03/2025 07:12:24 | U12: 17/03/2025 07:54:57 | V12: 26407885 | W12: PRODUCTIVIDAD | Z12: User 4 | AA12: NestleP.4 | AB12: CAMILO MONTAÑO RESTREPO | AC12: camilo.montano
A13: NESTLE PURINA | B13: COSTA | C13: BARRANQUILLA | D13: TRADICIONAL | E13: SUPERETE | F13: SUPERETES | G13: BARRANQUILLA | I13: 65453 | J13: DISTRIBUCIONES MILENA | K13: 0 | L13: Mercadeo | M13: 1 | N13: AUDITORIA - MERCADEO PURINA MARZO 2025 | O13: EL LINEAL SE ENCUENTRA LIMPIO Y ORGANIZADO | P13: SI | S13: 45733 | T13: 17/03/2025 07:12:24 | U13: 17/03/2025 07:55:06 | V13: 26407885 | W13: PRODUCTIVIDAD | Z13: User 4 | AA13: NestleP.4 | AB13: CAMILO MONTAÑO RESTREPO | AC13: camilo.montano
... A19: NESTLE PURINA | B19: COSTA | C19: BARRANQUILLA | D19: TRADICIONAL | E19: SUPERETE | F19: SUPERETES | G19: BARRANQUILLA | I19: 65453 | J19: DISTRIBUCIONES MILENA | K19: 0 | L19: Mercadeo | M19: 1 | N19: AUDITORIA - MERCADEO PURINA MARZO 2025 | O19: CONOCE EL % DE PARTICIPACIÓN QUE TIENE EN EL PUNTO DE VENTA E INFORMA CUAL ES ESE % | P19: SI | S19: 45733 | T19: 17/03/2025 07:12:24 | U19: 17/03/2025 07:55:49 | V19: 26407885 | W19: PRODUCTIVIDAD | Z19: User 4 | AA19: NestleP.4 | AB19: CAMILO MONTAÑO RESTREPO | AC19: camilo.montano
A20: NESTLE PURINA | B20: COSTA | C20: BARRANQUILLA | D20: TRADICIONAL | E20: SUPERETE | F20: SUPERETES | G20: BARRANQUILLA | I20: 65453 | J20: DISTRIBUCIONES MILENA | K20: 0 | L20: Mercadeo | M20: 1 | N20: AUDITORIA - MERCADEO PURINA MARZO 2025 | O20: QUE CANAL VA A AUDITAR | P20: =_xlfn.XLOOKUP((Tabla2[[#This Row],[CODIGO RUTA]]&Tabla2[[#This Row],[PREGUNTA]]),[1]PURINA!$J:$J,[1]PURINA!$I:$I) -> CANAL TRADICIONAL | S20: 45733 | T20: 17/03/2025 07:12:24 | U20: 17/03/2025 07:55:55 | V20: 26407885 | W20: PRODUCTIVIDAD | Z20: User 4 | AA20: NestleP.4 | AB20: CAMILO MONTAÑO RESTREPO | AC20: camilo.montano
A21: NESTLE PURINA | B21: COSTA | C21: BARRANQUILLA | D21: TRADICIONAL | E21: SUPERETE | F21: SUPERETES | G21: BARRANQUILLA | I21: 65453 | J21: DISTRIBUCIONES MILENA | K21: 0 | L21: Mercadeo | M21: 1 | N21: AUDITORIA - MERCADEO PURINA MARZO 2025 | O21: T. ESTA IMPLEMENTADA LA NUEVA ESTRATEGIA DE BAJA DE PRECIOS (SI EL MERCADERISTA INFORMA QUE EL PDV NO LO PERMITE IMPLEMENTAR QUEDARIA COMO N/A) | P21: SI | S21: 45733 | T21: 17/03/2025 07:12:24 | U21: 17/03/2025 07:56:01 | V21: 26407885 | W21: PRODUCTIVIDAD | Z21: User 4 | AA21: NestleP.4 | AB21: CAMILO MONTAÑO RESTREPO | AC21: camilo.montano
A22: NESTLE PURINA | B22: COSTA | C22: BARRANQUILLA | D22: TRADICIONAL | E22: SUPERETE | F22: SUPERETES | G22: BARRANQUILLA | I22: 65453 | J22: DISTRIBUCIONES MILENA | K22: 0 | L22: Mercadeo | M22: 1 | N22: AUDITORIA - MERCADEO PURINA MARZO 2025 | O22: SE PRESENTA ALGUNA NOVEDAD? | P22: NO | S22: 45733 | T22: 17/03/2025 07:12:24 | U22: 17/03/2025 07:56:04 | V22: 26407885 | W22: PRODUCTIVIDAD | Z22: User 4 | AA22: NestleP.4 | AB22: CAMILO MONTAÑO RESTREPO | AC22: camilo.montano
A23: NESTLE PURINA | B23: ANTIOQUIA | C23: MEDELLIN | D23: TRADICIONAL | E23: SUPERETE | F23: SUPERETES | G23: MEDELLIN | I23: 161719 | J23: SUPERMERCADO MAXIFRUVER PREMIUM | K23: 0 | L23: Mercadeo | M23: 1 | N23: AUDITORIA - MERCADEO PURINA MARZO 2025 | O23: ¿CUMPLE HORARIO DE ENTRADA O SALIDA DE LA TIENDA? | P23: SI | S23: 45735 | T23: 19/03/2025 09:28:46 | U23: 19/03/2025 12:51:49 | V23: 26426261 | W23: PRODUCTIVIDAD | Z23: User 10 | AA23: NestleP.10 | AB23: CAMILO MONTAÑO RESTREPO | AC23: camilo.montano
A24: NESTLE PURINA | B24: ANTIOQUIA | C24: MEDELLIN | D24: TRADICIONAL | E24: SUPERETE | F24: SUPERETES | G24: MEDELLIN | I24: 161719 | J24: SUPERMERCADO MAXIFRUVER PREMIUM | K24: 0 | L24: Mercadeo | M24: 1 | N24: AUDITORIA - MERCADEO PURINA MARZO 2025 | O24: CUENTA CON PANTALON DEL UNIFORME SEGÚN EL CARGO (NEGRO / ROJO / TURQUESA / JEAN) | P24: SI | S24: 45735 | T24: 19/03/2025 09:28:46 | U24: 19/03/2025 12:51:49 | V24: 26426261 | W24: PRODUCTIVIDAD | Z24: User 10 | AA24: NestleP.10 | AB24: CAMILO MONTAÑO RESTREPO | AC24: camilo.montano
A25: NESTLE PURINA | B25: ANTIOQUIA | C25: MEDELLIN | D25: TRADICIONAL | E25: SUPERETE | F25: SUPERETES | G25: MEDELLIN | I25: 161719 | J25: SUPERMERCADO MAXIFRUVER PREMIUM | K25: 0 | L25: Mercadeo | M25: 1 | N25: AUDITORIA - MERCADEO PURINA MARZO 2025 | O25: CUENTA CON CAMISA DEL UNIFORME Y LOGOS SEGÚN EL CARGO (NEGRA / GRIS / ROJA / TURQUESA) (ES PERMITIDO USAR DEBAJO DE LA CAMISA BUSO MANGA LARGA NEGRO) | P25: SI | S25: 45735 | T25: 19/03/2025 09:28:46 | U25: 19/03/2025 12:51:49 | V25: 26426261 | W25: PRODUCTIVIDAD | Z25: User 10 | AA25: NestleP.10 | AB25: CAMILO MONTAÑO RESTREPO | AC25: camilo.montano
A26: NESTLE PURINA | B26: ANTIOQUIA | C26: MEDELLIN | D26: TRADICIONAL | E26: SUPERETE | F26: SUPERETES | G26: MEDELLIN | I26: 161719 | J26: SUPERMERCADO MAXIFRUVER PREMIUM | K26: 0 | L26: Mercadeo | M26: 1 | N26: AUDITORIA - MERCADEO PURINA MARZO 2025 | O26: CUENTA CON CALZADO DE ACUERDO AL UNIFORME | P26: SI | S26: 45735 | T26: 19/03/2025 09:28:46 | U26: 19/03/2025 12:51:49 | V26: 26426261 | W26: PRODUCTIVIDAD | Z26: User 10 | AA26: NestleP.10 | AB26: CAMILO MONTAÑO RESTREPO | AC26: camilo.montano
A27: NESTLE PURINA | B27: ANTIOQUIA | C27: MEDELLIN | D27: TRADICIONAL | E27: SUPERETE | F27: SUPERETES | G27: MEDELLIN | I27: 161719 | J27: SUPERMERCADO MAXIFRUVER PREMIUM | K27: 0 | L27: Mercadeo | M27: 1 | N27: AUDITORIA - MERCADEO PURINA MARZO 2025 | O27: POSEE ALGUNA PRENDA ENCIMA DEL UNIFORME NO AUTORIZADA POR LA MARCA (SOLO PERMITIDO CHALECO DE SODIMAC Y EASY) | P27: NO | S27: 45735 | T27: 19/03/2025 09:28:46 | U27: 19/03/2025 12:51:49 | V27: 26426261 | W27: PRODUCTIVIDAD | Z27: User 10 | AA27: NestleP.10 | AB27: CAMILO MONTAÑO RESTREPO | AC27: camilo.montano
A28: NESTLE PURINA | B28: ANTIOQUIA | C28: MEDELLIN | D28: TRADICIONAL | E28: SUPERETE | F28: SUPERETES | G28: MEDELLIN | I28: 161719 | J28: SUPERMERCADO MAXIFRUVER PREMIUM | K28: 0 | L28: Mercadeo | M28: 1 | N28: AUDITORIA - MERCADEO PURINA MARZO 2025 | O28: EL UNIFORME Y ZAPATOS SE ENCUENTRAN LIMPIOS Y EN BUEN ESTADO | P28: SI | S28: 45735 | T28: 19/03/2025 09:28:46 | U28: 19/03/2025 12:51:49 | V28: 26426261 | W28: PRODUCTIVIDAD | Z28: User 10 | AA28: NestleP.10 | AB28: CAMILO MONTAÑO RESTREPO | AC28: camilo.montano
A29: NESTLE PURINA | B29: ANTIOQUIA | C29: MEDELLIN | D29: TRADICIONAL | E29: SUPERETE | F29: SUPERETES | G29: MEDELLIN | I29: 161719 | J29: SUPERMERCADO MAXIFRUVER PREMIUM | K29: 0 | L29: Mercadeo | M29: 1 | N29: AUDITORIA - MERCADEO PURINA MARZO 2025 | O29: SU CABELLO LUCE LIMPIO, ORGANIZADO O RECOGIDO | P29: SI | S29: 45735 | T29: 19/03/2025 09:28:46 | U29: 19/03/2025 12:51:49 | V29: 26426261 | W29: PRODUCTIVIDAD | Z29: User 10 | AA29: NestleP.10 | AB29: CAMILO MONTAÑO RESTREPO | AC29: camilo.montano
A30: NESTLE PURINA | B30: ANTIOQUIA | C30: MEDELLIN | D30: TRADICIONAL | E30: SUPERETE | F30: SUPERETES | G30: MEDELLIN | I30: 161719 | J30: SUPERMERCADO MAXIFRUVER PREMIUM | K30: 0 | L30: Mercadeo | M30: 1 | N30: AUDITORIA - MERCADEO PURINA MARZO 2025 | O30: PRESENTA EXCESO DE MAQUILLAJE QUE NO CUMPLE CON EL CODIGO DE VESTIMENTA | P30: NO | S30: 45735 | T30: 19/03/2025 09:28:46 | U30: 19/03/2025 12:51:49 | V30: 26426261 | W30: PRODUCTIVIDAD | Z30: User 10 | AA30: NestleP.10 | AB30: CAMILO MONTAÑO RESTREPO | AC30: camilo.montano
A31: NESTLE PURINA | B31: ANTIOQUIA | C31: MEDELLIN | D31: TRADICIONAL | E31: SUPERETE | F31: SUPERETES | G31: MEDELLIN | I31: 161719 | J31: SUPERMERCADO MAXIFRUVER PREMIUM | K31: 0 | L31: Mercadeo | M31: 1 | N31: AUDITORIA - MERCADEO PURINA MARZO 2025 | O31: TIENE TATUAJES O PIERCINGS VISIBLES QUE NO CUMPLE CON EL CODIGO DE VESTIMENTA | P31: SI | S31: 45735 | T31: 19/03/2025 09:28:46 | U31: 19/03/2025 12:51:49 | V31: 26426261 | W31: PRODUCTIVIDAD | Z31: User 10 | AA31: NestleP.10 | AB31: CAMILO MONTAÑO RESTREPO | AC31: camilo.montano
A32: NESTLE PURINA | B32: ANTIOQUIA | C32: MEDELLIN | D32: TRADICIONAL | E32: SUPERETE | F32: SUPERETES | G32: MEDELLIN | I32: 161719 | J32: SUPERMERCADO MAXIFRUVER PREMIUM | K32: 0 | L32: Mercadeo | M32: 1 | N32: AUDITORIA - MERCADEO PURINA MARZO 2025 | O32: TIENE UÑAS LLAMATIVAS Y/O LARGAS QUE NO CUMPLE CON EL CODIGO DE VESTIMENTA | P32: NO | S32: 45735 | T32: 19/03/2025 09:28:46 | U32: 19/03/2025 12:51:49 | V32: 26426261 | W32: PRODUCTIVIDAD | Z32: User 10 | AA32: NestleP.10 | AB32: CAMILO MONTAÑO RESTREPO | AC32: camilo.montano
... A40: NESTLE PURINA | B40: ANTIOQUIA | C40: MEDELLIN | D40: TRADICIONAL | E40: SUPERETE | F40: SUPERETES | G40: MEDELLIN | I40: 161719 | J40: SUPERMERCADO MAXIFRUVER PREMIUM | K40: 0 | L40: Mercadeo | M40: 1 | N40: AUDITORIA - MERCADEO PURINA MARZO 2025 | O40: CONOCE EL % DE PARTICIPACIÓN QUE TIENE EN EL PUNTO DE VENTA E INFORMA CUAL ES ESE % | P40: SI | S40: 45735 | T40: 19/03/2025 09:28:46 | U40: 19/03/2025 12:51:49 | V40: 26426261 | W40: PRODUCTIVIDAD | Z40: User 10 | AA40: NestleP.10 | AB40: CAMILO MONTAÑO RESTREPO | AC40: camilo.montano
A41: NESTLE PURINA | B41: ANTIOQUIA | C41: MEDELLIN | D41: TRADICIONAL | E41: SUPERETE | F41: SUPERETES | G41: MEDELLIN | I41: 161719 | J41: SUPERMERCADO MAXIFRUVER PREMIUM | K41: 0 | L41: Mercadeo | M41: 1 | N41: AUDITORIA - MERCADEO PURINA MARZO 2025 | O41: QUE CANAL VA A AUDITAR | P41: =_xlfn.XLOOKUP((Tabla2[[#This Row],[CODIGO RUTA]]&Tabla2[[#This Row],[PREGUNTA]]),[1]PURINA!$J:$J,[1]PURINA!$I:$I) -> CANAL TRADICIONAL | S41: 45735 | T41: 19/03/2025 09:28:46 | U41: 19/03/2025 12:51:49 | V41: 26426261 | W41: PRODUCTIVIDAD | Z41: User 10 | AA41: NestleP.10 | AB41: CAMILO MONTAÑO RESTREPO | AC41: camilo.montano
A42: NESTLE PURINA | B42: ANTIOQUIA | C42: MEDELLIN | D42: TRADICIONAL | E42: SUPERETE | F42: SUPERETES | G42: MEDELLIN | I42: 161719 | J42: SUPERMERCADO MAXIFRUVER PREMIUM | K42: 0 | L42: Mercadeo | M42: 1 | N42: AUDITORIA - MERCADEO PURINA MARZO 2025 | O42: T. ESTA IMPLEMENTADA LA NUEVA ESTRATEGIA DE BAJA DE PRECIOS (SI EL MERCADERISTA INFORMA QUE EL PDV NO LO PERMITE IMPLEMENTAR QUEDARIA COMO N/A) | P42: SI | S42: 45735 | T42: 19/03/2025 09:28:46 | U42: 19/03/2025 12:51:49 | V42: 26426261 | W42: PRODUCTIVIDAD | Z42: User 10 | AA42: NestleP.10 | AB42: CAMILO MONTAÑO RESTREPO | AC42: camilo.montano
A43: NESTLE PURINA | B43: ANTIOQUIA | C43: MEDELLIN | D43: TRADICIONAL | E43: SUPERETE | F43: SUPERETES | G43: MEDELLIN | I43: 161719 | J43: SUPERMERCADO MAXIFRUVER PREMIUM | K43: 0 | L43: Mercadeo | M43: 1 | N43: AUDITORIA - MERCADEO PURINA MARZO 2025 | O43: SE PRESENTA ALGUNA NOVEDAD? | P43: SI | S43: 45735 | T43: 19/03/2025 09:28:46 | U43: 19/03/2025 12:51:49 | V43: 26426261 | W43: PRODUCTIVIDAD | Z43: User 10 | AA43: NestleP.10 | AB43: CAMILO MONTAÑO RESTREPO | AC43: camilo.montano
A44: NESTLE PURINA | B44: ANTIOQUIA | C44: MEDELLIN | D44: TRADICIONAL | E44: SUPERETE | F44: SUPERETES | G44: MEDELLIN | I44: 161719 | J44: SUPERMERCADO MAXIFRUVER PREMIUM | K44: 0 | L44: Mercadeo | M44: 1 | N44: AUDITORIA - MERCADEO PURINA MARZO 2025 | O44: DESCRIBA LA NOVEDAD | P44: El vídeo se me movió un poco y se ve mucho la otra marca, pero a la chica de le hizo mistery y auditoría de purina, se le hizo compra porque su asesoría fue muy buena. Nos manifiesta que tiene muchos agotados, que ya los reporto y por el tema de agotados está perdiendo participación en el PDV de nuestra marca purina. | S44: 45735 | T44: 19/03/2025 09:28:46 | U44: 19/03/2025 12:51:49 | V44: 26426261 | W44: PRODUCTIVIDAD | Z44: User 10 | AA44: NestleP.10 | AB44: CAMILO MONTAÑO RESTREPO | AC44: camilo.montano
A45: NESTLE PURINA | B45: PACIFICO | C45: CALI | D45: TRADICIONAL | E45: SUPERETE | F45: SUPERETES | G45: CALI | I45: 66552 | J45: LA CASA DE LOS TENDEROS | K45: 0 | L45: Mercadeo | M45: 1 | N45: AUDITORIA - MERCADEO PURINA MARZO 2025 | O45: ¿CUMPLE HORARIO DE ENTRADA O SALIDA DE LA TIENDA? | P45: SI | S45: 45737 | T45: 21/03/2025 16:18:52 | U45: 21/03/2025 16:28:29 | V45: 26440178 | W45: PRODUCTIVIDAD | Z45: User 7 | AA45: NestleP.7 | AB45: CAMILO MONTAÑO RESTREPO | AC45: camilo.montano
A46: NESTLE PURINA | B46: PACIFICO | C46: CALI | D46: TRADICIONAL | E46: SUPERETE | F46: SUPERETES | G46: CALI | I46: 66552 | J46: LA CASA DE LOS TENDEROS | K46: 0 | L46: Mercadeo | M46: 1 | N46: AUDITORIA - MERCADEO PURINA MARZO 2025 | O46: CUENTA CON PANTALON DEL UNIFORME SEGÚN EL CARGO (NEGRO / ROJO / TURQUESA / JEAN) | P46: SI | S46: 45737 | T46: 21/03/2025 16:18:52 | U46: 21/03/2025 16:28:29 | V46: 26440178 | W46: PRODUCTIVIDAD | Z46: User 7 | AA46: NestleP.7 | AB46: CAMILO MONTAÑO RESTREPO | AC46: camilo.montano
A47: NESTLE PURINA | B47: PACIFICO | C47: CALI | D47: TRADICIONAL | E47: SUPERETE | F47: SUPERETES | G47: CALI | I47: 66552 | J47: LA CASA DE LOS TENDEROS | K47: 0 | L47: Mercadeo | M47: 1 | N47: AUDITORIA - MERCADEO PURINA MARZO 2025 | O47: CUENTA CON CAMISA DEL UNIFORME Y LOGOS SEGÚN EL CARGO (NEGRA / GRIS / ROJA / TURQUESA) (ES PERMITIDO USAR DEBAJO DE LA CAMISA BUSO MANGA LARGA NEGRO) | P47: SI | S47: 45737 | T47: 21/03/2025 16:18:52 | U47: 21/03/2025 16:28:29 | V47: 26440178 | W47: PRODUCTIVIDAD | Z47: User 7 | AA47: NestleP.7 | AB47: CAMILO MONTAÑO RESTREPO | AC47: camilo.montano
A48: NESTLE PURINA | B48: PACIFICO | C48: CALI | D48: TRADICIONAL | E48: SUPERETE | F48: SUPERETES | G48: CALI | I48: 66552 | J48: LA CASA DE LOS TENDEROS | K48: 0 | L48: Mercadeo | M48: 1 | N48: AUDITORIA - MERCADEO PURINA MARZO 2025 | O48: CUENTA CON CALZADO DE ACUERDO AL UNIFORME | P48: SI | S48: 45737 | T48: 21/03/2025 16:18:52 | U48: 21/03/2025 16:28:29 | V48: 26440178 | W48: PRODUCTIVIDAD | Z48: User 7 | AA48: NestleP.7 | AB48: CAMILO MONTAÑO RESTREPO | AC48: camilo.montano
A49: NESTLE PURINA | B49: PACIFICO | C49: CALI | D49: TRADICIONAL | E49: SUPERETE | F49: SUPERETES | G49: CALI | I49: 66552 | J49: LA CASA DE LOS TENDEROS | K49: 0 | L49: Mercadeo | M49: 1 | N49: AUDITORIA - MERCADEO PURINA MARZO 2025 | O49: POSEE ALGUNA PRENDA ENCIMA DEL UNIFORME NO AUTORIZADA POR LA MARCA (SOLO PERMITIDO CHALECO DE SODIMAC Y EASY) | P49: NO | S49: 45737 | T49: 21/03/2025 16:18:52 | U49: 21/03/2025 16:28:29 | V49: 26440178 | W49: PRODUCTIVIDAD | Z49: User 7 | AA49: NestleP.7 | AB49: CAMILO MONTAÑO RESTREPO | AC49: camilo.montano
A50: NESTLE PURINA | B50: PACIFICO | C50: CALI | D50: TRADICIONAL | E50: SUPERETE | F50: SUPERETES | G50: CALI | I50: 66552 | J50: LA CASA DE LOS TENDEROS | K50: 0 | L50: Mercadeo | M50: 1 | N50: AUDITORIA - MERCADEO PURINA MARZO 2025 | O50: EL UNIFORME Y ZAPATOS SE ENCUENTRAN LIMPIOS Y EN BUEN ESTADO | P50: SI | S50: 45737 | T50: 21/03/2025 16:18:52 | U50: 21/03/2025 16:28:29 | V50: 26440178 | W50: PRODUCTIVIDAD | Z50: User 7 | AA50: NestleP.7 | AB50: CAMILO MONTAÑO RESTREPO | AC50: camilo.montano
A51: NESTLE PURINA | B51: PACIFICO | C51: CALI | D51: TRADICIONAL | E51: SUPERETE | F51: SUPERETES | G51: CALI | I51: 66552 | J51: LA CASA DE LOS TENDEROS | K51: 0 | L51: Mercadeo | M51: 1 | N51: AUDITORIA - MERCADEO PURINA MARZO 2025 | O51: SU CABELLO LUCE LIMPIO, ORGANIZADO O RECOGIDO | P51: SI | S51: 45737 | T51: 21/03/2025 16:18:52 | U51: 21/03/2025 16:28:29 | V51: 26440178 | W51: PRODUCTIVIDAD | Z51: User 7 | AA51: NestleP.7 | AB51: CAMILO MONTAÑO RESTREPO | AC51: camilo.montano
A52: NESTLE PURINA | B52: PACIFICO | C52: CALI | D52: TRADICIONAL | E52: SUPERETE | F52: SUPERETES | G52: CALI | I52: 66552 | J52: LA CASA DE LOS TENDEROS | K52: 0 | L52: Mercadeo | M52: 1 | N52: AUDITORIA - MERCADEO PURINA MARZO 2025 | O52: PRESENTA EXCESO DE MAQUILLAJE QUE NO CUMPLE CON EL CODIGO DE VESTIMENTA | P52: NO | S52: 45737 | T52: 21/03/2025 16:18:52 | U52: 21/03/2025 16:28:29 | V52: 26440178 | W52: PRODUCTIVIDAD | Z52: User 7 | AA52: NestleP.7 | AB52: CAMILO MONTAÑO RESTREPO | AC52: camilo.montano
...

Sheet ENCUESTA
A1: TRADICIONAL | B1: ESPECIALIZADO | C1: MODERNO | D1: PESO | E1: CLUSTER | F1: TIPO | G1: PREGUNTA | H1: RTA CORRECTA | K1: Peso Cluster | L1: Cluster
A2: 20 | B2: 20 | C2: 20 | D2: 20 | E2: HORARIO | F2: UNICA | G2: ¿CUMPLE HORARIO DE ENTRADA O SALIDA DE LA TIENDA? | H2: SI | K2: 0.1 | L2: PRESENTACIÓN PERSONAL
A3: 1 | B3: 1 | C3: 1 | D3: 10 | E3: PRESENTACIÓN PERSONAL | F3: UNICA | G3: CUENTA CON PANTALON DEL UNIFORME SEGÚN EL CARGO (NEGRO / ROJO / TURQUESA / JEAN) | H3: SI | K3: 0.2 | L3: HORARIO
A4: 1 | B4: 1 | C4: 1 | D4: 10 | E4: PRESENTACIÓN PERSONAL | F4: UNICA | G4: CUENTA CON CAMISA DEL UNIFORME Y LOGOS SEGÚN EL CARGO (NEGRA / GRIS / ROJA / TURQUESA) (ES PERMITIDO USAR DEBAJO DE LA CAMISA BUSO MANGA LARGA NEGRO) | H4: SI | K4: 0.3 | L4: EJECUCION DEL PDV
A5: 1 | B5: 1 | C5: 1 | D5: 10 | E5: PRESENTACIÓN PERSONAL | F5: UNICA | G5: CUENTA CON CALZADO DE ACUERDO AL UNIFORME | H5: SI | K5: 0.4 | L5: ACTIVIDADES DEL MES
A6: 1 | B6: 1 | C6: 1 | D6: 10 | E6: PRESENTACIÓN PERSONAL | F6: UNICA | G6: POSEE ALGUNA PRENDA ENCIMA DEL UNIFORME NO AUTORIZADA POR LA MARCA (SOLO PERMITIDO CHALECO DE SODIMAC Y EASY) | H6: NO | K6: =SUM(K1:K5) -> 1 | L6: Total general
A7: 1 | B7: 1 | C7: 1 | D7: 10 | E7: PRESENTACIÓN PERSONAL | F7: UNICA | G7: EL UNIFORME Y ZAPATOS SE ENCUENTRAN LIMPIOS Y EN BUEN ESTADO | H7: SI
A8: 1 | B8: 1 | C8: 1 | D8: 10 | E8: PRESENTACIÓN PERSONAL | F8: UNICA | G8: SU CABELLO LUCE LIMPIO, ORGANIZADO O RECOGIDO | H8: SI
A9: 1 | B9: 1 | C9: 1 | D9: 10 | E9: PRESENTACIÓN PERSONAL | F9: UNICA | G9: PRESENTA EXCESO DE MAQUILLAJE QUE NO CUMPLE CON EL CODIGO DE VESTIMENTA | H9: NO
A10: 1 | B10: 1 | C10: 1 | D10: 10 | E10: PRESENTACIÓN PERSONAL | F10: UNICA | G10: TIENE TATUAJES O PIERCINGS VISIBLES QUE NO CUMPLE CON EL CODIGO DE VESTIMENTA | H10: NO
A11: 1 | B11: 1 | C11: 1 | D11: 10 | E11: PRESENTACIÓN PERSONAL | F11: UNICA | G11: TIENE UÑAS LLAMATIVAS Y/O LARGAS QUE NO CUMPLE CON EL CODIGO DE VESTIMENTA | H11: NO
A12: 1 | B12: 1 | C12: 1 | D12: 10 | E12: PRESENTACIÓN PERSONAL | F12: UNICA | G12: USA ACCESORIOS QUE NO CUMPLE CON EL CODIGO DE VESTIMENTA | H12: NO
A13: 4.2 | B13: 4.2 | C13: 4.2 | D13: 30 | E13: EJECUCION DEL PDV | F13: UNICA | G13: EL LINEAL SE ENCUENTRA LIMPIO Y ORGANIZADO | H13: SI
A14: 4.3 | B14: 4.3 | C14: 4.3 | D14: 30 | E14: EJECUCION DEL PDV | F14: UNICA | G14: LOS PRODUCTOS TIENEN EL PRECIO Y ESTAN ACORDE O CORRESPONDIENTE A CADA REFERENCIA | H14: SI
A15: 4.3 | B15: 4.3 | C15: 4.3 | D15: 30 | E15: EJECUCION DEL PDV | F15: UNICA | G15: LOS PRODUCTOS ESTAN SURTIDOS DE ACUERDO A PEPS O FIFO (REVISAR TANTO PRODUCTO SECO COMO HUMEDO) | H15: SI
A16: 4.3 | B16: 4.3 | C16: 4.3 | D16: 30 | E16: EJECUCION DEL PDV | F16: UNICA | G16: CONOCE LOS INFALTABLES DEL PUNTO DE VENTA Y CUENTA CON EL MATERIAL DE APOYO (AYUDAVENTAS INFALTABLES) | H16: SI
A17: 4.3 | B17: 4.3 | C17: 4.3 | D17: 30 | E17: EJECUCION DEL PDV | F17: UNICA | G17: CONOCE Y TIENE SURTIDO DE ACUERDO A LA ESTRATEGIA DE EXHIBICIÓN (ETAPAS DE VIDA - SEGMENTACIÓN DE MARCAS) | H17: SI
A18: 4.3 | B18: 4.3 | C18: 4.3 | D18: 30 | E18: EJECUCION DEL PDV | F18: UNICA | G18: CUAL ES LA ESTRATEGIA DE EXHIBICIÓN PARA LAS MARCAS MAINSTRAIN (ALPO Y GATSY) DE PURINA Y PORQUE? | H18: SI
... A29: 40 | B29: 0 | C29: 0 | D29: 40 | E29: ACTIVIDADES DEL MES | F29: UNICA | G29: T. ESTA IMPLEMENTADA LA NUEVA ESTRATEGIA DE BAJA DE PRECIOS (SI EL MERCADERISTA INFORMA QUE EL PDV NO LO PERMITE IMPLEMENTAR QUEDARIA COMO N/A) | H29: SI
A30: 0 | B30: 0 | C30: 0 | D30: 0 | E30: N/A | F30: UNICA | G30: SE PRESENTA ALGUNA NOVEDAD?
A31: 0 | B31: 0 | C31: 0 | D31: 0 | E31: N/A | F31: ABIERTA | G31: DESCRIBA LA NOVEDAD
